ü§ñ –ó–∞–ø—É—Å–∫ –±–æ—Ç–∞ DUNGEON Hookah...
üìÅ –î–∏—Ä–µ–∫—Ç–æ—Ä–∏—è: /Users/nikolajmisin/Documents/WebApp/next-app
üìù –õ–æ–≥ —Ñ–∞–π–ª: /Users/nikolajmisin/Documents/WebApp/next-app/bot.log

‚ñ∂Ô∏è  –ó–∞–ø—É—Å–∫ –±–æ—Ç–∞ –≤ 2025-10-15 20:28:44
2025-10-15 20:28:44,552 - __main__ - INFO - üöÄ Starting bot in polling mode...
2025-10-15 20:28:44,808 - httpx - INFO - HTTP Request: POST https://api.telegram.org/bot8242076298:AAGnHplpi7Ad4hOo9z4zTugjqcCEXLJt9to/getMe "HTTP/1.1 200 OK"
2025-10-15 20:28:44,874 - httpx - INFO - HTTP Request: POST https://api.telegram.org/bot8242076298:AAGnHplpi7Ad4hOo9z4zTugjqcCEXLJt9to/deleteWebhook "HTTP/1.1 200 OK"
2025-10-15 20:28:44,876 - telegram.ext.Application - INFO - Application started
2025-10-15 20:28:49,330 - httpx - INFO - HTTP Request: POST https://api.telegram.org/bot8242076298:AAGnHplpi7Ad4hOo9z4zTugjqcCEXLJt9to/getUpdates "HTTP/1.1 409 Conflict"
2025-10-15 20:28:49,332 - telegram.ext.Application - ERROR - No error handlers are registered, logging exception.
Traceback (most recent call last):
  File "/Library/Frameworks/Python.framework/Versions/3.13/lib/python3.13/site-packages/telegram/ext/_updater.py", line 743, in _network_loop_retry
    if not await do_action():
           ^^^^^^^^^^^^^^^^^
  File "/Library/Frameworks/Python.framework/Versions/3.13/lib/python3.13/site-packages/telegram/ext/_updater.py", line 737, in do_action
    return action_cb_task.result()
           ~~~~~~~~~~~~~~~~~~~~~^^
  File "/Library/Frameworks/Python.framework/Versions/3.13/lib/python3.13/site-packages/telegram/ext/_updater.py", line 367, in polling_action_cb
    updates = await self.bot.get_updates(
              ^^^^^^^^^^^^^^^^^^^^^^^^^^^
    ...<7 lines>...
    )
    ^
  File "/Library/Frameworks/Python.framework/Versions/3.13/lib/python3.13/site-packages/telegram/ext/_extbot.py", line 647, in get_updates
    updates = await super().get_updates(
              ^^^^^^^^^^^^^^^^^^^^^^^^^^
    ...<9 lines>...
    )
    ^
  File "/Library/Frameworks/Python.framework/Versions/3.13/lib/python3.13/site-packages/telegram/_bot.py", line 4421, in get_updates
    await self._post(
    ^^^^^^^^^^^^^^^^^
    ...<7 lines>...
    ),
    ^
  File "/Library/Frameworks/Python.framework/Versions/3.13/lib/python3.13/site-packages/telegram/_bot.py", line 617, in _post
    return await self._do_post(
           ^^^^^^^^^^^^^^^^^^^^
    ...<6 lines>...
    )
    ^
  File "/Library/Frameworks/Python.framework/Versions/3.13/lib/python3.13/site-packages/telegram/ext/_extbot.py", line 351, in _do_post
    return await super()._do_post(
           ^^^^^^^^^^^^^^^^^^^^^^^
    ...<6 lines>...
    )
    ^
  File "/Library/Frameworks/Python.framework/Versions/3.13/lib/python3.13/site-packages/telegram/_bot.py", line 646, in _do_post
    result = await request.post(
             ^^^^^^^^^^^^^^^^^^^
    ...<6 lines>...
    )
    ^
  File "/Library/Frameworks/Python.framework/Versions/3.13/lib/python3.13/site-packages/telegram/request/_baserequest.py", line 202, in post
    result = await self._request_wrapper(
             ^^^^^^^^^^^^^^^^^^^^^^^^^^^^
    ...<7 lines>...
    )
    ^
  File "/Library/Frameworks/Python.framework/Versions/3.13/lib/python3.13/site-packages/telegram/request/_baserequest.py", line 385, in _request_wrapper
    raise Conflict(message)
telegram.error.Conflict: Conflict: terminated by other getUpdates request; make sure that only one bot instance is running
2025-10-15 20:28:54,967 - httpx - INFO - HTTP Request: POST https://api.telegram.org/bot8242076298:AAGnHplpi7Ad4hOo9z4zTugjqcCEXLJt9to/getUpdates "HTTP/1.1 409 Conflict"
2025-10-15 20:28:54,969 - telegram.ext.Application - ERROR - No error handlers are registered, logging exception.
Traceback (most recent call last):
  File "/Library/Frameworks/Python.framework/Versions/3.13/lib/python3.13/site-packages/telegram/ext/_updater.py", line 743, in _network_loop_retry
    if not await do_action():
           ^^^^^^^^^^^^^^^^^
  File "/Library/Frameworks/Python.framework/Versions/3.13/lib/python3.13/site-packages/telegram/ext/_updater.py", line 737, in do_action
    return action_cb_task.result()
           ~~~~~~~~~~~~~~~~~~~~~^^
  File "/Library/Frameworks/Python.framework/Versions/3.13/lib/python3.13/site-packages/telegram/ext/_updater.py", line 367, in polling_action_cb
    updates = await self.bot.get_updates(
              ^^^^^^^^^^^^^^^^^^^^^^^^^^^
    ...<7 lines>...
    )
    ^
  File "/Library/Frameworks/Python.framework/Versions/3.13/lib/python3.13/site-packages/telegram/ext/_extbot.py", line 647, in get_updates
    updates = await super().get_updates(
              ^^^^^^^^^^^^^^^^^^^^^^^^^^
    ...<9 lines>...
    )
    ^
  File "/Library/Frameworks/Python.framework/Versions/3.13/lib/python3.13/site-packages/telegram/_bot.py", line 4421, in get_updates
    await self._post(
    ^^^^^^^^^^^^^^^^^
    ...<7 lines>...
    ),
    ^
  File "/Library/Frameworks/Python.framework/Versions/3.13/lib/python3.13/site-packages/telegram/_bot.py", line 617, in _post
    return await self._do_post(
           ^^^^^^^^^^^^^^^^^^^^
    ...<6 lines>...
    )
    ^
  File "/Library/Frameworks/Python.framework/Versions/3.13/lib/python3.13/site-packages/telegram/ext/_extbot.py", line 351, in _do_post
    return await super()._do_post(
           ^^^^^^^^^^^^^^^^^^^^^^^
    ...<6 lines>...
    )
    ^
  File "/Library/Frameworks/Python.framework/Versions/3.13/lib/python3.13/site-packages/telegram/_bot.py", line 646, in _do_post
    result = await request.post(
             ^^^^^^^^^^^^^^^^^^^
    ...<6 lines>...
    )
    ^
  File "/Library/Frameworks/Python.framework/Versions/3.13/lib/python3.13/site-packages/telegram/request/_baserequest.py", line 202, in post
    result = await self._request_wrapper(
             ^^^^^^^^^^^^^^^^^^^^^^^^^^^^
    ...<7 lines>...
    )
    ^
  File "/Library/Frameworks/Python.framework/Versions/3.13/lib/python3.13/site-packages/telegram/request/_baserequest.py", line 385, in _request_wrapper
    raise Conflict(message)
telegram.error.Conflict: Conflict: terminated by other getUpdates request; make sure that only one bot instance is running
2025-10-15 20:29:01,941 - httpx - INFO - HTTP Request: POST https://api.telegram.org/bot8242076298:AAGnHplpi7Ad4hOo9z4zTugjqcCEXLJt9to/getUpdates "HTTP/1.1 409 Conflict"
2025-10-15 20:29:01,942 - telegram.ext.Application - ERROR - No error handlers are registered, logging exception.
Traceback (most recent call last):
  File "/Library/Frameworks/Python.framework/Versions/3.13/lib/python3.13/site-packages/telegram/ext/_updater.py", line 743, in _network_loop_retry
    if not await do_action():
           ^^^^^^^^^^^^^^^^^
  File "/Library/Frameworks/Python.framework/Versions/3.13/lib/python3.13/site-packages/telegram/ext/_updater.py", line 737, in do_action
    return action_cb_task.result()
           ~~~~~~~~~~~~~~~~~~~~~^^
  File "/Library/Frameworks/Python.framework/Versions/3.13/lib/python3.13/site-packages/telegram/ext/_updater.py", line 367, in polling_action_cb
    updates = await self.bot.get_updates(
              ^^^^^^^^^^^^^^^^^^^^^^^^^^^
    ...<7 lines>...
    )
    ^
  File "/Library/Frameworks/Python.framework/Versions/3.13/lib/python3.13/site-packages/telegram/ext/_extbot.py", line 647, in get_updates
    updates = await super().get_updates(
              ^^^^^^^^^^^^^^^^^^^^^^^^^^
    ...<9 lines>...
    )
    ^
  File "/Library/Frameworks/Python.framework/Versions/3.13/lib/python3.13/site-packages/telegram/_bot.py", line 4421, in get_updates
    await self._post(
    ^^^^^^^^^^^^^^^^^
    ...<7 lines>...
    ),
    ^
  File "/Library/Frameworks/Python.framework/Versions/3.13/lib/python3.13/site-packages/telegram/_bot.py", line 617, in _post
    return await self._do_post(
           ^^^^^^^^^^^^^^^^^^^^
    ...<6 lines>...
    )
    ^
  File "/Library/Frameworks/Python.framework/Versions/3.13/lib/python3.13/site-packages/telegram/ext/_extbot.py", line 351, in _do_post
    return await super()._do_post(
           ^^^^^^^^^^^^^^^^^^^^^^^
    ...<6 lines>...
    )
    ^
  File "/Library/Frameworks/Python.framework/Versions/3.13/lib/python3.13/site-packages/telegram/_bot.py", line 646, in _do_post
    result = await request.post(
             ^^^^^^^^^^^^^^^^^^^
    ...<6 lines>...
    )
    ^
  File "/Library/Frameworks/Python.framework/Versions/3.13/lib/python3.13/site-packages/telegram/request/_baserequest.py", line 202, in post
    result = await self._request_wrapper(
             ^^^^^^^^^^^^^^^^^^^^^^^^^^^^
    ...<7 lines>...
    )
    ^
  File "/Library/Frameworks/Python.framework/Versions/3.13/lib/python3.13/site-packages/telegram/request/_baserequest.py", line 385, in _request_wrapper
    raise Conflict(message)
telegram.error.Conflict: Conflict: terminated by other getUpdates request; make sure that only one bot instance is running
2025-10-15 20:29:07,707 - httpx - INFO - HTTP Request: POST https://api.telegram.org/bot8242076298:AAGnHplpi7Ad4hOo9z4zTugjqcCEXLJt9to/getUpdates "HTTP/1.1 409 Conflict"
2025-10-15 20:29:07,709 - telegram.ext.Application - ERROR - No error handlers are registered, logging exception.
Traceback (most recent call last):
  File "/Library/Frameworks/Python.framework/Versions/3.13/lib/python3.13/site-packages/telegram/ext/_updater.py", line 743, in _network_loop_retry
    if not await do_action():
           ^^^^^^^^^^^^^^^^^
  File "/Library/Frameworks/Python.framework/Versions/3.13/lib/python3.13/site-packages/telegram/ext/_updater.py", line 737, in do_action
    return action_cb_task.result()
           ~~~~~~~~~~~~~~~~~~~~~^^
  File "/Library/Frameworks/Python.framework/Versions/3.13/lib/python3.13/site-packages/telegram/ext/_updater.py", line 367, in polling_action_cb
    updates = await self.bot.get_updates(
              ^^^^^^^^^^^^^^^^^^^^^^^^^^^
    ...<7 lines>...
    )
    ^
  File "/Library/Frameworks/Python.framework/Versions/3.13/lib/python3.13/site-packages/telegram/ext/_extbot.py", line 647, in get_updates
    updates = await super().get_updates(
              ^^^^^^^^^^^^^^^^^^^^^^^^^^
    ...<9 lines>...
    )
    ^
  File "/Library/Frameworks/Python.framework/Versions/3.13/lib/python3.13/site-packages/telegram/_bot.py", line 4421, in get_updates
    await self._post(
    ^^^^^^^^^^^^^^^^^
    ...<7 lines>...
    ),
    ^
  File "/Library/Frameworks/Python.framework/Versions/3.13/lib/python3.13/site-packages/telegram/_bot.py", line 617, in _post
    return await self._do_post(
           ^^^^^^^^^^^^^^^^^^^^
    ...<6 lines>...
    )
    ^
  File "/Library/Frameworks/Python.framework/Versions/3.13/lib/python3.13/site-packages/telegram/ext/_extbot.py", line 351, in _do_post
    return await super()._do_post(
           ^^^^^^^^^^^^^^^^^^^^^^^
    ...<6 lines>...
    )
    ^
  File "/Library/Frameworks/Python.framework/Versions/3.13/lib/python3.13/site-packages/telegram/_bot.py", line 646, in _do_post
    result = await request.post(
             ^^^^^^^^^^^^^^^^^^^
    ...<6 lines>...
    )
    ^
  File "/Library/Frameworks/Python.framework/Versions/3.13/lib/python3.13/site-packages/telegram/request/_baserequest.py", line 202, in post
    result = await self._request_wrapper(
             ^^^^^^^^^^^^^^^^^^^^^^^^^^^^
    ...<7 lines>...
    )
    ^
  File "/Library/Frameworks/Python.framework/Versions/3.13/lib/python3.13/site-packages/telegram/request/_baserequest.py", line 385, in _request_wrapper
    raise Conflict(message)
telegram.error.Conflict: Conflict: terminated by other getUpdates request; make sure that only one bot instance is running
2025-10-15 20:29:16,420 - httpx - INFO - HTTP Request: POST https://api.telegram.org/bot8242076298:AAGnHplpi7Ad4hOo9z4zTugjqcCEXLJt9to/getUpdates "HTTP/1.1 409 Conflict"
2025-10-15 20:29:16,422 - telegram.ext.Application - ERROR - No error handlers are registered, logging exception.
Traceback (most recent call last):
  File "/Library/Frameworks/Python.framework/Versions/3.13/lib/python3.13/site-packages/telegram/ext/_updater.py", line 743, in _network_loop_retry
    if not await do_action():
           ^^^^^^^^^^^^^^^^^
  File "/Library/Frameworks/Python.framework/Versions/3.13/lib/python3.13/site-packages/telegram/ext/_updater.py", line 737, in do_action
    return action_cb_task.result()
           ~~~~~~~~~~~~~~~~~~~~~^^
  File "/Library/Frameworks/Python.framework/Versions/3.13/lib/python3.13/site-packages/telegram/ext/_updater.py", line 367, in polling_action_cb
    updates = await self.bot.get_updates(
              ^^^^^^^^^^^^^^^^^^^^^^^^^^^
    ...<7 lines>...
    )
    ^
  File "/Library/Frameworks/Python.framework/Versions/3.13/lib/python3.13/site-packages/telegram/ext/_extbot.py", line 647, in get_updates
    updates = await super().get_updates(
              ^^^^^^^^^^^^^^^^^^^^^^^^^^
    ...<9 lines>...
    )
    ^
  File "/Library/Frameworks/Python.framework/Versions/3.13/lib/python3.13/site-packages/telegram/_bot.py", line 4421, in get_updates
    await self._post(
    ^^^^^^^^^^^^^^^^^
    ...<7 lines>...
    ),
    ^
  File "/Library/Frameworks/Python.framework/Versions/3.13/lib/python3.13/site-packages/telegram/_bot.py", line 617, in _post
    return await self._do_post(
           ^^^^^^^^^^^^^^^^^^^^
    ...<6 lines>...
    )
    ^
  File "/Library/Frameworks/Python.framework/Versions/3.13/lib/python3.13/site-packages/telegram/ext/_extbot.py", line 351, in _do_post
    return await super()._do_post(
           ^^^^^^^^^^^^^^^^^^^^^^^
    ...<6 lines>...
    )
    ^
  File "/Library/Frameworks/Python.framework/Versions/3.13/lib/python3.13/site-packages/telegram/_bot.py", line 646, in _do_post
    result = await request.post(
             ^^^^^^^^^^^^^^^^^^^
    ...<6 lines>...
    )
    ^
  File "/Library/Frameworks/Python.framework/Versions/3.13/lib/python3.13/site-packages/telegram/request/_baserequest.py", line 202, in post
    result = await self._request_wrapper(
             ^^^^^^^^^^^^^^^^^^^^^^^^^^^^
    ...<7 lines>...
    )
    ^
  File "/Library/Frameworks/Python.framework/Versions/3.13/lib/python3.13/site-packages/telegram/request/_baserequest.py", line 385, in _request_wrapper
    raise Conflict(message)
telegram.error.Conflict: Conflict: terminated by other getUpdates request; make sure that only one bot instance is running
2025-10-15 20:29:29,497 - httpx - INFO - HTTP Request: POST https://api.telegram.org/bot8242076298:AAGnHplpi7Ad4hOo9z4zTugjqcCEXLJt9to/getUpdates "HTTP/1.1 409 Conflict"
2025-10-15 20:29:29,498 - telegram.ext.Application - ERROR - No error handlers are registered, logging exception.
Traceback (most recent call last):
  File "/Library/Frameworks/Python.framework/Versions/3.13/lib/python3.13/site-packages/telegram/ext/_updater.py", line 743, in _network_loop_retry
    if not await do_action():
           ^^^^^^^^^^^^^^^^^
  File "/Library/Frameworks/Python.framework/Versions/3.13/lib/python3.13/site-packages/telegram/ext/_updater.py", line 737, in do_action
    return action_cb_task.result()
           ~~~~~~~~~~~~~~~~~~~~~^^
  File "/Library/Frameworks/Python.framework/Versions/3.13/lib/python3.13/site-packages/telegram/ext/_updater.py", line 367, in polling_action_cb
    updates = await self.bot.get_updates(
              ^^^^^^^^^^^^^^^^^^^^^^^^^^^
    ...<7 lines>...
    )
    ^
  File "/Library/Frameworks/Python.framework/Versions/3.13/lib/python3.13/site-packages/telegram/ext/_extbot.py", line 647, in get_updates
    updates = await super().get_updates(
              ^^^^^^^^^^^^^^^^^^^^^^^^^^
    ...<9 lines>...
    )
    ^
  File "/Library/Frameworks/Python.framework/Versions/3.13/lib/python3.13/site-packages/telegram/_bot.py", line 4421, in get_updates
    await self._post(
    ^^^^^^^^^^^^^^^^^
    ...<7 lines>...
    ),
    ^
  File "/Library/Frameworks/Python.framework/Versions/3.13/lib/python3.13/site-packages/telegram/_bot.py", line 617, in _post
    return await self._do_post(
           ^^^^^^^^^^^^^^^^^^^^
    ...<6 lines>...
    )
    ^
  File "/Library/Frameworks/Python.framework/Versions/3.13/lib/python3.13/site-packages/telegram/ext/_extbot.py", line 351, in _do_post
    return await super()._do_post(
           ^^^^^^^^^^^^^^^^^^^^^^^
    ...<6 lines>...
    )
    ^
  File "/Library/Frameworks/Python.framework/Versions/3.13/lib/python3.13/site-packages/telegram/_bot.py", line 646, in _do_post
    result = await request.post(
             ^^^^^^^^^^^^^^^^^^^
    ...<6 lines>...
    )
    ^
  File "/Library/Frameworks/Python.framework/Versions/3.13/lib/python3.13/site-packages/telegram/request/_baserequest.py", line 202, in post
    result = await self._request_wrapper(
             ^^^^^^^^^^^^^^^^^^^^^^^^^^^^
    ...<7 lines>...
    )
    ^
  File "/Library/Frameworks/Python.framework/Versions/3.13/lib/python3.13/site-packages/telegram/request/_baserequest.py", line 385, in _request_wrapper
    raise Conflict(message)
telegram.error.Conflict: Conflict: terminated by other getUpdates request; make sure that only one bot instance is running
2025-10-15 20:29:47,302 - httpx - INFO - HTTP Request: POST https://api.telegram.org/bot8242076298:AAGnHplpi7Ad4hOo9z4zTugjqcCEXLJt9to/getUpdates "HTTP/1.1 200 OK"
2025-10-15 20:29:48,898 - httpx - INFO - HTTP Request: POST https://api.telegram.org/bot8242076298:AAGnHplpi7Ad4hOo9z4zTugjqcCEXLJt9to/getUpdates "HTTP/1.1 409 Conflict"
2025-10-15 20:29:48,899 - telegram.ext.Application - ERROR - No error handlers are registered, logging exception.
Traceback (most recent call last):
  File "/Library/Frameworks/Python.framework/Versions/3.13/lib/python3.13/site-packages/telegram/ext/_updater.py", line 743, in _network_loop_retry
    if not await do_action():
           ^^^^^^^^^^^^^^^^^
  File "/Library/Frameworks/Python.framework/Versions/3.13/lib/python3.13/site-packages/telegram/ext/_updater.py", line 737, in do_action
    return action_cb_task.result()
           ~~~~~~~~~~~~~~~~~~~~~^^
  File "/Library/Frameworks/Python.framework/Versions/3.13/lib/python3.13/site-packages/telegram/ext/_updater.py", line 367, in polling_action_cb
    updates = await self.bot.get_updates(
              ^^^^^^^^^^^^^^^^^^^^^^^^^^^
    ...<7 lines>...
    )
    ^
  File "/Library/Frameworks/Python.framework/Versions/3.13/lib/python3.13/site-packages/telegram/ext/_extbot.py", line 647, in get_updates
    updates = await super().get_updates(
              ^^^^^^^^^^^^^^^^^^^^^^^^^^
    ...<9 lines>...
    )
    ^
  File "/Library/Frameworks/Python.framework/Versions/3.13/lib/python3.13/site-packages/telegram/_bot.py", line 4421, in get_updates
    await self._post(
    ^^^^^^^^^^^^^^^^^
    ...<7 lines>...
    ),
    ^
  File "/Library/Frameworks/Python.framework/Versions/3.13/lib/python3.13/site-packages/telegram/_bot.py", line 617, in _post
    return await self._do_post(
           ^^^^^^^^^^^^^^^^^^^^
    ...<6 lines>...
    )
    ^
  File "/Library/Frameworks/Python.framework/Versions/3.13/lib/python3.13/site-packages/telegram/ext/_extbot.py", line 351, in _do_post
    return await super()._do_post(
           ^^^^^^^^^^^^^^^^^^^^^^^
    ...<6 lines>...
    )
    ^
  File "/Library/Frameworks/Python.framework/Versions/3.13/lib/python3.13/site-packages/telegram/_bot.py", line 646, in _do_post
    result = await request.post(
             ^^^^^^^^^^^^^^^^^^^
    ...<6 lines>...
    )
    ^
  File "/Library/Frameworks/Python.framework/Versions/3.13/lib/python3.13/site-packages/telegram/request/_baserequest.py", line 202, in post
    result = await self._request_wrapper(
             ^^^^^^^^^^^^^^^^^^^^^^^^^^^^
    ...<7 lines>...
    )
    ^
  File "/Library/Frameworks/Python.framework/Versions/3.13/lib/python3.13/site-packages/telegram/request/_baserequest.py", line 385, in _request_wrapper
    raise Conflict(message)
telegram.error.Conflict: Conflict: terminated by other getUpdates request; make sure that only one bot instance is running
2025-10-15 20:29:52,577 - httpx - INFO - HTTP Request: POST https://api.telegram.org/bot8242076298:AAGnHplpi7Ad4hOo9z4zTugjqcCEXLJt9to/getUpdates "HTTP/1.1 200 OK"
2025-10-15 20:29:52,579 - __main__ - INFO - üöÄ START COMMAND CALLED!
2025-10-15 20:29:52,579 - __main__ - INFO - User 937011437 (shadowskydie) started the bot
2025-10-15 20:29:52,846 - httpx - INFO - HTTP Request: POST https://api.telegram.org/bot8242076298:AAGnHplpi7Ad4hOo9z4zTugjqcCEXLJt9to/sendMessage "HTTP/1.1 200 OK"
2025-10-15 20:29:53,821 - httpx - INFO - HTTP Request: POST https://api.telegram.org/bot8242076298:AAGnHplpi7Ad4hOo9z4zTugjqcCEXLJt9to/getUpdates "HTTP/1.1 200 OK"
2025-10-15 20:29:53,822 - __main__ - INFO - üöÄ START COMMAND CALLED!
2025-10-15 20:29:53,822 - __main__ - INFO - User 937011437 (shadowskydie) started the bot
2025-10-15 20:29:54,030 - httpx - INFO - HTTP Request: POST https://api.telegram.org/bot8242076298:AAGnHplpi7Ad4hOo9z4zTugjqcCEXLJt9to/sendMessage "HTTP/1.1 200 OK"
2025-10-15 20:29:54,785 - httpx - INFO - HTTP Request: POST https://api.telegram.org/bot8242076298:AAGnHplpi7Ad4hOo9z4zTugjqcCEXLJt9to/getUpdates "HTTP/1.1 200 OK"
2025-10-15 20:29:54,786 - __main__ - INFO - üöÄ START COMMAND CALLED!
2025-10-15 20:29:54,786 - __main__ - INFO - User 937011437 (shadowskydie) started the bot
2025-10-15 20:29:54,994 - httpx - INFO - HTTP Request: POST https://api.telegram.org/bot8242076298:AAGnHplpi7Ad4hOo9z4zTugjqcCEXLJt9to/sendMessage "HTTP/1.1 200 OK"
2025-10-15 20:30:04,851 - httpx - INFO - HTTP Request: POST https://api.telegram.org/bot8242076298:AAGnHplpi7Ad4hOo9z4zTugjqcCEXLJt9to/getUpdates "HTTP/1.1 200 OK"
2025-10-15 20:30:10,261 - httpx - INFO - HTTP Request: POST https://api.telegram.org/bot8242076298:AAGnHplpi7Ad4hOo9z4zTugjqcCEXLJt9to/getUpdates "HTTP/1.1 409 Conflict"
2025-10-15 20:30:10,262 - telegram.ext.Application - ERROR - No error handlers are registered, logging exception.
Traceback (most recent call last):
  File "/Library/Frameworks/Python.framework/Versions/3.13/lib/python3.13/site-packages/telegram/ext/_updater.py", line 743, in _network_loop_retry
    if not await do_action():
           ^^^^^^^^^^^^^^^^^
  File "/Library/Frameworks/Python.framework/Versions/3.13/lib/python3.13/site-packages/telegram/ext/_updater.py", line 737, in do_action
    return action_cb_task.result()
           ~~~~~~~~~~~~~~~~~~~~~^^
  File "/Library/Frameworks/Python.framework/Versions/3.13/lib/python3.13/site-packages/telegram/ext/_updater.py", line 367, in polling_action_cb
    updates = await self.bot.get_updates(
              ^^^^^^^^^^^^^^^^^^^^^^^^^^^
    ...<7 lines>...
    )
    ^
  File "/Library/Frameworks/Python.framework/Versions/3.13/lib/python3.13/site-packages/telegram/ext/_extbot.py", line 647, in get_updates
    updates = await super().get_updates(
              ^^^^^^^^^^^^^^^^^^^^^^^^^^
    ...<9 lines>...
    )
    ^
  File "/Library/Frameworks/Python.framework/Versions/3.13/lib/python3.13/site-packages/telegram/_bot.py", line 4421, in get_updates
    await self._post(
    ^^^^^^^^^^^^^^^^^
    ...<7 lines>...
    ),
    ^
  File "/Library/Frameworks/Python.framework/Versions/3.13/lib/python3.13/site-packages/telegram/_bot.py", line 617, in _post
    return await self._do_post(
           ^^^^^^^^^^^^^^^^^^^^
    ...<6 lines>...
    )
    ^
  File "/Library/Frameworks/Python.framework/Versions/3.13/lib/python3.13/site-packages/telegram/ext/_extbot.py", line 351, in _do_post
    return await super()._do_post(
           ^^^^^^^^^^^^^^^^^^^^^^^
    ...<6 lines>...
    )
    ^
  File "/Library/Frameworks/Python.framework/Versions/3.13/lib/python3.13/site-packages/telegram/_bot.py", line 646, in _do_post
    result = await request.post(
             ^^^^^^^^^^^^^^^^^^^
    ...<6 lines>...
    )
    ^
  File "/Library/Frameworks/Python.framework/Versions/3.13/lib/python3.13/site-packages/telegram/request/_baserequest.py", line 202, in post
    result = await self._request_wrapper(
             ^^^^^^^^^^^^^^^^^^^^^^^^^^^^
    ...<7 lines>...
    )
    ^
  File "/Library/Frameworks/Python.framework/Versions/3.13/lib/python3.13/site-packages/telegram/request/_baserequest.py", line 385, in _request_wrapper
    raise Conflict(message)
telegram.error.Conflict: Conflict: terminated by other getUpdates request; make sure that only one bot instance is running
2025-10-15 20:30:21,344 - httpx - INFO - HTTP Request: POST https://api.telegram.org/bot8242076298:AAGnHplpi7Ad4hOo9z4zTugjqcCEXLJt9to/getUpdates "HTTP/1.1 200 OK"
2025-10-15 20:30:31,481 - httpx - INFO - HTTP Request: POST https://api.telegram.org/bot8242076298:AAGnHplpi7Ad4hOo9z4zTugjqcCEXLJt9to/getUpdates "HTTP/1.1 200 OK"
2025-10-15 20:30:40,170 - httpx - INFO - HTTP Request: POST https://api.telegram.org/bot8242076298:AAGnHplpi7Ad4hOo9z4zTugjqcCEXLJt9to/getUpdates "HTTP/1.1 409 Conflict"
2025-10-15 20:30:40,171 - telegram.ext.Application - ERROR - No error handlers are registered, logging exception.
Traceback (most recent call last):
  File "/Library/Frameworks/Python.framework/Versions/3.13/lib/python3.13/site-packages/telegram/ext/_updater.py", line 743, in _network_loop_retry
    if not await do_action():
           ^^^^^^^^^^^^^^^^^
  File "/Library/Frameworks/Python.framework/Versions/3.13/lib/python3.13/site-packages/telegram/ext/_updater.py", line 737, in do_action
    return action_cb_task.result()
           ~~~~~~~~~~~~~~~~~~~~~^^
  File "/Library/Frameworks/Python.framework/Versions/3.13/lib/python3.13/site-packages/telegram/ext/_updater.py", line 367, in polling_action_cb
    updates = await self.bot.get_updates(
              ^^^^^^^^^^^^^^^^^^^^^^^^^^^
    ...<7 lines>...
    )
    ^
  File "/Library/Frameworks/Python.framework/Versions/3.13/lib/python3.13/site-packages/telegram/ext/_extbot.py", line 647, in get_updates
    updates = await super().get_updates(
              ^^^^^^^^^^^^^^^^^^^^^^^^^^
    ...<9 lines>...
    )
    ^
  File "/Library/Frameworks/Python.framework/Versions/3.13/lib/python3.13/site-packages/telegram/_bot.py", line 4421, in get_updates
    await self._post(
    ^^^^^^^^^^^^^^^^^
    ...<7 lines>...
    ),
    ^
  File "/Library/Frameworks/Python.framework/Versions/3.13/lib/python3.13/site-packages/telegram/_bot.py", line 617, in _post
    return await self._do_post(
           ^^^^^^^^^^^^^^^^^^^^
    ...<6 lines>...
    )
    ^
  File "/Library/Frameworks/Python.framework/Versions/3.13/lib/python3.13/site-packages/telegram/ext/_extbot.py", line 351, in _do_post
    return await super()._do_post(
           ^^^^^^^^^^^^^^^^^^^^^^^
    ...<6 lines>...
    )
    ^
  File "/Library/Frameworks/Python.framework/Versions/3.13/lib/python3.13/site-packages/telegram/_bot.py", line 646, in _do_post
    result = await request.post(
             ^^^^^^^^^^^^^^^^^^^
    ...<6 lines>...
    )
    ^
  File "/Library/Frameworks/Python.framework/Versions/3.13/lib/python3.13/site-packages/telegram/request/_baserequest.py", line 202, in post
    result = await self._request_wrapper(
             ^^^^^^^^^^^^^^^^^^^^^^^^^^^^
    ...<7 lines>...
    )
    ^
  File "/Library/Frameworks/Python.framework/Versions/3.13/lib/python3.13/site-packages/telegram/request/_baserequest.py", line 385, in _request_wrapper
    raise Conflict(message)
telegram.error.Conflict: Conflict: terminated by other getUpdates request; make sure that only one bot instance is running
2025-10-15 20:30:51,240 - httpx - INFO - HTTP Request: POST https://api.telegram.org/bot8242076298:AAGnHplpi7Ad4hOo9z4zTugjqcCEXLJt9to/getUpdates "HTTP/1.1 200 OK"
2025-10-15 20:31:01,384 - httpx - INFO - HTTP Request: POST https://api.telegram.org/bot8242076298:AAGnHplpi7Ad4hOo9z4zTugjqcCEXLJt9to/getUpdates "HTTP/1.1 200 OK"
2025-10-15 20:31:11,454 - httpx - INFO - HTTP Request: POST https://api.telegram.org/bot8242076298:AAGnHplpi7Ad4hOo9z4zTugjqcCEXLJt9to/getUpdates "HTTP/1.1 200 OK"
2025-10-15 20:31:14,451 - httpx - INFO - HTTP Request: POST https://api.telegram.org/bot8242076298:AAGnHplpi7Ad4hOo9z4zTugjqcCEXLJt9to/getUpdates "HTTP/1.1 409 Conflict"
2025-10-15 20:31:14,452 - telegram.ext.Application - ERROR - No error handlers are registered, logging exception.
Traceback (most recent call last):
  File "/Library/Frameworks/Python.framework/Versions/3.13/lib/python3.13/site-packages/telegram/ext/_updater.py", line 743, in _network_loop_retry
    if not await do_action():
           ^^^^^^^^^^^^^^^^^
  File "/Library/Frameworks/Python.framework/Versions/3.13/lib/python3.13/site-packages/telegram/ext/_updater.py", line 737, in do_action
    return action_cb_task.result()
           ~~~~~~~~~~~~~~~~~~~~~^^
  File "/Library/Frameworks/Python.framework/Versions/3.13/lib/python3.13/site-packages/telegram/ext/_updater.py", line 367, in polling_action_cb
    updates = await self.bot.get_updates(
              ^^^^^^^^^^^^^^^^^^^^^^^^^^^
    ...<7 lines>...
    )
    ^
  File "/Library/Frameworks/Python.framework/Versions/3.13/lib/python3.13/site-packages/telegram/ext/_extbot.py", line 647, in get_updates
    updates = await super().get_updates(
              ^^^^^^^^^^^^^^^^^^^^^^^^^^
    ...<9 lines>...
    )
    ^
  File "/Library/Frameworks/Python.framework/Versions/3.13/lib/python3.13/site-packages/telegram/_bot.py", line 4421, in get_updates
    await self._post(
    ^^^^^^^^^^^^^^^^^
    ...<7 lines>...
    ),
    ^
  File "/Library/Frameworks/Python.framework/Versions/3.13/lib/python3.13/site-packages/telegram/_bot.py", line 617, in _post
    return await self._do_post(
           ^^^^^^^^^^^^^^^^^^^^
    ...<6 lines>...
    )
    ^
  File "/Library/Frameworks/Python.framework/Versions/3.13/lib/python3.13/site-packages/telegram/ext/_extbot.py", line 351, in _do_post
    return await super()._do_post(
           ^^^^^^^^^^^^^^^^^^^^^^^
    ...<6 lines>...
    )
    ^
  File "/Library/Frameworks/Python.framework/Versions/3.13/lib/python3.13/site-packages/telegram/_bot.py", line 646, in _do_post
    result = await request.post(
             ^^^^^^^^^^^^^^^^^^^
    ...<6 lines>...
    )
    ^
  File "/Library/Frameworks/Python.framework/Versions/3.13/lib/python3.13/site-packages/telegram/request/_baserequest.py", line 202, in post
    result = await self._request_wrapper(
             ^^^^^^^^^^^^^^^^^^^^^^^^^^^^
    ...<7 lines>...
    )
    ^
  File "/Library/Frameworks/Python.framework/Versions/3.13/lib/python3.13/site-packages/telegram/request/_baserequest.py", line 385, in _request_wrapper
    raise Conflict(message)
telegram.error.Conflict: Conflict: terminated by other getUpdates request; make sure that only one bot instance is running
2025-10-15 20:31:25,526 - httpx - INFO - HTTP Request: POST https://api.telegram.org/bot8242076298:AAGnHplpi7Ad4hOo9z4zTugjqcCEXLJt9to/getUpdates "HTTP/1.1 200 OK"
2025-10-15 20:31:35,654 - httpx - INFO - HTTP Request: POST https://api.telegram.org/bot8242076298:AAGnHplpi7Ad4hOo9z4zTugjqcCEXLJt9to/getUpdates "HTTP/1.1 200 OK"
2025-10-15 20:31:45,826 - httpx - INFO - HTTP Request: POST https://api.telegram.org/bot8242076298:AAGnHplpi7Ad4hOo9z4zTugjqcCEXLJt9to/getUpdates "HTTP/1.1 200 OK"
2025-10-15 20:31:48,747 - httpx - INFO - HTTP Request: POST https://api.telegram.org/bot8242076298:AAGnHplpi7Ad4hOo9z4zTugjqcCEXLJt9to/getUpdates "HTTP/1.1 409 Conflict"
2025-10-15 20:31:48,748 - telegram.ext.Application - ERROR - No error handlers are registered, logging exception.
Traceback (most recent call last):
  File "/Library/Frameworks/Python.framework/Versions/3.13/lib/python3.13/site-packages/telegram/ext/_updater.py", line 743, in _network_loop_retry
    if not await do_action():
           ^^^^^^^^^^^^^^^^^
  File "/Library/Frameworks/Python.framework/Versions/3.13/lib/python3.13/site-packages/telegram/ext/_updater.py", line 737, in do_action
    return action_cb_task.result()
           ~~~~~~~~~~~~~~~~~~~~~^^
  File "/Library/Frameworks/Python.framework/Versions/3.13/lib/python3.13/site-packages/telegram/ext/_updater.py", line 367, in polling_action_cb
    updates = await self.bot.get_updates(
              ^^^^^^^^^^^^^^^^^^^^^^^^^^^
    ...<7 lines>...
    )
    ^
  File "/Library/Frameworks/Python.framework/Versions/3.13/lib/python3.13/site-packages/telegram/ext/_extbot.py", line 647, in get_updates
    updates = await super().get_updates(
              ^^^^^^^^^^^^^^^^^^^^^^^^^^
    ...<9 lines>...
    )
    ^
  File "/Library/Frameworks/Python.framework/Versions/3.13/lib/python3.13/site-packages/telegram/_bot.py", line 4421, in get_updates
    await self._post(
    ^^^^^^^^^^^^^^^^^
    ...<7 lines>...
    ),
    ^
  File "/Library/Frameworks/Python.framework/Versions/3.13/lib/python3.13/site-packages/telegram/_bot.py", line 617, in _post
    return await self._do_post(
           ^^^^^^^^^^^^^^^^^^^^
    ...<6 lines>...
    )
    ^
  File "/Library/Frameworks/Python.framework/Versions/3.13/lib/python3.13/site-packages/telegram/ext/_extbot.py", line 351, in _do_post
    return await super()._do_post(
           ^^^^^^^^^^^^^^^^^^^^^^^
    ...<6 lines>...
    )
    ^
  File "/Library/Frameworks/Python.framework/Versions/3.13/lib/python3.13/site-packages/telegram/_bot.py", line 646, in _do_post
    result = await request.post(
             ^^^^^^^^^^^^^^^^^^^
    ...<6 lines>...
    )
    ^
  File "/Library/Frameworks/Python.framework/Versions/3.13/lib/python3.13/site-packages/telegram/request/_baserequest.py", line 202, in post
    result = await self._request_wrapper(
             ^^^^^^^^^^^^^^^^^^^^^^^^^^^^
    ...<7 lines>...
    )
    ^
  File "/Library/Frameworks/Python.framework/Versions/3.13/lib/python3.13/site-packages/telegram/request/_baserequest.py", line 385, in _request_wrapper
    raise Conflict(message)
telegram.error.Conflict: Conflict: terminated by other getUpdates request; make sure that only one bot instance is running
2025-10-15 20:31:59,815 - httpx - INFO - HTTP Request: POST https://api.telegram.org/bot8242076298:AAGnHplpi7Ad4hOo9z4zTugjqcCEXLJt9to/getUpdates "HTTP/1.1 200 OK"
2025-10-15 20:32:09,890 - httpx - INFO - HTTP Request: POST https://api.telegram.org/bot8242076298:AAGnHplpi7Ad4hOo9z4zTugjqcCEXLJt9to/getUpdates "HTTP/1.1 200 OK"
2025-10-15 20:32:20,026 - httpx - INFO - HTTP Request: POST https://api.telegram.org/bot8242076298:AAGnHplpi7Ad4hOo9z4zTugjqcCEXLJt9to/getUpdates "HTTP/1.1 200 OK"
2025-10-15 20:32:23,032 - httpx - INFO - HTTP Request: POST https://api.telegram.org/bot8242076298:AAGnHplpi7Ad4hOo9z4zTugjqcCEXLJt9to/getUpdates "HTTP/1.1 409 Conflict"
2025-10-15 20:32:23,033 - telegram.ext.Application - ERROR - No error handlers are registered, logging exception.
Traceback (most recent call last):
  File "/Library/Frameworks/Python.framework/Versions/3.13/lib/python3.13/site-packages/telegram/ext/_updater.py", line 743, in _network_loop_retry
    if not await do_action():
           ^^^^^^^^^^^^^^^^^
  File "/Library/Frameworks/Python.framework/Versions/3.13/lib/python3.13/site-packages/telegram/ext/_updater.py", line 737, in do_action
    return action_cb_task.result()
           ~~~~~~~~~~~~~~~~~~~~~^^
  File "/Library/Frameworks/Python.framework/Versions/3.13/lib/python3.13/site-packages/telegram/ext/_updater.py", line 367, in polling_action_cb
    updates = await self.bot.get_updates(
              ^^^^^^^^^^^^^^^^^^^^^^^^^^^
    ...<7 lines>...
    )
    ^
  File "/Library/Frameworks/Python.framework/Versions/3.13/lib/python3.13/site-packages/telegram/ext/_extbot.py", line 647, in get_updates
    updates = await super().get_updates(
              ^^^^^^^^^^^^^^^^^^^^^^^^^^
    ...<9 lines>...
    )
    ^
  File "/Library/Frameworks/Python.framework/Versions/3.13/lib/python3.13/site-packages/telegram/_bot.py", line 4421, in get_updates
    await self._post(
    ^^^^^^^^^^^^^^^^^
    ...<7 lines>...
    ),
    ^
  File "/Library/Frameworks/Python.framework/Versions/3.13/lib/python3.13/site-packages/telegram/_bot.py", line 617, in _post
    return await self._do_post(
           ^^^^^^^^^^^^^^^^^^^^
    ...<6 lines>...
    )
    ^
  File "/Library/Frameworks/Python.framework/Versions/3.13/lib/python3.13/site-packages/telegram/ext/_extbot.py", line 351, in _do_post
    return await super()._do_post(
           ^^^^^^^^^^^^^^^^^^^^^^^
    ...<6 lines>...
    )
    ^
  File "/Library/Frameworks/Python.framework/Versions/3.13/lib/python3.13/site-packages/telegram/_bot.py", line 646, in _do_post
    result = await request.post(
             ^^^^^^^^^^^^^^^^^^^
    ...<6 lines>...
    )
    ^
  File "/Library/Frameworks/Python.framework/Versions/3.13/lib/python3.13/site-packages/telegram/request/_baserequest.py", line 202, in post
    result = await self._request_wrapper(
             ^^^^^^^^^^^^^^^^^^^^^^^^^^^^
    ...<7 lines>...
    )
    ^
  File "/Library/Frameworks/Python.framework/Versions/3.13/lib/python3.13/site-packages/telegram/request/_baserequest.py", line 385, in _request_wrapper
    raise Conflict(message)
telegram.error.Conflict: Conflict: terminated by other getUpdates request; make sure that only one bot instance is running
2025-10-15 20:32:33,054 - httpx - INFO - HTTP Request: POST https://api.telegram.org/bot8242076298:AAGnHplpi7Ad4hOo9z4zTugjqcCEXLJt9to/getUpdates "HTTP/1.1 200 OK"
2025-10-15 20:32:33,057 - __main__ - INFO - üöÄ START COMMAND CALLED!
2025-10-15 20:32:33,057 - __main__ - INFO - User 937011437 (shadowskydie) started the bot
2025-10-15 20:32:33,279 - httpx - INFO - HTTP Request: POST https://api.telegram.org/bot8242076298:AAGnHplpi7Ad4hOo9z4zTugjqcCEXLJt9to/sendMessage "HTTP/1.1 200 OK"
2025-10-15 20:32:43,170 - httpx - INFO - HTTP Request: POST https://api.telegram.org/bot8242076298:AAGnHplpi7Ad4hOo9z4zTugjqcCEXLJt9to/getUpdates "HTTP/1.1 200 OK"
2025-10-15 20:32:53,236 - httpx - INFO - HTTP Request: POST https://api.telegram.org/bot8242076298:AAGnHplpi7Ad4hOo9z4zTugjqcCEXLJt9to/getUpdates "HTTP/1.1 200 OK"
2025-10-15 20:32:57,422 - httpx - INFO - HTTP Request: POST https://api.telegram.org/bot8242076298:AAGnHplpi7Ad4hOo9z4zTugjqcCEXLJt9to/getUpdates "HTTP/1.1 409 Conflict"
2025-10-15 20:32:57,423 - telegram.ext.Application - ERROR - No error handlers are registered, logging exception.
Traceback (most recent call last):
  File "/Library/Frameworks/Python.framework/Versions/3.13/lib/python3.13/site-packages/telegram/ext/_updater.py", line 743, in _network_loop_retry
    if not await do_action():
           ^^^^^^^^^^^^^^^^^
  File "/Library/Frameworks/Python.framework/Versions/3.13/lib/python3.13/site-packages/telegram/ext/_updater.py", line 737, in do_action
    return action_cb_task.result()
           ~~~~~~~~~~~~~~~~~~~~~^^
  File "/Library/Frameworks/Python.framework/Versions/3.13/lib/python3.13/site-packages/telegram/ext/_updater.py", line 367, in polling_action_cb
    updates = await self.bot.get_updates(
              ^^^^^^^^^^^^^^^^^^^^^^^^^^^
    ...<7 lines>...
    )
    ^
  File "/Library/Frameworks/Python.framework/Versions/3.13/lib/python3.13/site-packages/telegram/ext/_extbot.py", line 647, in get_updates
    updates = await super().get_updates(
              ^^^^^^^^^^^^^^^^^^^^^^^^^^
    ...<9 lines>...
    )
    ^
  File "/Library/Frameworks/Python.framework/Versions/3.13/lib/python3.13/site-packages/telegram/_bot.py", line 4421, in get_updates
    await self._post(
    ^^^^^^^^^^^^^^^^^
    ...<7 lines>...
    ),
    ^
  File "/Library/Frameworks/Python.framework/Versions/3.13/lib/python3.13/site-packages/telegram/_bot.py", line 617, in _post
    return await self._do_post(
           ^^^^^^^^^^^^^^^^^^^^
    ...<6 lines>...
    )
    ^
  File "/Library/Frameworks/Python.framework/Versions/3.13/lib/python3.13/site-packages/telegram/ext/_extbot.py", line 351, in _do_post
    return await super()._do_post(
           ^^^^^^^^^^^^^^^^^^^^^^^
    ...<6 lines>...
    )
    ^
  File "/Library/Frameworks/Python.framework/Versions/3.13/lib/python3.13/site-packages/telegram/_bot.py", line 646, in _do_post
    result = await request.post(
             ^^^^^^^^^^^^^^^^^^^
    ...<6 lines>...
    )
    ^
  File "/Library/Frameworks/Python.framework/Versions/3.13/lib/python3.13/site-packages/telegram/request/_baserequest.py", line 202, in post
    result = await self._request_wrapper(
             ^^^^^^^^^^^^^^^^^^^^^^^^^^^^
    ...<7 lines>...
    )
    ^
  File "/Library/Frameworks/Python.framework/Versions/3.13/lib/python3.13/site-packages/telegram/request/_baserequest.py", line 385, in _request_wrapper
    raise Conflict(message)
telegram.error.Conflict: Conflict: terminated by other getUpdates request; make sure that only one bot instance is running
2025-10-15 20:33:08,564 - httpx - INFO - HTTP Request: POST https://api.telegram.org/bot8242076298:AAGnHplpi7Ad4hOo9z4zTugjqcCEXLJt9to/getUpdates "HTTP/1.1 200 OK"
2025-10-15 20:33:18,632 - httpx - INFO - HTTP Request: POST https://api.telegram.org/bot8242076298:AAGnHplpi7Ad4hOo9z4zTugjqcCEXLJt9to/getUpdates "HTTP/1.1 200 OK"
2025-10-15 20:33:28,712 - httpx - INFO - HTTP Request: POST https://api.telegram.org/bot8242076298:AAGnHplpi7Ad4hOo9z4zTugjqcCEXLJt9to/getUpdates "HTTP/1.1 200 OK"
2025-10-15 20:33:31,820 - httpx - INFO - HTTP Request: POST https://api.telegram.org/bot8242076298:AAGnHplpi7Ad4hOo9z4zTugjqcCEXLJt9to/getUpdates "HTTP/1.1 409 Conflict"
2025-10-15 20:33:31,821 - telegram.ext.Application - ERROR - No error handlers are registered, logging exception.
Traceback (most recent call last):
  File "/Library/Frameworks/Python.framework/Versions/3.13/lib/python3.13/site-packages/telegram/ext/_updater.py", line 743, in _network_loop_retry
    if not await do_action():
           ^^^^^^^^^^^^^^^^^
  File "/Library/Frameworks/Python.framework/Versions/3.13/lib/python3.13/site-packages/telegram/ext/_updater.py", line 737, in do_action
    return action_cb_task.result()
           ~~~~~~~~~~~~~~~~~~~~~^^
  File "/Library/Frameworks/Python.framework/Versions/3.13/lib/python3.13/site-packages/telegram/ext/_updater.py", line 367, in polling_action_cb
    updates = await self.bot.get_updates(
              ^^^^^^^^^^^^^^^^^^^^^^^^^^^
    ...<7 lines>...
    )
    ^
  File "/Library/Frameworks/Python.framework/Versions/3.13/lib/python3.13/site-packages/telegram/ext/_extbot.py", line 647, in get_updates
    updates = await super().get_updates(
              ^^^^^^^^^^^^^^^^^^^^^^^^^^
    ...<9 lines>...
    )
    ^
  File "/Library/Frameworks/Python.framework/Versions/3.13/lib/python3.13/site-packages/telegram/_bot.py", line 4421, in get_updates
    await self._post(
    ^^^^^^^^^^^^^^^^^
    ...<7 lines>...
    ),
    ^
  File "/Library/Frameworks/Python.framework/Versions/3.13/lib/python3.13/site-packages/telegram/_bot.py", line 617, in _post
    return await self._do_post(
           ^^^^^^^^^^^^^^^^^^^^
    ...<6 lines>...
    )
    ^
  File "/Library/Frameworks/Python.framework/Versions/3.13/lib/python3.13/site-packages/telegram/ext/_extbot.py", line 351, in _do_post
    return await super()._do_post(
           ^^^^^^^^^^^^^^^^^^^^^^^
    ...<6 lines>...
    )
    ^
  File "/Library/Frameworks/Python.framework/Versions/3.13/lib/python3.13/site-packages/telegram/_bot.py", line 646, in _do_post
    result = await request.post(
             ^^^^^^^^^^^^^^^^^^^
    ...<6 lines>...
    )
    ^
  File "/Library/Frameworks/Python.framework/Versions/3.13/lib/python3.13/site-packages/telegram/request/_baserequest.py", line 202, in post
    result = await self._request_wrapper(
             ^^^^^^^^^^^^^^^^^^^^^^^^^^^^
    ...<7 lines>...
    )
    ^
  File "/Library/Frameworks/Python.framework/Versions/3.13/lib/python3.13/site-packages/telegram/request/_baserequest.py", line 385, in _request_wrapper
    raise Conflict(message)
telegram.error.Conflict: Conflict: terminated by other getUpdates request; make sure that only one bot instance is running
2025-10-15 20:33:42,885 - httpx - INFO - HTTP Request: POST https://api.telegram.org/bot8242076298:AAGnHplpi7Ad4hOo9z4zTugjqcCEXLJt9to/getUpdates "HTTP/1.1 200 OK"
2025-10-15 20:33:53,006 - httpx - INFO - HTTP Request: POST https://api.telegram.org/bot8242076298:AAGnHplpi7Ad4hOo9z4zTugjqcCEXLJt9to/getUpdates "HTTP/1.1 200 OK"
2025-10-15 20:34:03,075 - httpx - INFO - HTTP Request: POST https://api.telegram.org/bot8242076298:AAGnHplpi7Ad4hOo9z4zTugjqcCEXLJt9to/getUpdates "HTTP/1.1 200 OK"
2025-10-15 20:34:06,102 - httpx - INFO - HTTP Request: POST https://api.telegram.org/bot8242076298:AAGnHplpi7Ad4hOo9z4zTugjqcCEXLJt9to/getUpdates "HTTP/1.1 409 Conflict"
2025-10-15 20:34:06,103 - telegram.ext.Application - ERROR - No error handlers are registered, logging exception.
Traceback (most recent call last):
  File "/Library/Frameworks/Python.framework/Versions/3.13/lib/python3.13/site-packages/telegram/ext/_updater.py", line 743, in _network_loop_retry
    if not await do_action():
           ^^^^^^^^^^^^^^^^^
  File "/Library/Frameworks/Python.framework/Versions/3.13/lib/python3.13/site-packages/telegram/ext/_updater.py", line 737, in do_action
    return action_cb_task.result()
           ~~~~~~~~~~~~~~~~~~~~~^^
  File "/Library/Frameworks/Python.framework/Versions/3.13/lib/python3.13/site-packages/telegram/ext/_updater.py", line 367, in polling_action_cb
    updates = await self.bot.get_updates(
              ^^^^^^^^^^^^^^^^^^^^^^^^^^^
    ...<7 lines>...
    )
    ^
  File "/Library/Frameworks/Python.framework/Versions/3.13/lib/python3.13/site-packages/telegram/ext/_extbot.py", line 647, in get_updates
    updates = await super().get_updates(
              ^^^^^^^^^^^^^^^^^^^^^^^^^^
    ...<9 lines>...
    )
    ^
  File "/Library/Frameworks/Python.framework/Versions/3.13/lib/python3.13/site-packages/telegram/_bot.py", line 4421, in get_updates
    await self._post(
    ^^^^^^^^^^^^^^^^^
    ...<7 lines>...
    ),
    ^
  File "/Library/Frameworks/Python.framework/Versions/3.13/lib/python3.13/site-packages/telegram/_bot.py", line 617, in _post
    return await self._do_post(
           ^^^^^^^^^^^^^^^^^^^^
    ...<6 lines>...
    )
    ^
  File "/Library/Frameworks/Python.framework/Versions/3.13/lib/python3.13/site-packages/telegram/ext/_extbot.py", line 351, in _do_post
    return await super()._do_post(
           ^^^^^^^^^^^^^^^^^^^^^^^
    ...<6 lines>...
    )
    ^
  File "/Library/Frameworks/Python.framework/Versions/3.13/lib/python3.13/site-packages/telegram/_bot.py", line 646, in _do_post
    result = await request.post(
             ^^^^^^^^^^^^^^^^^^^
    ...<6 lines>...
    )
    ^
  File "/Library/Frameworks/Python.framework/Versions/3.13/lib/python3.13/site-packages/telegram/request/_baserequest.py", line 202, in post
    result = await self._request_wrapper(
             ^^^^^^^^^^^^^^^^^^^^^^^^^^^^
    ...<7 lines>...
    )
    ^
  File "/Library/Frameworks/Python.framework/Versions/3.13/lib/python3.13/site-packages/telegram/request/_baserequest.py", line 385, in _request_wrapper
    raise Conflict(message)
telegram.error.Conflict: Conflict: terminated by other getUpdates request; make sure that only one bot instance is running
2025-10-15 20:34:17,272 - httpx - INFO - HTTP Request: POST https://api.telegram.org/bot8242076298:AAGnHplpi7Ad4hOo9z4zTugjqcCEXLJt9to/getUpdates "HTTP/1.1 200 OK"
2025-10-15 20:34:27,339 - httpx - INFO - HTTP Request: POST https://api.telegram.org/bot8242076298:AAGnHplpi7Ad4hOo9z4zTugjqcCEXLJt9to/getUpdates "HTTP/1.1 200 OK"
2025-10-15 20:34:37,447 - httpx - INFO - HTTP Request: POST https://api.telegram.org/bot8242076298:AAGnHplpi7Ad4hOo9z4zTugjqcCEXLJt9to/getUpdates "HTTP/1.1 200 OK"
2025-10-15 20:34:40,382 - httpx - INFO - HTTP Request: POST https://api.telegram.org/bot8242076298:AAGnHplpi7Ad4hOo9z4zTugjqcCEXLJt9to/getUpdates "HTTP/1.1 409 Conflict"
2025-10-15 20:34:40,383 - telegram.ext.Application - ERROR - No error handlers are registered, logging exception.
Traceback (most recent call last):
  File "/Library/Frameworks/Python.framework/Versions/3.13/lib/python3.13/site-packages/telegram/ext/_updater.py", line 743, in _network_loop_retry
    if not await do_action():
           ^^^^^^^^^^^^^^^^^
  File "/Library/Frameworks/Python.framework/Versions/3.13/lib/python3.13/site-packages/telegram/ext/_updater.py", line 737, in do_action
    return action_cb_task.result()
           ~~~~~~~~~~~~~~~~~~~~~^^
  File "/Library/Frameworks/Python.framework/Versions/3.13/lib/python3.13/site-packages/telegram/ext/_updater.py", line 367, in polling_action_cb
    updates = await self.bot.get_updates(
              ^^^^^^^^^^^^^^^^^^^^^^^^^^^
    ...<7 lines>...
    )
    ^
  File "/Library/Frameworks/Python.framework/Versions/3.13/lib/python3.13/site-packages/telegram/ext/_extbot.py", line 647, in get_updates
    updates = await super().get_updates(
              ^^^^^^^^^^^^^^^^^^^^^^^^^^
    ...<9 lines>...
    )
    ^
  File "/Library/Frameworks/Python.framework/Versions/3.13/lib/python3.13/site-packages/telegram/_bot.py", line 4421, in get_updates
    await self._post(
    ^^^^^^^^^^^^^^^^^
    ...<7 lines>...
    ),
    ^
  File "/Library/Frameworks/Python.framework/Versions/3.13/lib/python3.13/site-packages/telegram/_bot.py", line 617, in _post
    return await self._do_post(
           ^^^^^^^^^^^^^^^^^^^^
    ...<6 lines>...
    )
    ^
  File "/Library/Frameworks/Python.framework/Versions/3.13/lib/python3.13/site-packages/telegram/ext/_extbot.py", line 351, in _do_post
    return await super()._do_post(
           ^^^^^^^^^^^^^^^^^^^^^^^
    ...<6 lines>...
    )
    ^
  File "/Library/Frameworks/Python.framework/Versions/3.13/lib/python3.13/site-packages/telegram/_bot.py", line 646, in _do_post
    result = await request.post(
             ^^^^^^^^^^^^^^^^^^^
    ...<6 lines>...
    )
    ^
  File "/Library/Frameworks/Python.framework/Versions/3.13/lib/python3.13/site-packages/telegram/request/_baserequest.py", line 202, in post
    result = await self._request_wrapper(
             ^^^^^^^^^^^^^^^^^^^^^^^^^^^^
    ...<7 lines>...
    )
    ^
  File "/Library/Frameworks/Python.framework/Versions/3.13/lib/python3.13/site-packages/telegram/request/_baserequest.py", line 385, in _request_wrapper
    raise Conflict(message)
telegram.error.Conflict: Conflict: terminated by other getUpdates request; make sure that only one bot instance is running
2025-10-15 20:34:51,453 - httpx - INFO - HTTP Request: POST https://api.telegram.org/bot8242076298:AAGnHplpi7Ad4hOo9z4zTugjqcCEXLJt9to/getUpdates "HTTP/1.1 200 OK"
2025-10-15 20:35:01,614 - httpx - INFO - HTTP Request: POST https://api.telegram.org/bot8242076298:AAGnHplpi7Ad4hOo9z4zTugjqcCEXLJt9to/getUpdates "HTTP/1.1 200 OK"
2025-10-15 20:35:11,751 - httpx - INFO - HTTP Request: POST https://api.telegram.org/bot8242076298:AAGnHplpi7Ad4hOo9z4zTugjqcCEXLJt9to/getUpdates "HTTP/1.1 200 OK"
2025-10-15 20:35:14,656 - httpx - INFO - HTTP Request: POST https://api.telegram.org/bot8242076298:AAGnHplpi7Ad4hOo9z4zTugjqcCEXLJt9to/getUpdates "HTTP/1.1 409 Conflict"
2025-10-15 20:35:14,656 - telegram.ext.Application - ERROR - No error handlers are registered, logging exception.
Traceback (most recent call last):
  File "/Library/Frameworks/Python.framework/Versions/3.13/lib/python3.13/site-packages/telegram/ext/_updater.py", line 743, in _network_loop_retry
    if not await do_action():
           ^^^^^^^^^^^^^^^^^
  File "/Library/Frameworks/Python.framework/Versions/3.13/lib/python3.13/site-packages/telegram/ext/_updater.py", line 737, in do_action
    return action_cb_task.result()
           ~~~~~~~~~~~~~~~~~~~~~^^
  File "/Library/Frameworks/Python.framework/Versions/3.13/lib/python3.13/site-packages/telegram/ext/_updater.py", line 367, in polling_action_cb
    updates = await self.bot.get_updates(
              ^^^^^^^^^^^^^^^^^^^^^^^^^^^
    ...<7 lines>...
    )
    ^
  File "/Library/Frameworks/Python.framework/Versions/3.13/lib/python3.13/site-packages/telegram/ext/_extbot.py", line 647, in get_updates
    updates = await super().get_updates(
              ^^^^^^^^^^^^^^^^^^^^^^^^^^
    ...<9 lines>...
    )
    ^
  File "/Library/Frameworks/Python.framework/Versions/3.13/lib/python3.13/site-packages/telegram/_bot.py", line 4421, in get_updates
    await self._post(
    ^^^^^^^^^^^^^^^^^
    ...<7 lines>...
    ),
    ^
  File "/Library/Frameworks/Python.framework/Versions/3.13/lib/python3.13/site-packages/telegram/_bot.py", line 617, in _post
    return await self._do_post(
           ^^^^^^^^^^^^^^^^^^^^
    ...<6 lines>...
    )
    ^
  File "/Library/Frameworks/Python.framework/Versions/3.13/lib/python3.13/site-packages/telegram/ext/_extbot.py", line 351, in _do_post
    return await super()._do_post(
           ^^^^^^^^^^^^^^^^^^^^^^^
    ...<6 lines>...
    )
    ^
  File "/Library/Frameworks/Python.framework/Versions/3.13/lib/python3.13/site-packages/telegram/_bot.py", line 646, in _do_post
    result = await request.post(
             ^^^^^^^^^^^^^^^^^^^
    ...<6 lines>...
    )
    ^
  File "/Library/Frameworks/Python.framework/Versions/3.13/lib/python3.13/site-packages/telegram/request/_baserequest.py", line 202, in post
    result = await self._request_wrapper(
             ^^^^^^^^^^^^^^^^^^^^^^^^^^^^
    ...<7 lines>...
    )
    ^
  File "/Library/Frameworks/Python.framework/Versions/3.13/lib/python3.13/site-packages/telegram/request/_baserequest.py", line 385, in _request_wrapper
    raise Conflict(message)
telegram.error.Conflict: Conflict: terminated by other getUpdates request; make sure that only one bot instance is running
2025-10-15 20:35:25,721 - httpx - INFO - HTTP Request: POST https://api.telegram.org/bot8242076298:AAGnHplpi7Ad4hOo9z4zTugjqcCEXLJt9to/getUpdates "HTTP/1.1 200 OK"
2025-10-15 20:35:35,785 - httpx - INFO - HTTP Request: POST https://api.telegram.org/bot8242076298:AAGnHplpi7Ad4hOo9z4zTugjqcCEXLJt9to/getUpdates "HTTP/1.1 200 OK"
2025-10-15 20:35:45,853 - httpx - INFO - HTTP Request: POST https://api.telegram.org/bot8242076298:AAGnHplpi7Ad4hOo9z4zTugjqcCEXLJt9to/getUpdates "HTTP/1.1 200 OK"
2025-10-15 20:35:48,930 - httpx - INFO - HTTP Request: POST https://api.telegram.org/bot8242076298:AAGnHplpi7Ad4hOo9z4zTugjqcCEXLJt9to/getUpdates "HTTP/1.1 409 Conflict"
2025-10-15 20:35:48,931 - telegram.ext.Application - ERROR - No error handlers are registered, logging exception.
Traceback (most recent call last):
  File "/Library/Frameworks/Python.framework/Versions/3.13/lib/python3.13/site-packages/telegram/ext/_updater.py", line 743, in _network_loop_retry
    if not await do_action():
           ^^^^^^^^^^^^^^^^^
  File "/Library/Frameworks/Python.framework/Versions/3.13/lib/python3.13/site-packages/telegram/ext/_updater.py", line 737, in do_action
    return action_cb_task.result()
           ~~~~~~~~~~~~~~~~~~~~~^^
  File "/Library/Frameworks/Python.framework/Versions/3.13/lib/python3.13/site-packages/telegram/ext/_updater.py", line 367, in polling_action_cb
    updates = await self.bot.get_updates(
              ^^^^^^^^^^^^^^^^^^^^^^^^^^^
    ...<7 lines>...
    )
    ^
  File "/Library/Frameworks/Python.framework/Versions/3.13/lib/python3.13/site-packages/telegram/ext/_extbot.py", line 647, in get_updates
    updates = await super().get_updates(
              ^^^^^^^^^^^^^^^^^^^^^^^^^^
    ...<9 lines>...
    )
    ^
  File "/Library/Frameworks/Python.framework/Versions/3.13/lib/python3.13/site-packages/telegram/_bot.py", line 4421, in get_updates
    await self._post(
    ^^^^^^^^^^^^^^^^^
    ...<7 lines>...
    ),
    ^
  File "/Library/Frameworks/Python.framework/Versions/3.13/lib/python3.13/site-packages/telegram/_bot.py", line 617, in _post
    return await self._do_post(
           ^^^^^^^^^^^^^^^^^^^^
    ...<6 lines>...
    )
    ^
  File "/Library/Frameworks/Python.framework/Versions/3.13/lib/python3.13/site-packages/telegram/ext/_extbot.py", line 351, in _do_post
    return await super()._do_post(
           ^^^^^^^^^^^^^^^^^^^^^^^
    ...<6 lines>...
    )
    ^
  File "/Library/Frameworks/Python.framework/Versions/3.13/lib/python3.13/site-packages/telegram/_bot.py", line 646, in _do_post
    result = await request.post(
             ^^^^^^^^^^^^^^^^^^^
    ...<6 lines>...
    )
    ^
  File "/Library/Frameworks/Python.framework/Versions/3.13/lib/python3.13/site-packages/telegram/request/_baserequest.py", line 202, in post
    result = await self._request_wrapper(
             ^^^^^^^^^^^^^^^^^^^^^^^^^^^^
    ...<7 lines>...
    )
    ^
  File "/Library/Frameworks/Python.framework/Versions/3.13/lib/python3.13/site-packages/telegram/request/_baserequest.py", line 385, in _request_wrapper
    raise Conflict(message)
telegram.error.Conflict: Conflict: terminated by other getUpdates request; make sure that only one bot instance is running
2025-10-15 20:36:00,085 - httpx - INFO - HTTP Request: POST https://api.telegram.org/bot8242076298:AAGnHplpi7Ad4hOo9z4zTugjqcCEXLJt9to/getUpdates "HTTP/1.1 200 OK"
2025-10-15 20:36:10,152 - httpx - INFO - HTTP Request: POST https://api.telegram.org/bot8242076298:AAGnHplpi7Ad4hOo9z4zTugjqcCEXLJt9to/getUpdates "HTTP/1.1 200 OK"
2025-10-15 20:36:20,260 - httpx - INFO - HTTP Request: POST https://api.telegram.org/bot8242076298:AAGnHplpi7Ad4hOo9z4zTugjqcCEXLJt9to/getUpdates "HTTP/1.1 200 OK"
2025-10-15 20:36:23,233 - httpx - INFO - HTTP Request: POST https://api.telegram.org/bot8242076298:AAGnHplpi7Ad4hOo9z4zTugjqcCEXLJt9to/getUpdates "HTTP/1.1 409 Conflict"
2025-10-15 20:36:23,233 - telegram.ext.Application - ERROR - No error handlers are registered, logging exception.
Traceback (most recent call last):
  File "/Library/Frameworks/Python.framework/Versions/3.13/lib/python3.13/site-packages/telegram/ext/_updater.py", line 743, in _network_loop_retry
    if not await do_action():
           ^^^^^^^^^^^^^^^^^
  File "/Library/Frameworks/Python.framework/Versions/3.13/lib/python3.13/site-packages/telegram/ext/_updater.py", line 737, in do_action
    return action_cb_task.result()
           ~~~~~~~~~~~~~~~~~~~~~^^
  File "/Library/Frameworks/Python.framework/Versions/3.13/lib/python3.13/site-packages/telegram/ext/_updater.py", line 367, in polling_action_cb
    updates = await self.bot.get_updates(
              ^^^^^^^^^^^^^^^^^^^^^^^^^^^
    ...<7 lines>...
    )
    ^
  File "/Library/Frameworks/Python.framework/Versions/3.13/lib/python3.13/site-packages/telegram/ext/_extbot.py", line 647, in get_updates
    updates = await super().get_updates(
              ^^^^^^^^^^^^^^^^^^^^^^^^^^
    ...<9 lines>...
    )
    ^
  File "/Library/Frameworks/Python.framework/Versions/3.13/lib/python3.13/site-packages/telegram/_bot.py", line 4421, in get_updates
    await self._post(
    ^^^^^^^^^^^^^^^^^
    ...<7 lines>...
    ),
    ^
  File "/Library/Frameworks/Python.framework/Versions/3.13/lib/python3.13/site-packages/telegram/_bot.py", line 617, in _post
    return await self._do_post(
           ^^^^^^^^^^^^^^^^^^^^
    ...<6 lines>...
    )
    ^
  File "/Library/Frameworks/Python.framework/Versions/3.13/lib/python3.13/site-packages/telegram/ext/_extbot.py", line 351, in _do_post
    return await super()._do_post(
           ^^^^^^^^^^^^^^^^^^^^^^^
    ...<6 lines>...
    )
    ^
  File "/Library/Frameworks/Python.framework/Versions/3.13/lib/python3.13/site-packages/telegram/_bot.py", line 646, in _do_post
    result = await request.post(
             ^^^^^^^^^^^^^^^^^^^
    ...<6 lines>...
    )
    ^
  File "/Library/Frameworks/Python.framework/Versions/3.13/lib/python3.13/site-packages/telegram/request/_baserequest.py", line 202, in post
    result = await self._request_wrapper(
             ^^^^^^^^^^^^^^^^^^^^^^^^^^^^
    ...<7 lines>...
    )
    ^
  File "/Library/Frameworks/Python.framework/Versions/3.13/lib/python3.13/site-packages/telegram/request/_baserequest.py", line 385, in _request_wrapper
    raise Conflict(message)
telegram.error.Conflict: Conflict: terminated by other getUpdates request; make sure that only one bot instance is running
2025-10-15 20:36:34,306 - httpx - INFO - HTTP Request: POST https://api.telegram.org/bot8242076298:AAGnHplpi7Ad4hOo9z4zTugjqcCEXLJt9to/getUpdates "HTTP/1.1 200 OK"
2025-10-15 20:36:44,371 - httpx - INFO - HTTP Request: POST https://api.telegram.org/bot8242076298:AAGnHplpi7Ad4hOo9z4zTugjqcCEXLJt9to/getUpdates "HTTP/1.1 200 OK"
2025-10-15 20:36:54,459 - httpx - INFO - HTTP Request: POST https://api.telegram.org/bot8242076298:AAGnHplpi7Ad4hOo9z4zTugjqcCEXLJt9to/getUpdates "HTTP/1.1 200 OK"
2025-10-15 20:36:57,524 - httpx - INFO - HTTP Request: POST https://api.telegram.org/bot8242076298:AAGnHplpi7Ad4hOo9z4zTugjqcCEXLJt9to/getUpdates "HTTP/1.1 409 Conflict"
2025-10-15 20:36:57,526 - telegram.ext.Application - ERROR - No error handlers are registered, logging exception.
Traceback (most recent call last):
  File "/Library/Frameworks/Python.framework/Versions/3.13/lib/python3.13/site-packages/telegram/ext/_updater.py", line 743, in _network_loop_retry
    if not await do_action():
           ^^^^^^^^^^^^^^^^^
  File "/Library/Frameworks/Python.framework/Versions/3.13/lib/python3.13/site-packages/telegram/ext/_updater.py", line 737, in do_action
    return action_cb_task.result()
           ~~~~~~~~~~~~~~~~~~~~~^^
  File "/Library/Frameworks/Python.framework/Versions/3.13/lib/python3.13/site-packages/telegram/ext/_updater.py", line 367, in polling_action_cb
    updates = await self.bot.get_updates(
              ^^^^^^^^^^^^^^^^^^^^^^^^^^^
    ...<7 lines>...
    )
    ^
  File "/Library/Frameworks/Python.framework/Versions/3.13/lib/python3.13/site-packages/telegram/ext/_extbot.py", line 647, in get_updates
    updates = await super().get_updates(
              ^^^^^^^^^^^^^^^^^^^^^^^^^^
    ...<9 lines>...
    )
    ^
  File "/Library/Frameworks/Python.framework/Versions/3.13/lib/python3.13/site-packages/telegram/_bot.py", line 4421, in get_updates
    await self._post(
    ^^^^^^^^^^^^^^^^^
    ...<7 lines>...
    ),
    ^
  File "/Library/Frameworks/Python.framework/Versions/3.13/lib/python3.13/site-packages/telegram/_bot.py", line 617, in _post
    return await self._do_post(
           ^^^^^^^^^^^^^^^^^^^^
    ...<6 lines>...
    )
    ^
  File "/Library/Frameworks/Python.framework/Versions/3.13/lib/python3.13/site-packages/telegram/ext/_extbot.py", line 351, in _do_post
    return await super()._do_post(
           ^^^^^^^^^^^^^^^^^^^^^^^
    ...<6 lines>...
    )
    ^
  File "/Library/Frameworks/Python.framework/Versions/3.13/lib/python3.13/site-packages/telegram/_bot.py", line 646, in _do_post
    result = await request.post(
             ^^^^^^^^^^^^^^^^^^^
    ...<6 lines>...
    )
    ^
  File "/Library/Frameworks/Python.framework/Versions/3.13/lib/python3.13/site-packages/telegram/request/_baserequest.py", line 202, in post
    result = await self._request_wrapper(
             ^^^^^^^^^^^^^^^^^^^^^^^^^^^^
    ...<7 lines>...
    )
    ^
  File "/Library/Frameworks/Python.framework/Versions/3.13/lib/python3.13/site-packages/telegram/request/_baserequest.py", line 385, in _request_wrapper
    raise Conflict(message)
telegram.error.Conflict: Conflict: terminated by other getUpdates request; make sure that only one bot instance is running
2025-10-15 20:37:08,600 - httpx - INFO - HTTP Request: POST https://api.telegram.org/bot8242076298:AAGnHplpi7Ad4hOo9z4zTugjqcCEXLJt9to/getUpdates "HTTP/1.1 200 OK"
2025-10-15 20:37:18,672 - httpx - INFO - HTTP Request: POST https://api.telegram.org/bot8242076298:AAGnHplpi7Ad4hOo9z4zTugjqcCEXLJt9to/getUpdates "HTTP/1.1 200 OK"
2025-10-15 20:37:28,742 - httpx - INFO - HTTP Request: POST https://api.telegram.org/bot8242076298:AAGnHplpi7Ad4hOo9z4zTugjqcCEXLJt9to/getUpdates "HTTP/1.1 200 OK"
2025-10-15 20:37:31,828 - httpx - INFO - HTTP Request: POST https://api.telegram.org/bot8242076298:AAGnHplpi7Ad4hOo9z4zTugjqcCEXLJt9to/getUpdates "HTTP/1.1 409 Conflict"
2025-10-15 20:37:31,829 - telegram.ext.Application - ERROR - No error handlers are registered, logging exception.
Traceback (most recent call last):
  File "/Library/Frameworks/Python.framework/Versions/3.13/lib/python3.13/site-packages/telegram/ext/_updater.py", line 743, in _network_loop_retry
    if not await do_action():
           ^^^^^^^^^^^^^^^^^
  File "/Library/Frameworks/Python.framework/Versions/3.13/lib/python3.13/site-packages/telegram/ext/_updater.py", line 737, in do_action
    return action_cb_task.result()
           ~~~~~~~~~~~~~~~~~~~~~^^
  File "/Library/Frameworks/Python.framework/Versions/3.13/lib/python3.13/site-packages/telegram/ext/_updater.py", line 367, in polling_action_cb
    updates = await self.bot.get_updates(
              ^^^^^^^^^^^^^^^^^^^^^^^^^^^
    ...<7 lines>...
    )
    ^
  File "/Library/Frameworks/Python.framework/Versions/3.13/lib/python3.13/site-packages/telegram/ext/_extbot.py", line 647, in get_updates
    updates = await super().get_updates(
              ^^^^^^^^^^^^^^^^^^^^^^^^^^
    ...<9 lines>...
    )
    ^
  File "/Library/Frameworks/Python.framework/Versions/3.13/lib/python3.13/site-packages/telegram/_bot.py", line 4421, in get_updates
    await self._post(
    ^^^^^^^^^^^^^^^^^
    ...<7 lines>...
    ),
    ^
  File "/Library/Frameworks/Python.framework/Versions/3.13/lib/python3.13/site-packages/telegram/_bot.py", line 617, in _post
    return await self._do_post(
           ^^^^^^^^^^^^^^^^^^^^
    ...<6 lines>...
    )
    ^
  File "/Library/Frameworks/Python.framework/Versions/3.13/lib/python3.13/site-packages/telegram/ext/_extbot.py", line 351, in _do_post
    return await super()._do_post(
           ^^^^^^^^^^^^^^^^^^^^^^^
    ...<6 lines>...
    )
    ^
  File "/Library/Frameworks/Python.framework/Versions/3.13/lib/python3.13/site-packages/telegram/_bot.py", line 646, in _do_post
    result = await request.post(
             ^^^^^^^^^^^^^^^^^^^
    ...<6 lines>...
    )
    ^
  File "/Library/Frameworks/Python.framework/Versions/3.13/lib/python3.13/site-packages/telegram/request/_baserequest.py", line 202, in post
    result = await self._request_wrapper(
             ^^^^^^^^^^^^^^^^^^^^^^^^^^^^
    ...<7 lines>...
    )
    ^
  File "/Library/Frameworks/Python.framework/Versions/3.13/lib/python3.13/site-packages/telegram/request/_baserequest.py", line 385, in _request_wrapper
    raise Conflict(message)
telegram.error.Conflict: Conflict: terminated by other getUpdates request; make sure that only one bot instance is running
2025-10-15 20:37:42,902 - httpx - INFO - HTTP Request: POST https://api.telegram.org/bot8242076298:AAGnHplpi7Ad4hOo9z4zTugjqcCEXLJt9to/getUpdates "HTTP/1.1 200 OK"
2025-10-15 20:37:52,979 - httpx - INFO - HTTP Request: POST https://api.telegram.org/bot8242076298:AAGnHplpi7Ad4hOo9z4zTugjqcCEXLJt9to/getUpdates "HTTP/1.1 200 OK"
2025-10-15 20:38:03,050 - httpx - INFO - HTTP Request: POST https://api.telegram.org/bot8242076298:AAGnHplpi7Ad4hOo9z4zTugjqcCEXLJt9to/getUpdates "HTTP/1.1 200 OK"
2025-10-15 20:38:06,113 - httpx - INFO - HTTP Request: POST https://api.telegram.org/bot8242076298:AAGnHplpi7Ad4hOo9z4zTugjqcCEXLJt9to/getUpdates "HTTP/1.1 409 Conflict"
2025-10-15 20:38:06,113 - telegram.ext.Application - ERROR - No error handlers are registered, logging exception.
Traceback (most recent call last):
  File "/Library/Frameworks/Python.framework/Versions/3.13/lib/python3.13/site-packages/telegram/ext/_updater.py", line 743, in _network_loop_retry
    if not await do_action():
           ^^^^^^^^^^^^^^^^^
  File "/Library/Frameworks/Python.framework/Versions/3.13/lib/python3.13/site-packages/telegram/ext/_updater.py", line 737, in do_action
    return action_cb_task.result()
           ~~~~~~~~~~~~~~~~~~~~~^^
  File "/Library/Frameworks/Python.framework/Versions/3.13/lib/python3.13/site-packages/telegram/ext/_updater.py", line 367, in polling_action_cb
    updates = await self.bot.get_updates(
              ^^^^^^^^^^^^^^^^^^^^^^^^^^^
    ...<7 lines>...
    )
    ^
  File "/Library/Frameworks/Python.framework/Versions/3.13/lib/python3.13/site-packages/telegram/ext/_extbot.py", line 647, in get_updates
    updates = await super().get_updates(
              ^^^^^^^^^^^^^^^^^^^^^^^^^^
    ...<9 lines>...
    )
    ^
  File "/Library/Frameworks/Python.framework/Versions/3.13/lib/python3.13/site-packages/telegram/_bot.py", line 4421, in get_updates
    await self._post(
    ^^^^^^^^^^^^^^^^^
    ...<7 lines>...
    ),
    ^
  File "/Library/Frameworks/Python.framework/Versions/3.13/lib/python3.13/site-packages/telegram/_bot.py", line 617, in _post
    return await self._do_post(
           ^^^^^^^^^^^^^^^^^^^^
    ...<6 lines>...
    )
    ^
  File "/Library/Frameworks/Python.framework/Versions/3.13/lib/python3.13/site-packages/telegram/ext/_extbot.py", line 351, in _do_post
    return await super()._do_post(
           ^^^^^^^^^^^^^^^^^^^^^^^
    ...<6 lines>...
    )
    ^
  File "/Library/Frameworks/Python.framework/Versions/3.13/lib/python3.13/site-packages/telegram/_bot.py", line 646, in _do_post
    result = await request.post(
             ^^^^^^^^^^^^^^^^^^^
    ...<6 lines>...
    )
    ^
  File "/Library/Frameworks/Python.framework/Versions/3.13/lib/python3.13/site-packages/telegram/request/_baserequest.py", line 202, in post
    result = await self._request_wrapper(
             ^^^^^^^^^^^^^^^^^^^^^^^^^^^^
    ...<7 lines>...
    )
    ^
  File "/Library/Frameworks/Python.framework/Versions/3.13/lib/python3.13/site-packages/telegram/request/_baserequest.py", line 385, in _request_wrapper
    raise Conflict(message)
telegram.error.Conflict: Conflict: terminated by other getUpdates request; make sure that only one bot instance is running
