ü§ñ –ó–∞–ø—É—Å–∫ –±–æ—Ç–∞ DUNGEON Hookah...
üìÅ –î–∏—Ä–µ–∫—Ç–æ—Ä–∏—è: /Users/nikolajmisin/Documents/WebApp/next-app
üìù –õ–æ–≥ —Ñ–∞–π–ª: /Users/nikolajmisin/Documents/WebApp/next-app/bot.log

‚ñ∂Ô∏è  –ó–∞–ø—É—Å–∫ –±–æ—Ç–∞ –≤ 2025-10-15 20:28:44
2025-10-15 20:28:44,552 - __main__ - INFO - üöÄ Starting bot in polling mode...
2025-10-15 20:28:44,808 - httpx - INFO - HTTP Request: POST https://api.telegram.org/bot8242076298:AAGnHplpi7Ad4hOo9z4zTugjqcCEXLJt9to/getMe "HTTP/1.1 200 OK"
2025-10-15 20:28:44,874 - httpx - INFO - HTTP Request: POST https://api.telegram.org/bot8242076298:AAGnHplpi7Ad4hOo9z4zTugjqcCEXLJt9to/deleteWebhook "HTTP/1.1 200 OK"
2025-10-15 20:28:44,876 - telegram.ext.Application - INFO - Application started
2025-10-15 20:28:49,330 - httpx - INFO - HTTP Request: POST https://api.telegram.org/bot8242076298:AAGnHplpi7Ad4hOo9z4zTugjqcCEXLJt9to/getUpdates "HTTP/1.1 409 Conflict"
2025-10-15 20:28:49,332 - telegram.ext.Application - ERROR - No error handlers are registered, logging exception.
Traceback (most recent call last):
  File "/Library/Frameworks/Python.framework/Versions/3.13/lib/python3.13/site-packages/telegram/ext/_updater.py", line 743, in _network_loop_retry
    if not await do_action():
           ^^^^^^^^^^^^^^^^^
  File "/Library/Frameworks/Python.framework/Versions/3.13/lib/python3.13/site-packages/telegram/ext/_updater.py", line 737, in do_action
    return action_cb_task.result()
           ~~~~~~~~~~~~~~~~~~~~~^^
  File "/Library/Frameworks/Python.framework/Versions/3.13/lib/python3.13/site-packages/telegram/ext/_updater.py", line 367, in polling_action_cb
    updates = await self.bot.get_updates(
              ^^^^^^^^^^^^^^^^^^^^^^^^^^^
    ...<7 lines>...
    )
    ^
  File "/Library/Frameworks/Python.framework/Versions/3.13/lib/python3.13/site-packages/telegram/ext/_extbot.py", line 647, in get_updates
    updates = await super().get_updates(
              ^^^^^^^^^^^^^^^^^^^^^^^^^^
    ...<9 lines>...
    )
    ^
  File "/Library/Frameworks/Python.framework/Versions/3.13/lib/python3.13/site-packages/telegram/_bot.py", line 4421, in get_updates
    await self._post(
    ^^^^^^^^^^^^^^^^^
    ...<7 lines>...
    ),
    ^
  File "/Library/Frameworks/Python.framework/Versions/3.13/lib/python3.13/site-packages/telegram/_bot.py", line 617, in _post
    return await self._do_post(
           ^^^^^^^^^^^^^^^^^^^^
    ...<6 lines>...
    )
    ^
  File "/Library/Frameworks/Python.framework/Versions/3.13/lib/python3.13/site-packages/telegram/ext/_extbot.py", line 351, in _do_post
    return await super()._do_post(
           ^^^^^^^^^^^^^^^^^^^^^^^
    ...<6 lines>...
    )
    ^
  File "/Library/Frameworks/Python.framework/Versions/3.13/lib/python3.13/site-packages/telegram/_bot.py", line 646, in _do_post
    result = await request.post(
             ^^^^^^^^^^^^^^^^^^^
    ...<6 lines>...
    )
    ^
  File "/Library/Frameworks/Python.framework/Versions/3.13/lib/python3.13/site-packages/telegram/request/_baserequest.py", line 202, in post
    result = await self._request_wrapper(
             ^^^^^^^^^^^^^^^^^^^^^^^^^^^^
    ...<7 lines>...
    )
    ^
  File "/Library/Frameworks/Python.framework/Versions/3.13/lib/python3.13/site-packages/telegram/request/_baserequest.py", line 385, in _request_wrapper
    raise Conflict(message)
telegram.error.Conflict: Conflict: terminated by other getUpdates request; make sure that only one bot instance is running
2025-10-15 20:28:54,967 - httpx - INFO - HTTP Request: POST https://api.telegram.org/bot8242076298:AAGnHplpi7Ad4hOo9z4zTugjqcCEXLJt9to/getUpdates "HTTP/1.1 409 Conflict"
2025-10-15 20:28:54,969 - telegram.ext.Application - ERROR - No error handlers are registered, logging exception.
Traceback (most recent call last):
  File "/Library/Frameworks/Python.framework/Versions/3.13/lib/python3.13/site-packages/telegram/ext/_updater.py", line 743, in _network_loop_retry
    if not await do_action():
           ^^^^^^^^^^^^^^^^^
  File "/Library/Frameworks/Python.framework/Versions/3.13/lib/python3.13/site-packages/telegram/ext/_updater.py", line 737, in do_action
    return action_cb_task.result()
           ~~~~~~~~~~~~~~~~~~~~~^^
  File "/Library/Frameworks/Python.framework/Versions/3.13/lib/python3.13/site-packages/telegram/ext/_updater.py", line 367, in polling_action_cb
    updates = await self.bot.get_updates(
              ^^^^^^^^^^^^^^^^^^^^^^^^^^^
    ...<7 lines>...
    )
    ^
  File "/Library/Frameworks/Python.framework/Versions/3.13/lib/python3.13/site-packages/telegram/ext/_extbot.py", line 647, in get_updates
    updates = await super().get_updates(
              ^^^^^^^^^^^^^^^^^^^^^^^^^^
    ...<9 lines>...
    )
    ^
  File "/Library/Frameworks/Python.framework/Versions/3.13/lib/python3.13/site-packages/telegram/_bot.py", line 4421, in get_updates
    await self._post(
    ^^^^^^^^^^^^^^^^^
    ...<7 lines>...
    ),
    ^
  File "/Library/Frameworks/Python.framework/Versions/3.13/lib/python3.13/site-packages/telegram/_bot.py", line 617, in _post
    return await self._do_post(
           ^^^^^^^^^^^^^^^^^^^^
    ...<6 lines>...
    )
    ^
  File "/Library/Frameworks/Python.framework/Versions/3.13/lib/python3.13/site-packages/telegram/ext/_extbot.py", line 351, in _do_post
    return await super()._do_post(
           ^^^^^^^^^^^^^^^^^^^^^^^
    ...<6 lines>...
    )
    ^
  File "/Library/Frameworks/Python.framework/Versions/3.13/lib/python3.13/site-packages/telegram/_bot.py", line 646, in _do_post
    result = await request.post(
             ^^^^^^^^^^^^^^^^^^^
    ...<6 lines>...
    )
    ^
  File "/Library/Frameworks/Python.framework/Versions/3.13/lib/python3.13/site-packages/telegram/request/_baserequest.py", line 202, in post
    result = await self._request_wrapper(
             ^^^^^^^^^^^^^^^^^^^^^^^^^^^^
    ...<7 lines>...
    )
    ^
  File "/Library/Frameworks/Python.framework/Versions/3.13/lib/python3.13/site-packages/telegram/request/_baserequest.py", line 385, in _request_wrapper
    raise Conflict(message)
telegram.error.Conflict: Conflict: terminated by other getUpdates request; make sure that only one bot instance is running
2025-10-15 20:29:01,941 - httpx - INFO - HTTP Request: POST https://api.telegram.org/bot8242076298:AAGnHplpi7Ad4hOo9z4zTugjqcCEXLJt9to/getUpdates "HTTP/1.1 409 Conflict"
2025-10-15 20:29:01,942 - telegram.ext.Application - ERROR - No error handlers are registered, logging exception.
Traceback (most recent call last):
  File "/Library/Frameworks/Python.framework/Versions/3.13/lib/python3.13/site-packages/telegram/ext/_updater.py", line 743, in _network_loop_retry
    if not await do_action():
           ^^^^^^^^^^^^^^^^^
  File "/Library/Frameworks/Python.framework/Versions/3.13/lib/python3.13/site-packages/telegram/ext/_updater.py", line 737, in do_action
    return action_cb_task.result()
           ~~~~~~~~~~~~~~~~~~~~~^^
  File "/Library/Frameworks/Python.framework/Versions/3.13/lib/python3.13/site-packages/telegram/ext/_updater.py", line 367, in polling_action_cb
    updates = await self.bot.get_updates(
              ^^^^^^^^^^^^^^^^^^^^^^^^^^^
    ...<7 lines>...
    )
    ^
  File "/Library/Frameworks/Python.framework/Versions/3.13/lib/python3.13/site-packages/telegram/ext/_extbot.py", line 647, in get_updates
    updates = await super().get_updates(
              ^^^^^^^^^^^^^^^^^^^^^^^^^^
    ...<9 lines>...
    )
    ^
  File "/Library/Frameworks/Python.framework/Versions/3.13/lib/python3.13/site-packages/telegram/_bot.py", line 4421, in get_updates
    await self._post(
    ^^^^^^^^^^^^^^^^^
    ...<7 lines>...
    ),
    ^
  File "/Library/Frameworks/Python.framework/Versions/3.13/lib/python3.13/site-packages/telegram/_bot.py", line 617, in _post
    return await self._do_post(
           ^^^^^^^^^^^^^^^^^^^^
    ...<6 lines>...
    )
    ^
  File "/Library/Frameworks/Python.framework/Versions/3.13/lib/python3.13/site-packages/telegram/ext/_extbot.py", line 351, in _do_post
    return await super()._do_post(
           ^^^^^^^^^^^^^^^^^^^^^^^
    ...<6 lines>...
    )
    ^
  File "/Library/Frameworks/Python.framework/Versions/3.13/lib/python3.13/site-packages/telegram/_bot.py", line 646, in _do_post
    result = await request.post(
             ^^^^^^^^^^^^^^^^^^^
    ...<6 lines>...
    )
    ^
  File "/Library/Frameworks/Python.framework/Versions/3.13/lib/python3.13/site-packages/telegram/request/_baserequest.py", line 202, in post
    result = await self._request_wrapper(
             ^^^^^^^^^^^^^^^^^^^^^^^^^^^^
    ...<7 lines>...
    )
    ^
  File "/Library/Frameworks/Python.framework/Versions/3.13/lib/python3.13/site-packages/telegram/request/_baserequest.py", line 385, in _request_wrapper
    raise Conflict(message)
telegram.error.Conflict: Conflict: terminated by other getUpdates request; make sure that only one bot instance is running
2025-10-15 20:29:07,707 - httpx - INFO - HTTP Request: POST https://api.telegram.org/bot8242076298:AAGnHplpi7Ad4hOo9z4zTugjqcCEXLJt9to/getUpdates "HTTP/1.1 409 Conflict"
2025-10-15 20:29:07,709 - telegram.ext.Application - ERROR - No error handlers are registered, logging exception.
Traceback (most recent call last):
  File "/Library/Frameworks/Python.framework/Versions/3.13/lib/python3.13/site-packages/telegram/ext/_updater.py", line 743, in _network_loop_retry
    if not await do_action():
           ^^^^^^^^^^^^^^^^^
  File "/Library/Frameworks/Python.framework/Versions/3.13/lib/python3.13/site-packages/telegram/ext/_updater.py", line 737, in do_action
    return action_cb_task.result()
           ~~~~~~~~~~~~~~~~~~~~~^^
  File "/Library/Frameworks/Python.framework/Versions/3.13/lib/python3.13/site-packages/telegram/ext/_updater.py", line 367, in polling_action_cb
    updates = await self.bot.get_updates(
              ^^^^^^^^^^^^^^^^^^^^^^^^^^^
    ...<7 lines>...
    )
    ^
  File "/Library/Frameworks/Python.framework/Versions/3.13/lib/python3.13/site-packages/telegram/ext/_extbot.py", line 647, in get_updates
    updates = await super().get_updates(
              ^^^^^^^^^^^^^^^^^^^^^^^^^^
    ...<9 lines>...
    )
    ^
  File "/Library/Frameworks/Python.framework/Versions/3.13/lib/python3.13/site-packages/telegram/_bot.py", line 4421, in get_updates
    await self._post(
    ^^^^^^^^^^^^^^^^^
    ...<7 lines>...
    ),
    ^
  File "/Library/Frameworks/Python.framework/Versions/3.13/lib/python3.13/site-packages/telegram/_bot.py", line 617, in _post
    return await self._do_post(
           ^^^^^^^^^^^^^^^^^^^^
    ...<6 lines>...
    )
    ^
  File "/Library/Frameworks/Python.framework/Versions/3.13/lib/python3.13/site-packages/telegram/ext/_extbot.py", line 351, in _do_post
    return await super()._do_post(
           ^^^^^^^^^^^^^^^^^^^^^^^
    ...<6 lines>...
    )
    ^
  File "/Library/Frameworks/Python.framework/Versions/3.13/lib/python3.13/site-packages/telegram/_bot.py", line 646, in _do_post
    result = await request.post(
             ^^^^^^^^^^^^^^^^^^^
    ...<6 lines>...
    )
    ^
  File "/Library/Frameworks/Python.framework/Versions/3.13/lib/python3.13/site-packages/telegram/request/_baserequest.py", line 202, in post
    result = await self._request_wrapper(
             ^^^^^^^^^^^^^^^^^^^^^^^^^^^^
    ...<7 lines>...
    )
    ^
  File "/Library/Frameworks/Python.framework/Versions/3.13/lib/python3.13/site-packages/telegram/request/_baserequest.py", line 385, in _request_wrapper
    raise Conflict(message)
telegram.error.Conflict: Conflict: terminated by other getUpdates request; make sure that only one bot instance is running
2025-10-15 20:29:16,420 - httpx - INFO - HTTP Request: POST https://api.telegram.org/bot8242076298:AAGnHplpi7Ad4hOo9z4zTugjqcCEXLJt9to/getUpdates "HTTP/1.1 409 Conflict"
2025-10-15 20:29:16,422 - telegram.ext.Application - ERROR - No error handlers are registered, logging exception.
Traceback (most recent call last):
  File "/Library/Frameworks/Python.framework/Versions/3.13/lib/python3.13/site-packages/telegram/ext/_updater.py", line 743, in _network_loop_retry
    if not await do_action():
           ^^^^^^^^^^^^^^^^^
  File "/Library/Frameworks/Python.framework/Versions/3.13/lib/python3.13/site-packages/telegram/ext/_updater.py", line 737, in do_action
    return action_cb_task.result()
           ~~~~~~~~~~~~~~~~~~~~~^^
  File "/Library/Frameworks/Python.framework/Versions/3.13/lib/python3.13/site-packages/telegram/ext/_updater.py", line 367, in polling_action_cb
    updates = await self.bot.get_updates(
              ^^^^^^^^^^^^^^^^^^^^^^^^^^^
    ...<7 lines>...
    )
    ^
  File "/Library/Frameworks/Python.framework/Versions/3.13/lib/python3.13/site-packages/telegram/ext/_extbot.py", line 647, in get_updates
    updates = await super().get_updates(
              ^^^^^^^^^^^^^^^^^^^^^^^^^^
    ...<9 lines>...
    )
    ^
  File "/Library/Frameworks/Python.framework/Versions/3.13/lib/python3.13/site-packages/telegram/_bot.py", line 4421, in get_updates
    await self._post(
    ^^^^^^^^^^^^^^^^^
    ...<7 lines>...
    ),
    ^
  File "/Library/Frameworks/Python.framework/Versions/3.13/lib/python3.13/site-packages/telegram/_bot.py", line 617, in _post
    return await self._do_post(
           ^^^^^^^^^^^^^^^^^^^^
    ...<6 lines>...
    )
    ^
  File "/Library/Frameworks/Python.framework/Versions/3.13/lib/python3.13/site-packages/telegram/ext/_extbot.py", line 351, in _do_post
    return await super()._do_post(
           ^^^^^^^^^^^^^^^^^^^^^^^
    ...<6 lines>...
    )
    ^
  File "/Library/Frameworks/Python.framework/Versions/3.13/lib/python3.13/site-packages/telegram/_bot.py", line 646, in _do_post
    result = await request.post(
             ^^^^^^^^^^^^^^^^^^^
    ...<6 lines>...
    )
    ^
  File "/Library/Frameworks/Python.framework/Versions/3.13/lib/python3.13/site-packages/telegram/request/_baserequest.py", line 202, in post
    result = await self._request_wrapper(
             ^^^^^^^^^^^^^^^^^^^^^^^^^^^^
    ...<7 lines>...
    )
    ^
  File "/Library/Frameworks/Python.framework/Versions/3.13/lib/python3.13/site-packages/telegram/request/_baserequest.py", line 385, in _request_wrapper
    raise Conflict(message)
telegram.error.Conflict: Conflict: terminated by other getUpdates request; make sure that only one bot instance is running
2025-10-15 20:29:29,497 - httpx - INFO - HTTP Request: POST https://api.telegram.org/bot8242076298:AAGnHplpi7Ad4hOo9z4zTugjqcCEXLJt9to/getUpdates "HTTP/1.1 409 Conflict"
2025-10-15 20:29:29,498 - telegram.ext.Application - ERROR - No error handlers are registered, logging exception.
Traceback (most recent call last):
  File "/Library/Frameworks/Python.framework/Versions/3.13/lib/python3.13/site-packages/telegram/ext/_updater.py", line 743, in _network_loop_retry
    if not await do_action():
           ^^^^^^^^^^^^^^^^^
  File "/Library/Frameworks/Python.framework/Versions/3.13/lib/python3.13/site-packages/telegram/ext/_updater.py", line 737, in do_action
    return action_cb_task.result()
           ~~~~~~~~~~~~~~~~~~~~~^^
  File "/Library/Frameworks/Python.framework/Versions/3.13/lib/python3.13/site-packages/telegram/ext/_updater.py", line 367, in polling_action_cb
    updates = await self.bot.get_updates(
              ^^^^^^^^^^^^^^^^^^^^^^^^^^^
    ...<7 lines>...
    )
    ^
  File "/Library/Frameworks/Python.framework/Versions/3.13/lib/python3.13/site-packages/telegram/ext/_extbot.py", line 647, in get_updates
    updates = await super().get_updates(
              ^^^^^^^^^^^^^^^^^^^^^^^^^^
    ...<9 lines>...
    )
    ^
  File "/Library/Frameworks/Python.framework/Versions/3.13/lib/python3.13/site-packages/telegram/_bot.py", line 4421, in get_updates
    await self._post(
    ^^^^^^^^^^^^^^^^^
    ...<7 lines>...
    ),
    ^
  File "/Library/Frameworks/Python.framework/Versions/3.13/lib/python3.13/site-packages/telegram/_bot.py", line 617, in _post
    return await self._do_post(
           ^^^^^^^^^^^^^^^^^^^^
    ...<6 lines>...
    )
    ^
  File "/Library/Frameworks/Python.framework/Versions/3.13/lib/python3.13/site-packages/telegram/ext/_extbot.py", line 351, in _do_post
    return await super()._do_post(
           ^^^^^^^^^^^^^^^^^^^^^^^
    ...<6 lines>...
    )
    ^
  File "/Library/Frameworks/Python.framework/Versions/3.13/lib/python3.13/site-packages/telegram/_bot.py", line 646, in _do_post
    result = await request.post(
             ^^^^^^^^^^^^^^^^^^^
    ...<6 lines>...
    )
    ^
  File "/Library/Frameworks/Python.framework/Versions/3.13/lib/python3.13/site-packages/telegram/request/_baserequest.py", line 202, in post
    result = await self._request_wrapper(
             ^^^^^^^^^^^^^^^^^^^^^^^^^^^^
    ...<7 lines>...
    )
    ^
  File "/Library/Frameworks/Python.framework/Versions/3.13/lib/python3.13/site-packages/telegram/request/_baserequest.py", line 385, in _request_wrapper
    raise Conflict(message)
telegram.error.Conflict: Conflict: terminated by other getUpdates request; make sure that only one bot instance is running
2025-10-15 20:29:47,302 - httpx - INFO - HTTP Request: POST https://api.telegram.org/bot8242076298:AAGnHplpi7Ad4hOo9z4zTugjqcCEXLJt9to/getUpdates "HTTP/1.1 200 OK"
2025-10-15 20:29:48,898 - httpx - INFO - HTTP Request: POST https://api.telegram.org/bot8242076298:AAGnHplpi7Ad4hOo9z4zTugjqcCEXLJt9to/getUpdates "HTTP/1.1 409 Conflict"
2025-10-15 20:29:48,899 - telegram.ext.Application - ERROR - No error handlers are registered, logging exception.
Traceback (most recent call last):
  File "/Library/Frameworks/Python.framework/Versions/3.13/lib/python3.13/site-packages/telegram/ext/_updater.py", line 743, in _network_loop_retry
    if not await do_action():
           ^^^^^^^^^^^^^^^^^
  File "/Library/Frameworks/Python.framework/Versions/3.13/lib/python3.13/site-packages/telegram/ext/_updater.py", line 737, in do_action
    return action_cb_task.result()
           ~~~~~~~~~~~~~~~~~~~~~^^
  File "/Library/Frameworks/Python.framework/Versions/3.13/lib/python3.13/site-packages/telegram/ext/_updater.py", line 367, in polling_action_cb
    updates = await self.bot.get_updates(
              ^^^^^^^^^^^^^^^^^^^^^^^^^^^
    ...<7 lines>...
    )
    ^
  File "/Library/Frameworks/Python.framework/Versions/3.13/lib/python3.13/site-packages/telegram/ext/_extbot.py", line 647, in get_updates
    updates = await super().get_updates(
              ^^^^^^^^^^^^^^^^^^^^^^^^^^
    ...<9 lines>...
    )
    ^
  File "/Library/Frameworks/Python.framework/Versions/3.13/lib/python3.13/site-packages/telegram/_bot.py", line 4421, in get_updates
    await self._post(
    ^^^^^^^^^^^^^^^^^
    ...<7 lines>...
    ),
    ^
  File "/Library/Frameworks/Python.framework/Versions/3.13/lib/python3.13/site-packages/telegram/_bot.py", line 617, in _post
    return await self._do_post(
           ^^^^^^^^^^^^^^^^^^^^
    ...<6 lines>...
    )
    ^
  File "/Library/Frameworks/Python.framework/Versions/3.13/lib/python3.13/site-packages/telegram/ext/_extbot.py", line 351, in _do_post
    return await super()._do_post(
           ^^^^^^^^^^^^^^^^^^^^^^^
    ...<6 lines>...
    )
    ^
  File "/Library/Frameworks/Python.framework/Versions/3.13/lib/python3.13/site-packages/telegram/_bot.py", line 646, in _do_post
    result = await request.post(
             ^^^^^^^^^^^^^^^^^^^
    ...<6 lines>...
    )
    ^
  File "/Library/Frameworks/Python.framework/Versions/3.13/lib/python3.13/site-packages/telegram/request/_baserequest.py", line 202, in post
    result = await self._request_wrapper(
             ^^^^^^^^^^^^^^^^^^^^^^^^^^^^
    ...<7 lines>...
    )
    ^
  File "/Library/Frameworks/Python.framework/Versions/3.13/lib/python3.13/site-packages/telegram/request/_baserequest.py", line 385, in _request_wrapper
    raise Conflict(message)
telegram.error.Conflict: Conflict: terminated by other getUpdates request; make sure that only one bot instance is running
2025-10-15 20:29:52,577 - httpx - INFO - HTTP Request: POST https://api.telegram.org/bot8242076298:AAGnHplpi7Ad4hOo9z4zTugjqcCEXLJt9to/getUpdates "HTTP/1.1 200 OK"
2025-10-15 20:29:52,579 - __main__ - INFO - üöÄ START COMMAND CALLED!
2025-10-15 20:29:52,579 - __main__ - INFO - User 937011437 (shadowskydie) started the bot
2025-10-15 20:29:52,846 - httpx - INFO - HTTP Request: POST https://api.telegram.org/bot8242076298:AAGnHplpi7Ad4hOo9z4zTugjqcCEXLJt9to/sendMessage "HTTP/1.1 200 OK"
2025-10-15 20:29:53,821 - httpx - INFO - HTTP Request: POST https://api.telegram.org/bot8242076298:AAGnHplpi7Ad4hOo9z4zTugjqcCEXLJt9to/getUpdates "HTTP/1.1 200 OK"
2025-10-15 20:29:53,822 - __main__ - INFO - üöÄ START COMMAND CALLED!
2025-10-15 20:29:53,822 - __main__ - INFO - User 937011437 (shadowskydie) started the bot
2025-10-15 20:29:54,030 - httpx - INFO - HTTP Request: POST https://api.telegram.org/bot8242076298:AAGnHplpi7Ad4hOo9z4zTugjqcCEXLJt9to/sendMessage "HTTP/1.1 200 OK"
2025-10-15 20:29:54,785 - httpx - INFO - HTTP Request: POST https://api.telegram.org/bot8242076298:AAGnHplpi7Ad4hOo9z4zTugjqcCEXLJt9to/getUpdates "HTTP/1.1 200 OK"
2025-10-15 20:29:54,786 - __main__ - INFO - üöÄ START COMMAND CALLED!
2025-10-15 20:29:54,786 - __main__ - INFO - User 937011437 (shadowskydie) started the bot
2025-10-15 20:29:54,994 - httpx - INFO - HTTP Request: POST https://api.telegram.org/bot8242076298:AAGnHplpi7Ad4hOo9z4zTugjqcCEXLJt9to/sendMessage "HTTP/1.1 200 OK"
2025-10-15 20:30:04,851 - httpx - INFO - HTTP Request: POST https://api.telegram.org/bot8242076298:AAGnHplpi7Ad4hOo9z4zTugjqcCEXLJt9to/getUpdates "HTTP/1.1 200 OK"
2025-10-15 20:30:10,261 - httpx - INFO - HTTP Request: POST https://api.telegram.org/bot8242076298:AAGnHplpi7Ad4hOo9z4zTugjqcCEXLJt9to/getUpdates "HTTP/1.1 409 Conflict"
2025-10-15 20:30:10,262 - telegram.ext.Application - ERROR - No error handlers are registered, logging exception.
Traceback (most recent call last):
  File "/Library/Frameworks/Python.framework/Versions/3.13/lib/python3.13/site-packages/telegram/ext/_updater.py", line 743, in _network_loop_retry
    if not await do_action():
           ^^^^^^^^^^^^^^^^^
  File "/Library/Frameworks/Python.framework/Versions/3.13/lib/python3.13/site-packages/telegram/ext/_updater.py", line 737, in do_action
    return action_cb_task.result()
           ~~~~~~~~~~~~~~~~~~~~~^^
  File "/Library/Frameworks/Python.framework/Versions/3.13/lib/python3.13/site-packages/telegram/ext/_updater.py", line 367, in polling_action_cb
    updates = await self.bot.get_updates(
              ^^^^^^^^^^^^^^^^^^^^^^^^^^^
    ...<7 lines>...
    )
    ^
  File "/Library/Frameworks/Python.framework/Versions/3.13/lib/python3.13/site-packages/telegram/ext/_extbot.py", line 647, in get_updates
    updates = await super().get_updates(
              ^^^^^^^^^^^^^^^^^^^^^^^^^^
    ...<9 lines>...
    )
    ^
  File "/Library/Frameworks/Python.framework/Versions/3.13/lib/python3.13/site-packages/telegram/_bot.py", line 4421, in get_updates
    await self._post(
    ^^^^^^^^^^^^^^^^^
    ...<7 lines>...
    ),
    ^
  File "/Library/Frameworks/Python.framework/Versions/3.13/lib/python3.13/site-packages/telegram/_bot.py", line 617, in _post
    return await self._do_post(
           ^^^^^^^^^^^^^^^^^^^^
    ...<6 lines>...
    )
    ^
  File "/Library/Frameworks/Python.framework/Versions/3.13/lib/python3.13/site-packages/telegram/ext/_extbot.py", line 351, in _do_post
    return await super()._do_post(
           ^^^^^^^^^^^^^^^^^^^^^^^
    ...<6 lines>...
    )
    ^
  File "/Library/Frameworks/Python.framework/Versions/3.13/lib/python3.13/site-packages/telegram/_bot.py", line 646, in _do_post
    result = await request.post(
             ^^^^^^^^^^^^^^^^^^^
    ...<6 lines>...
    )
    ^
  File "/Library/Frameworks/Python.framework/Versions/3.13/lib/python3.13/site-packages/telegram/request/_baserequest.py", line 202, in post
    result = await self._request_wrapper(
             ^^^^^^^^^^^^^^^^^^^^^^^^^^^^
    ...<7 lines>...
    )
    ^
  File "/Library/Frameworks/Python.framework/Versions/3.13/lib/python3.13/site-packages/telegram/request/_baserequest.py", line 385, in _request_wrapper
    raise Conflict(message)
telegram.error.Conflict: Conflict: terminated by other getUpdates request; make sure that only one bot instance is running
2025-10-15 20:30:21,344 - httpx - INFO - HTTP Request: POST https://api.telegram.org/bot8242076298:AAGnHplpi7Ad4hOo9z4zTugjqcCEXLJt9to/getUpdates "HTTP/1.1 200 OK"
2025-10-15 20:30:31,481 - httpx - INFO - HTTP Request: POST https://api.telegram.org/bot8242076298:AAGnHplpi7Ad4hOo9z4zTugjqcCEXLJt9to/getUpdates "HTTP/1.1 200 OK"
2025-10-15 20:30:40,170 - httpx - INFO - HTTP Request: POST https://api.telegram.org/bot8242076298:AAGnHplpi7Ad4hOo9z4zTugjqcCEXLJt9to/getUpdates "HTTP/1.1 409 Conflict"
2025-10-15 20:30:40,171 - telegram.ext.Application - ERROR - No error handlers are registered, logging exception.
Traceback (most recent call last):
  File "/Library/Frameworks/Python.framework/Versions/3.13/lib/python3.13/site-packages/telegram/ext/_updater.py", line 743, in _network_loop_retry
    if not await do_action():
           ^^^^^^^^^^^^^^^^^
  File "/Library/Frameworks/Python.framework/Versions/3.13/lib/python3.13/site-packages/telegram/ext/_updater.py", line 737, in do_action
    return action_cb_task.result()
           ~~~~~~~~~~~~~~~~~~~~~^^
  File "/Library/Frameworks/Python.framework/Versions/3.13/lib/python3.13/site-packages/telegram/ext/_updater.py", line 367, in polling_action_cb
    updates = await self.bot.get_updates(
              ^^^^^^^^^^^^^^^^^^^^^^^^^^^
    ...<7 lines>...
    )
    ^
  File "/Library/Frameworks/Python.framework/Versions/3.13/lib/python3.13/site-packages/telegram/ext/_extbot.py", line 647, in get_updates
    updates = await super().get_updates(
              ^^^^^^^^^^^^^^^^^^^^^^^^^^
    ...<9 lines>...
    )
    ^
  File "/Library/Frameworks/Python.framework/Versions/3.13/lib/python3.13/site-packages/telegram/_bot.py", line 4421, in get_updates
    await self._post(
    ^^^^^^^^^^^^^^^^^
    ...<7 lines>...
    ),
    ^
  File "/Library/Frameworks/Python.framework/Versions/3.13/lib/python3.13/site-packages/telegram/_bot.py", line 617, in _post
    return await self._do_post(
           ^^^^^^^^^^^^^^^^^^^^
    ...<6 lines>...
    )
    ^
  File "/Library/Frameworks/Python.framework/Versions/3.13/lib/python3.13/site-packages/telegram/ext/_extbot.py", line 351, in _do_post
    return await super()._do_post(
           ^^^^^^^^^^^^^^^^^^^^^^^
    ...<6 lines>...
    )
    ^
  File "/Library/Frameworks/Python.framework/Versions/3.13/lib/python3.13/site-packages/telegram/_bot.py", line 646, in _do_post
    result = await request.post(
             ^^^^^^^^^^^^^^^^^^^
    ...<6 lines>...
    )
    ^
  File "/Library/Frameworks/Python.framework/Versions/3.13/lib/python3.13/site-packages/telegram/request/_baserequest.py", line 202, in post
    result = await self._request_wrapper(
             ^^^^^^^^^^^^^^^^^^^^^^^^^^^^
    ...<7 lines>...
    )
    ^
  File "/Library/Frameworks/Python.framework/Versions/3.13/lib/python3.13/site-packages/telegram/request/_baserequest.py", line 385, in _request_wrapper
    raise Conflict(message)
telegram.error.Conflict: Conflict: terminated by other getUpdates request; make sure that only one bot instance is running
