ü§ñ –ó–∞–ø—É—Å–∫ –±–æ—Ç–∞ DUNGEON Hookah...
üìÅ –î–∏—Ä–µ–∫—Ç–æ—Ä–∏—è: /Users/nikolajmisin/Documents/WebApp/next-app
üìù –õ–æ–≥ —Ñ–∞–π–ª: /Users/nikolajmisin/Documents/WebApp/next-app/bot.log

‚ñ∂Ô∏è  –ó–∞–ø—É—Å–∫ –±–æ—Ç–∞ –≤ 2025-10-15 20:28:44
2025-10-15 20:28:44,552 - __main__ - INFO - üöÄ Starting bot in polling mode...
2025-10-15 20:28:44,808 - httpx - INFO - HTTP Request: POST https://api.telegram.org/bot8242076298:AAGnHplpi7Ad4hOo9z4zTugjqcCEXLJt9to/getMe "HTTP/1.1 200 OK"
2025-10-15 20:28:44,874 - httpx - INFO - HTTP Request: POST https://api.telegram.org/bot8242076298:AAGnHplpi7Ad4hOo9z4zTugjqcCEXLJt9to/deleteWebhook "HTTP/1.1 200 OK"
2025-10-15 20:28:44,876 - telegram.ext.Application - INFO - Application started
2025-10-15 20:28:49,330 - httpx - INFO - HTTP Request: POST https://api.telegram.org/bot8242076298:AAGnHplpi7Ad4hOo9z4zTugjqcCEXLJt9to/getUpdates "HTTP/1.1 409 Conflict"
2025-10-15 20:28:49,332 - telegram.ext.Application - ERROR - No error handlers are registered, logging exception.
Traceback (most recent call last):
  File "/Library/Frameworks/Python.framework/Versions/3.13/lib/python3.13/site-packages/telegram/ext/_updater.py", line 743, in _network_loop_retry
    if not await do_action():
           ^^^^^^^^^^^^^^^^^
  File "/Library/Frameworks/Python.framework/Versions/3.13/lib/python3.13/site-packages/telegram/ext/_updater.py", line 737, in do_action
    return action_cb_task.result()
           ~~~~~~~~~~~~~~~~~~~~~^^
  File "/Library/Frameworks/Python.framework/Versions/3.13/lib/python3.13/site-packages/telegram/ext/_updater.py", line 367, in polling_action_cb
    updates = await self.bot.get_updates(
              ^^^^^^^^^^^^^^^^^^^^^^^^^^^
    ...<7 lines>...
    )
    ^
  File "/Library/Frameworks/Python.framework/Versions/3.13/lib/python3.13/site-packages/telegram/ext/_extbot.py", line 647, in get_updates
    updates = await super().get_updates(
              ^^^^^^^^^^^^^^^^^^^^^^^^^^
    ...<9 lines>...
    )
    ^
  File "/Library/Frameworks/Python.framework/Versions/3.13/lib/python3.13/site-packages/telegram/_bot.py", line 4421, in get_updates
    await self._post(
    ^^^^^^^^^^^^^^^^^
    ...<7 lines>...
    ),
    ^
  File "/Library/Frameworks/Python.framework/Versions/3.13/lib/python3.13/site-packages/telegram/_bot.py", line 617, in _post
    return await self._do_post(
           ^^^^^^^^^^^^^^^^^^^^
    ...<6 lines>...
    )
    ^
  File "/Library/Frameworks/Python.framework/Versions/3.13/lib/python3.13/site-packages/telegram/ext/_extbot.py", line 351, in _do_post
    return await super()._do_post(
           ^^^^^^^^^^^^^^^^^^^^^^^
    ...<6 lines>...
    )
    ^
  File "/Library/Frameworks/Python.framework/Versions/3.13/lib/python3.13/site-packages/telegram/_bot.py", line 646, in _do_post
    result = await request.post(
             ^^^^^^^^^^^^^^^^^^^
    ...<6 lines>...
    )
    ^
  File "/Library/Frameworks/Python.framework/Versions/3.13/lib/python3.13/site-packages/telegram/request/_baserequest.py", line 202, in post
    result = await self._request_wrapper(
             ^^^^^^^^^^^^^^^^^^^^^^^^^^^^
    ...<7 lines>...
    )
    ^
  File "/Library/Frameworks/Python.framework/Versions/3.13/lib/python3.13/site-packages/telegram/request/_baserequest.py", line 385, in _request_wrapper
    raise Conflict(message)
telegram.error.Conflict: Conflict: terminated by other getUpdates request; make sure that only one bot instance is running
2025-10-15 20:28:54,967 - httpx - INFO - HTTP Request: POST https://api.telegram.org/bot8242076298:AAGnHplpi7Ad4hOo9z4zTugjqcCEXLJt9to/getUpdates "HTTP/1.1 409 Conflict"
2025-10-15 20:28:54,969 - telegram.ext.Application - ERROR - No error handlers are registered, logging exception.
Traceback (most recent call last):
  File "/Library/Frameworks/Python.framework/Versions/3.13/lib/python3.13/site-packages/telegram/ext/_updater.py", line 743, in _network_loop_retry
    if not await do_action():
           ^^^^^^^^^^^^^^^^^
  File "/Library/Frameworks/Python.framework/Versions/3.13/lib/python3.13/site-packages/telegram/ext/_updater.py", line 737, in do_action
    return action_cb_task.result()
           ~~~~~~~~~~~~~~~~~~~~~^^
  File "/Library/Frameworks/Python.framework/Versions/3.13/lib/python3.13/site-packages/telegram/ext/_updater.py", line 367, in polling_action_cb
    updates = await self.bot.get_updates(
              ^^^^^^^^^^^^^^^^^^^^^^^^^^^
    ...<7 lines>...
    )
    ^
  File "/Library/Frameworks/Python.framework/Versions/3.13/lib/python3.13/site-packages/telegram/ext/_extbot.py", line 647, in get_updates
    updates = await super().get_updates(
              ^^^^^^^^^^^^^^^^^^^^^^^^^^
    ...<9 lines>...
    )
    ^
  File "/Library/Frameworks/Python.framework/Versions/3.13/lib/python3.13/site-packages/telegram/_bot.py", line 4421, in get_updates
    await self._post(
    ^^^^^^^^^^^^^^^^^
    ...<7 lines>...
    ),
    ^
  File "/Library/Frameworks/Python.framework/Versions/3.13/lib/python3.13/site-packages/telegram/_bot.py", line 617, in _post
    return await self._do_post(
           ^^^^^^^^^^^^^^^^^^^^
    ...<6 lines>...
    )
    ^
  File "/Library/Frameworks/Python.framework/Versions/3.13/lib/python3.13/site-packages/telegram/ext/_extbot.py", line 351, in _do_post
    return await super()._do_post(
           ^^^^^^^^^^^^^^^^^^^^^^^
    ...<6 lines>...
    )
    ^
  File "/Library/Frameworks/Python.framework/Versions/3.13/lib/python3.13/site-packages/telegram/_bot.py", line 646, in _do_post
    result = await request.post(
             ^^^^^^^^^^^^^^^^^^^
    ...<6 lines>...
    )
    ^
  File "/Library/Frameworks/Python.framework/Versions/3.13/lib/python3.13/site-packages/telegram/request/_baserequest.py", line 202, in post
    result = await self._request_wrapper(
             ^^^^^^^^^^^^^^^^^^^^^^^^^^^^
    ...<7 lines>...
    )
    ^
  File "/Library/Frameworks/Python.framework/Versions/3.13/lib/python3.13/site-packages/telegram/request/_baserequest.py", line 385, in _request_wrapper
    raise Conflict(message)
telegram.error.Conflict: Conflict: terminated by other getUpdates request; make sure that only one bot instance is running
2025-10-15 20:29:01,941 - httpx - INFO - HTTP Request: POST https://api.telegram.org/bot8242076298:AAGnHplpi7Ad4hOo9z4zTugjqcCEXLJt9to/getUpdates "HTTP/1.1 409 Conflict"
2025-10-15 20:29:01,942 - telegram.ext.Application - ERROR - No error handlers are registered, logging exception.
Traceback (most recent call last):
  File "/Library/Frameworks/Python.framework/Versions/3.13/lib/python3.13/site-packages/telegram/ext/_updater.py", line 743, in _network_loop_retry
    if not await do_action():
           ^^^^^^^^^^^^^^^^^
  File "/Library/Frameworks/Python.framework/Versions/3.13/lib/python3.13/site-packages/telegram/ext/_updater.py", line 737, in do_action
    return action_cb_task.result()
           ~~~~~~~~~~~~~~~~~~~~~^^
  File "/Library/Frameworks/Python.framework/Versions/3.13/lib/python3.13/site-packages/telegram/ext/_updater.py", line 367, in polling_action_cb
    updates = await self.bot.get_updates(
              ^^^^^^^^^^^^^^^^^^^^^^^^^^^
    ...<7 lines>...
    )
    ^
  File "/Library/Frameworks/Python.framework/Versions/3.13/lib/python3.13/site-packages/telegram/ext/_extbot.py", line 647, in get_updates
    updates = await super().get_updates(
              ^^^^^^^^^^^^^^^^^^^^^^^^^^
    ...<9 lines>...
    )
    ^
  File "/Library/Frameworks/Python.framework/Versions/3.13/lib/python3.13/site-packages/telegram/_bot.py", line 4421, in get_updates
    await self._post(
    ^^^^^^^^^^^^^^^^^
    ...<7 lines>...
    ),
    ^
  File "/Library/Frameworks/Python.framework/Versions/3.13/lib/python3.13/site-packages/telegram/_bot.py", line 617, in _post
    return await self._do_post(
           ^^^^^^^^^^^^^^^^^^^^
    ...<6 lines>...
    )
    ^
  File "/Library/Frameworks/Python.framework/Versions/3.13/lib/python3.13/site-packages/telegram/ext/_extbot.py", line 351, in _do_post
    return await super()._do_post(
           ^^^^^^^^^^^^^^^^^^^^^^^
    ...<6 lines>...
    )
    ^
  File "/Library/Frameworks/Python.framework/Versions/3.13/lib/python3.13/site-packages/telegram/_bot.py", line 646, in _do_post
    result = await request.post(
             ^^^^^^^^^^^^^^^^^^^
    ...<6 lines>...
    )
    ^
  File "/Library/Frameworks/Python.framework/Versions/3.13/lib/python3.13/site-packages/telegram/request/_baserequest.py", line 202, in post
    result = await self._request_wrapper(
             ^^^^^^^^^^^^^^^^^^^^^^^^^^^^
    ...<7 lines>...
    )
    ^
  File "/Library/Frameworks/Python.framework/Versions/3.13/lib/python3.13/site-packages/telegram/request/_baserequest.py", line 385, in _request_wrapper
    raise Conflict(message)
telegram.error.Conflict: Conflict: terminated by other getUpdates request; make sure that only one bot instance is running
2025-10-15 20:29:07,707 - httpx - INFO - HTTP Request: POST https://api.telegram.org/bot8242076298:AAGnHplpi7Ad4hOo9z4zTugjqcCEXLJt9to/getUpdates "HTTP/1.1 409 Conflict"
2025-10-15 20:29:07,709 - telegram.ext.Application - ERROR - No error handlers are registered, logging exception.
Traceback (most recent call last):
  File "/Library/Frameworks/Python.framework/Versions/3.13/lib/python3.13/site-packages/telegram/ext/_updater.py", line 743, in _network_loop_retry
    if not await do_action():
           ^^^^^^^^^^^^^^^^^
  File "/Library/Frameworks/Python.framework/Versions/3.13/lib/python3.13/site-packages/telegram/ext/_updater.py", line 737, in do_action
    return action_cb_task.result()
           ~~~~~~~~~~~~~~~~~~~~~^^
  File "/Library/Frameworks/Python.framework/Versions/3.13/lib/python3.13/site-packages/telegram/ext/_updater.py", line 367, in polling_action_cb
    updates = await self.bot.get_updates(
              ^^^^^^^^^^^^^^^^^^^^^^^^^^^
    ...<7 lines>...
    )
    ^
  File "/Library/Frameworks/Python.framework/Versions/3.13/lib/python3.13/site-packages/telegram/ext/_extbot.py", line 647, in get_updates
    updates = await super().get_updates(
              ^^^^^^^^^^^^^^^^^^^^^^^^^^
    ...<9 lines>...
    )
    ^
  File "/Library/Frameworks/Python.framework/Versions/3.13/lib/python3.13/site-packages/telegram/_bot.py", line 4421, in get_updates
    await self._post(
    ^^^^^^^^^^^^^^^^^
    ...<7 lines>...
    ),
    ^
  File "/Library/Frameworks/Python.framework/Versions/3.13/lib/python3.13/site-packages/telegram/_bot.py", line 617, in _post
    return await self._do_post(
           ^^^^^^^^^^^^^^^^^^^^
    ...<6 lines>...
    )
    ^
  File "/Library/Frameworks/Python.framework/Versions/3.13/lib/python3.13/site-packages/telegram/ext/_extbot.py", line 351, in _do_post
    return await super()._do_post(
           ^^^^^^^^^^^^^^^^^^^^^^^
    ...<6 lines>...
    )
    ^
  File "/Library/Frameworks/Python.framework/Versions/3.13/lib/python3.13/site-packages/telegram/_bot.py", line 646, in _do_post
    result = await request.post(
             ^^^^^^^^^^^^^^^^^^^
    ...<6 lines>...
    )
    ^
  File "/Library/Frameworks/Python.framework/Versions/3.13/lib/python3.13/site-packages/telegram/request/_baserequest.py", line 202, in post
    result = await self._request_wrapper(
             ^^^^^^^^^^^^^^^^^^^^^^^^^^^^
    ...<7 lines>...
    )
    ^
  File "/Library/Frameworks/Python.framework/Versions/3.13/lib/python3.13/site-packages/telegram/request/_baserequest.py", line 385, in _request_wrapper
    raise Conflict(message)
telegram.error.Conflict: Conflict: terminated by other getUpdates request; make sure that only one bot instance is running
2025-10-15 20:29:16,420 - httpx - INFO - HTTP Request: POST https://api.telegram.org/bot8242076298:AAGnHplpi7Ad4hOo9z4zTugjqcCEXLJt9to/getUpdates "HTTP/1.1 409 Conflict"
2025-10-15 20:29:16,422 - telegram.ext.Application - ERROR - No error handlers are registered, logging exception.
Traceback (most recent call last):
  File "/Library/Frameworks/Python.framework/Versions/3.13/lib/python3.13/site-packages/telegram/ext/_updater.py", line 743, in _network_loop_retry
    if not await do_action():
           ^^^^^^^^^^^^^^^^^
  File "/Library/Frameworks/Python.framework/Versions/3.13/lib/python3.13/site-packages/telegram/ext/_updater.py", line 737, in do_action
    return action_cb_task.result()
           ~~~~~~~~~~~~~~~~~~~~~^^
  File "/Library/Frameworks/Python.framework/Versions/3.13/lib/python3.13/site-packages/telegram/ext/_updater.py", line 367, in polling_action_cb
    updates = await self.bot.get_updates(
              ^^^^^^^^^^^^^^^^^^^^^^^^^^^
    ...<7 lines>...
    )
    ^
  File "/Library/Frameworks/Python.framework/Versions/3.13/lib/python3.13/site-packages/telegram/ext/_extbot.py", line 647, in get_updates
    updates = await super().get_updates(
              ^^^^^^^^^^^^^^^^^^^^^^^^^^
    ...<9 lines>...
    )
    ^
  File "/Library/Frameworks/Python.framework/Versions/3.13/lib/python3.13/site-packages/telegram/_bot.py", line 4421, in get_updates
    await self._post(
    ^^^^^^^^^^^^^^^^^
    ...<7 lines>...
    ),
    ^
  File "/Library/Frameworks/Python.framework/Versions/3.13/lib/python3.13/site-packages/telegram/_bot.py", line 617, in _post
    return await self._do_post(
           ^^^^^^^^^^^^^^^^^^^^
    ...<6 lines>...
    )
    ^
  File "/Library/Frameworks/Python.framework/Versions/3.13/lib/python3.13/site-packages/telegram/ext/_extbot.py", line 351, in _do_post
    return await super()._do_post(
           ^^^^^^^^^^^^^^^^^^^^^^^
    ...<6 lines>...
    )
    ^
  File "/Library/Frameworks/Python.framework/Versions/3.13/lib/python3.13/site-packages/telegram/_bot.py", line 646, in _do_post
    result = await request.post(
             ^^^^^^^^^^^^^^^^^^^
    ...<6 lines>...
    )
    ^
  File "/Library/Frameworks/Python.framework/Versions/3.13/lib/python3.13/site-packages/telegram/request/_baserequest.py", line 202, in post
    result = await self._request_wrapper(
             ^^^^^^^^^^^^^^^^^^^^^^^^^^^^
    ...<7 lines>...
    )
    ^
  File "/Library/Frameworks/Python.framework/Versions/3.13/lib/python3.13/site-packages/telegram/request/_baserequest.py", line 385, in _request_wrapper
    raise Conflict(message)
telegram.error.Conflict: Conflict: terminated by other getUpdates request; make sure that only one bot instance is running
2025-10-15 20:29:29,497 - httpx - INFO - HTTP Request: POST https://api.telegram.org/bot8242076298:AAGnHplpi7Ad4hOo9z4zTugjqcCEXLJt9to/getUpdates "HTTP/1.1 409 Conflict"
2025-10-15 20:29:29,498 - telegram.ext.Application - ERROR - No error handlers are registered, logging exception.
Traceback (most recent call last):
  File "/Library/Frameworks/Python.framework/Versions/3.13/lib/python3.13/site-packages/telegram/ext/_updater.py", line 743, in _network_loop_retry
    if not await do_action():
           ^^^^^^^^^^^^^^^^^
  File "/Library/Frameworks/Python.framework/Versions/3.13/lib/python3.13/site-packages/telegram/ext/_updater.py", line 737, in do_action
    return action_cb_task.result()
           ~~~~~~~~~~~~~~~~~~~~~^^
  File "/Library/Frameworks/Python.framework/Versions/3.13/lib/python3.13/site-packages/telegram/ext/_updater.py", line 367, in polling_action_cb
    updates = await self.bot.get_updates(
              ^^^^^^^^^^^^^^^^^^^^^^^^^^^
    ...<7 lines>...
    )
    ^
  File "/Library/Frameworks/Python.framework/Versions/3.13/lib/python3.13/site-packages/telegram/ext/_extbot.py", line 647, in get_updates
    updates = await super().get_updates(
              ^^^^^^^^^^^^^^^^^^^^^^^^^^
    ...<9 lines>...
    )
    ^
  File "/Library/Frameworks/Python.framework/Versions/3.13/lib/python3.13/site-packages/telegram/_bot.py", line 4421, in get_updates
    await self._post(
    ^^^^^^^^^^^^^^^^^
    ...<7 lines>...
    ),
    ^
  File "/Library/Frameworks/Python.framework/Versions/3.13/lib/python3.13/site-packages/telegram/_bot.py", line 617, in _post
    return await self._do_post(
           ^^^^^^^^^^^^^^^^^^^^
    ...<6 lines>...
    )
    ^
  File "/Library/Frameworks/Python.framework/Versions/3.13/lib/python3.13/site-packages/telegram/ext/_extbot.py", line 351, in _do_post
    return await super()._do_post(
           ^^^^^^^^^^^^^^^^^^^^^^^
    ...<6 lines>...
    )
    ^
  File "/Library/Frameworks/Python.framework/Versions/3.13/lib/python3.13/site-packages/telegram/_bot.py", line 646, in _do_post
    result = await request.post(
             ^^^^^^^^^^^^^^^^^^^
    ...<6 lines>...
    )
    ^
  File "/Library/Frameworks/Python.framework/Versions/3.13/lib/python3.13/site-packages/telegram/request/_baserequest.py", line 202, in post
    result = await self._request_wrapper(
             ^^^^^^^^^^^^^^^^^^^^^^^^^^^^
    ...<7 lines>...
    )
    ^
  File "/Library/Frameworks/Python.framework/Versions/3.13/lib/python3.13/site-packages/telegram/request/_baserequest.py", line 385, in _request_wrapper
    raise Conflict(message)
telegram.error.Conflict: Conflict: terminated by other getUpdates request; make sure that only one bot instance is running
2025-10-15 20:29:47,302 - httpx - INFO - HTTP Request: POST https://api.telegram.org/bot8242076298:AAGnHplpi7Ad4hOo9z4zTugjqcCEXLJt9to/getUpdates "HTTP/1.1 200 OK"
2025-10-15 20:29:48,898 - httpx - INFO - HTTP Request: POST https://api.telegram.org/bot8242076298:AAGnHplpi7Ad4hOo9z4zTugjqcCEXLJt9to/getUpdates "HTTP/1.1 409 Conflict"
2025-10-15 20:29:48,899 - telegram.ext.Application - ERROR - No error handlers are registered, logging exception.
Traceback (most recent call last):
  File "/Library/Frameworks/Python.framework/Versions/3.13/lib/python3.13/site-packages/telegram/ext/_updater.py", line 743, in _network_loop_retry
    if not await do_action():
           ^^^^^^^^^^^^^^^^^
  File "/Library/Frameworks/Python.framework/Versions/3.13/lib/python3.13/site-packages/telegram/ext/_updater.py", line 737, in do_action
    return action_cb_task.result()
           ~~~~~~~~~~~~~~~~~~~~~^^
  File "/Library/Frameworks/Python.framework/Versions/3.13/lib/python3.13/site-packages/telegram/ext/_updater.py", line 367, in polling_action_cb
    updates = await self.bot.get_updates(
              ^^^^^^^^^^^^^^^^^^^^^^^^^^^
    ...<7 lines>...
    )
    ^
  File "/Library/Frameworks/Python.framework/Versions/3.13/lib/python3.13/site-packages/telegram/ext/_extbot.py", line 647, in get_updates
    updates = await super().get_updates(
              ^^^^^^^^^^^^^^^^^^^^^^^^^^
    ...<9 lines>...
    )
    ^
  File "/Library/Frameworks/Python.framework/Versions/3.13/lib/python3.13/site-packages/telegram/_bot.py", line 4421, in get_updates
    await self._post(
    ^^^^^^^^^^^^^^^^^
    ...<7 lines>...
    ),
    ^
  File "/Library/Frameworks/Python.framework/Versions/3.13/lib/python3.13/site-packages/telegram/_bot.py", line 617, in _post
    return await self._do_post(
           ^^^^^^^^^^^^^^^^^^^^
    ...<6 lines>...
    )
    ^
  File "/Library/Frameworks/Python.framework/Versions/3.13/lib/python3.13/site-packages/telegram/ext/_extbot.py", line 351, in _do_post
    return await super()._do_post(
           ^^^^^^^^^^^^^^^^^^^^^^^
    ...<6 lines>...
    )
    ^
  File "/Library/Frameworks/Python.framework/Versions/3.13/lib/python3.13/site-packages/telegram/_bot.py", line 646, in _do_post
    result = await request.post(
             ^^^^^^^^^^^^^^^^^^^
    ...<6 lines>...
    )
    ^
  File "/Library/Frameworks/Python.framework/Versions/3.13/lib/python3.13/site-packages/telegram/request/_baserequest.py", line 202, in post
    result = await self._request_wrapper(
             ^^^^^^^^^^^^^^^^^^^^^^^^^^^^
    ...<7 lines>...
    )
    ^
  File "/Library/Frameworks/Python.framework/Versions/3.13/lib/python3.13/site-packages/telegram/request/_baserequest.py", line 385, in _request_wrapper
    raise Conflict(message)
telegram.error.Conflict: Conflict: terminated by other getUpdates request; make sure that only one bot instance is running
2025-10-15 20:29:52,577 - httpx - INFO - HTTP Request: POST https://api.telegram.org/bot8242076298:AAGnHplpi7Ad4hOo9z4zTugjqcCEXLJt9to/getUpdates "HTTP/1.1 200 OK"
2025-10-15 20:29:52,579 - __main__ - INFO - üöÄ START COMMAND CALLED!
2025-10-15 20:29:52,579 - __main__ - INFO - User 937011437 (shadowskydie) started the bot
2025-10-15 20:29:52,846 - httpx - INFO - HTTP Request: POST https://api.telegram.org/bot8242076298:AAGnHplpi7Ad4hOo9z4zTugjqcCEXLJt9to/sendMessage "HTTP/1.1 200 OK"
2025-10-15 20:29:53,821 - httpx - INFO - HTTP Request: POST https://api.telegram.org/bot8242076298:AAGnHplpi7Ad4hOo9z4zTugjqcCEXLJt9to/getUpdates "HTTP/1.1 200 OK"
2025-10-15 20:29:53,822 - __main__ - INFO - üöÄ START COMMAND CALLED!
2025-10-15 20:29:53,822 - __main__ - INFO - User 937011437 (shadowskydie) started the bot
2025-10-15 20:29:54,030 - httpx - INFO - HTTP Request: POST https://api.telegram.org/bot8242076298:AAGnHplpi7Ad4hOo9z4zTugjqcCEXLJt9to/sendMessage "HTTP/1.1 200 OK"
2025-10-15 20:29:54,785 - httpx - INFO - HTTP Request: POST https://api.telegram.org/bot8242076298:AAGnHplpi7Ad4hOo9z4zTugjqcCEXLJt9to/getUpdates "HTTP/1.1 200 OK"
2025-10-15 20:29:54,786 - __main__ - INFO - üöÄ START COMMAND CALLED!
2025-10-15 20:29:54,786 - __main__ - INFO - User 937011437 (shadowskydie) started the bot
2025-10-15 20:29:54,994 - httpx - INFO - HTTP Request: POST https://api.telegram.org/bot8242076298:AAGnHplpi7Ad4hOo9z4zTugjqcCEXLJt9to/sendMessage "HTTP/1.1 200 OK"
2025-10-15 20:30:04,851 - httpx - INFO - HTTP Request: POST https://api.telegram.org/bot8242076298:AAGnHplpi7Ad4hOo9z4zTugjqcCEXLJt9to/getUpdates "HTTP/1.1 200 OK"
2025-10-15 20:30:10,261 - httpx - INFO - HTTP Request: POST https://api.telegram.org/bot8242076298:AAGnHplpi7Ad4hOo9z4zTugjqcCEXLJt9to/getUpdates "HTTP/1.1 409 Conflict"
2025-10-15 20:30:10,262 - telegram.ext.Application - ERROR - No error handlers are registered, logging exception.
Traceback (most recent call last):
  File "/Library/Frameworks/Python.framework/Versions/3.13/lib/python3.13/site-packages/telegram/ext/_updater.py", line 743, in _network_loop_retry
    if not await do_action():
           ^^^^^^^^^^^^^^^^^
  File "/Library/Frameworks/Python.framework/Versions/3.13/lib/python3.13/site-packages/telegram/ext/_updater.py", line 737, in do_action
    return action_cb_task.result()
           ~~~~~~~~~~~~~~~~~~~~~^^
  File "/Library/Frameworks/Python.framework/Versions/3.13/lib/python3.13/site-packages/telegram/ext/_updater.py", line 367, in polling_action_cb
    updates = await self.bot.get_updates(
              ^^^^^^^^^^^^^^^^^^^^^^^^^^^
    ...<7 lines>...
    )
    ^
  File "/Library/Frameworks/Python.framework/Versions/3.13/lib/python3.13/site-packages/telegram/ext/_extbot.py", line 647, in get_updates
    updates = await super().get_updates(
              ^^^^^^^^^^^^^^^^^^^^^^^^^^
    ...<9 lines>...
    )
    ^
  File "/Library/Frameworks/Python.framework/Versions/3.13/lib/python3.13/site-packages/telegram/_bot.py", line 4421, in get_updates
    await self._post(
    ^^^^^^^^^^^^^^^^^
    ...<7 lines>...
    ),
    ^
  File "/Library/Frameworks/Python.framework/Versions/3.13/lib/python3.13/site-packages/telegram/_bot.py", line 617, in _post
    return await self._do_post(
           ^^^^^^^^^^^^^^^^^^^^
    ...<6 lines>...
    )
    ^
  File "/Library/Frameworks/Python.framework/Versions/3.13/lib/python3.13/site-packages/telegram/ext/_extbot.py", line 351, in _do_post
    return await super()._do_post(
           ^^^^^^^^^^^^^^^^^^^^^^^
    ...<6 lines>...
    )
    ^
  File "/Library/Frameworks/Python.framework/Versions/3.13/lib/python3.13/site-packages/telegram/_bot.py", line 646, in _do_post
    result = await request.post(
             ^^^^^^^^^^^^^^^^^^^
    ...<6 lines>...
    )
    ^
  File "/Library/Frameworks/Python.framework/Versions/3.13/lib/python3.13/site-packages/telegram/request/_baserequest.py", line 202, in post
    result = await self._request_wrapper(
             ^^^^^^^^^^^^^^^^^^^^^^^^^^^^
    ...<7 lines>...
    )
    ^
  File "/Library/Frameworks/Python.framework/Versions/3.13/lib/python3.13/site-packages/telegram/request/_baserequest.py", line 385, in _request_wrapper
    raise Conflict(message)
telegram.error.Conflict: Conflict: terminated by other getUpdates request; make sure that only one bot instance is running
2025-10-15 20:30:21,344 - httpx - INFO - HTTP Request: POST https://api.telegram.org/bot8242076298:AAGnHplpi7Ad4hOo9z4zTugjqcCEXLJt9to/getUpdates "HTTP/1.1 200 OK"
2025-10-15 20:30:31,481 - httpx - INFO - HTTP Request: POST https://api.telegram.org/bot8242076298:AAGnHplpi7Ad4hOo9z4zTugjqcCEXLJt9to/getUpdates "HTTP/1.1 200 OK"
2025-10-15 20:30:40,170 - httpx - INFO - HTTP Request: POST https://api.telegram.org/bot8242076298:AAGnHplpi7Ad4hOo9z4zTugjqcCEXLJt9to/getUpdates "HTTP/1.1 409 Conflict"
2025-10-15 20:30:40,171 - telegram.ext.Application - ERROR - No error handlers are registered, logging exception.
Traceback (most recent call last):
  File "/Library/Frameworks/Python.framework/Versions/3.13/lib/python3.13/site-packages/telegram/ext/_updater.py", line 743, in _network_loop_retry
    if not await do_action():
           ^^^^^^^^^^^^^^^^^
  File "/Library/Frameworks/Python.framework/Versions/3.13/lib/python3.13/site-packages/telegram/ext/_updater.py", line 737, in do_action
    return action_cb_task.result()
           ~~~~~~~~~~~~~~~~~~~~~^^
  File "/Library/Frameworks/Python.framework/Versions/3.13/lib/python3.13/site-packages/telegram/ext/_updater.py", line 367, in polling_action_cb
    updates = await self.bot.get_updates(
              ^^^^^^^^^^^^^^^^^^^^^^^^^^^
    ...<7 lines>...
    )
    ^
  File "/Library/Frameworks/Python.framework/Versions/3.13/lib/python3.13/site-packages/telegram/ext/_extbot.py", line 647, in get_updates
    updates = await super().get_updates(
              ^^^^^^^^^^^^^^^^^^^^^^^^^^
    ...<9 lines>...
    )
    ^
  File "/Library/Frameworks/Python.framework/Versions/3.13/lib/python3.13/site-packages/telegram/_bot.py", line 4421, in get_updates
    await self._post(
    ^^^^^^^^^^^^^^^^^
    ...<7 lines>...
    ),
    ^
  File "/Library/Frameworks/Python.framework/Versions/3.13/lib/python3.13/site-packages/telegram/_bot.py", line 617, in _post
    return await self._do_post(
           ^^^^^^^^^^^^^^^^^^^^
    ...<6 lines>...
    )
    ^
  File "/Library/Frameworks/Python.framework/Versions/3.13/lib/python3.13/site-packages/telegram/ext/_extbot.py", line 351, in _do_post
    return await super()._do_post(
           ^^^^^^^^^^^^^^^^^^^^^^^
    ...<6 lines>...
    )
    ^
  File "/Library/Frameworks/Python.framework/Versions/3.13/lib/python3.13/site-packages/telegram/_bot.py", line 646, in _do_post
    result = await request.post(
             ^^^^^^^^^^^^^^^^^^^
    ...<6 lines>...
    )
    ^
  File "/Library/Frameworks/Python.framework/Versions/3.13/lib/python3.13/site-packages/telegram/request/_baserequest.py", line 202, in post
    result = await self._request_wrapper(
             ^^^^^^^^^^^^^^^^^^^^^^^^^^^^
    ...<7 lines>...
    )
    ^
  File "/Library/Frameworks/Python.framework/Versions/3.13/lib/python3.13/site-packages/telegram/request/_baserequest.py", line 385, in _request_wrapper
    raise Conflict(message)
telegram.error.Conflict: Conflict: terminated by other getUpdates request; make sure that only one bot instance is running
2025-10-15 20:30:51,240 - httpx - INFO - HTTP Request: POST https://api.telegram.org/bot8242076298:AAGnHplpi7Ad4hOo9z4zTugjqcCEXLJt9to/getUpdates "HTTP/1.1 200 OK"
2025-10-15 20:31:01,384 - httpx - INFO - HTTP Request: POST https://api.telegram.org/bot8242076298:AAGnHplpi7Ad4hOo9z4zTugjqcCEXLJt9to/getUpdates "HTTP/1.1 200 OK"
2025-10-15 20:31:11,454 - httpx - INFO - HTTP Request: POST https://api.telegram.org/bot8242076298:AAGnHplpi7Ad4hOo9z4zTugjqcCEXLJt9to/getUpdates "HTTP/1.1 200 OK"
2025-10-15 20:31:14,451 - httpx - INFO - HTTP Request: POST https://api.telegram.org/bot8242076298:AAGnHplpi7Ad4hOo9z4zTugjqcCEXLJt9to/getUpdates "HTTP/1.1 409 Conflict"
2025-10-15 20:31:14,452 - telegram.ext.Application - ERROR - No error handlers are registered, logging exception.
Traceback (most recent call last):
  File "/Library/Frameworks/Python.framework/Versions/3.13/lib/python3.13/site-packages/telegram/ext/_updater.py", line 743, in _network_loop_retry
    if not await do_action():
           ^^^^^^^^^^^^^^^^^
  File "/Library/Frameworks/Python.framework/Versions/3.13/lib/python3.13/site-packages/telegram/ext/_updater.py", line 737, in do_action
    return action_cb_task.result()
           ~~~~~~~~~~~~~~~~~~~~~^^
  File "/Library/Frameworks/Python.framework/Versions/3.13/lib/python3.13/site-packages/telegram/ext/_updater.py", line 367, in polling_action_cb
    updates = await self.bot.get_updates(
              ^^^^^^^^^^^^^^^^^^^^^^^^^^^
    ...<7 lines>...
    )
    ^
  File "/Library/Frameworks/Python.framework/Versions/3.13/lib/python3.13/site-packages/telegram/ext/_extbot.py", line 647, in get_updates
    updates = await super().get_updates(
              ^^^^^^^^^^^^^^^^^^^^^^^^^^
    ...<9 lines>...
    )
    ^
  File "/Library/Frameworks/Python.framework/Versions/3.13/lib/python3.13/site-packages/telegram/_bot.py", line 4421, in get_updates
    await self._post(
    ^^^^^^^^^^^^^^^^^
    ...<7 lines>...
    ),
    ^
  File "/Library/Frameworks/Python.framework/Versions/3.13/lib/python3.13/site-packages/telegram/_bot.py", line 617, in _post
    return await self._do_post(
           ^^^^^^^^^^^^^^^^^^^^
    ...<6 lines>...
    )
    ^
  File "/Library/Frameworks/Python.framework/Versions/3.13/lib/python3.13/site-packages/telegram/ext/_extbot.py", line 351, in _do_post
    return await super()._do_post(
           ^^^^^^^^^^^^^^^^^^^^^^^
    ...<6 lines>...
    )
    ^
  File "/Library/Frameworks/Python.framework/Versions/3.13/lib/python3.13/site-packages/telegram/_bot.py", line 646, in _do_post
    result = await request.post(
             ^^^^^^^^^^^^^^^^^^^
    ...<6 lines>...
    )
    ^
  File "/Library/Frameworks/Python.framework/Versions/3.13/lib/python3.13/site-packages/telegram/request/_baserequest.py", line 202, in post
    result = await self._request_wrapper(
             ^^^^^^^^^^^^^^^^^^^^^^^^^^^^
    ...<7 lines>...
    )
    ^
  File "/Library/Frameworks/Python.framework/Versions/3.13/lib/python3.13/site-packages/telegram/request/_baserequest.py", line 385, in _request_wrapper
    raise Conflict(message)
telegram.error.Conflict: Conflict: terminated by other getUpdates request; make sure that only one bot instance is running
2025-10-15 20:31:25,526 - httpx - INFO - HTTP Request: POST https://api.telegram.org/bot8242076298:AAGnHplpi7Ad4hOo9z4zTugjqcCEXLJt9to/getUpdates "HTTP/1.1 200 OK"
2025-10-15 20:31:35,654 - httpx - INFO - HTTP Request: POST https://api.telegram.org/bot8242076298:AAGnHplpi7Ad4hOo9z4zTugjqcCEXLJt9to/getUpdates "HTTP/1.1 200 OK"
2025-10-15 20:31:45,826 - httpx - INFO - HTTP Request: POST https://api.telegram.org/bot8242076298:AAGnHplpi7Ad4hOo9z4zTugjqcCEXLJt9to/getUpdates "HTTP/1.1 200 OK"
2025-10-15 20:31:48,747 - httpx - INFO - HTTP Request: POST https://api.telegram.org/bot8242076298:AAGnHplpi7Ad4hOo9z4zTugjqcCEXLJt9to/getUpdates "HTTP/1.1 409 Conflict"
2025-10-15 20:31:48,748 - telegram.ext.Application - ERROR - No error handlers are registered, logging exception.
Traceback (most recent call last):
  File "/Library/Frameworks/Python.framework/Versions/3.13/lib/python3.13/site-packages/telegram/ext/_updater.py", line 743, in _network_loop_retry
    if not await do_action():
           ^^^^^^^^^^^^^^^^^
  File "/Library/Frameworks/Python.framework/Versions/3.13/lib/python3.13/site-packages/telegram/ext/_updater.py", line 737, in do_action
    return action_cb_task.result()
           ~~~~~~~~~~~~~~~~~~~~~^^
  File "/Library/Frameworks/Python.framework/Versions/3.13/lib/python3.13/site-packages/telegram/ext/_updater.py", line 367, in polling_action_cb
    updates = await self.bot.get_updates(
              ^^^^^^^^^^^^^^^^^^^^^^^^^^^
    ...<7 lines>...
    )
    ^
  File "/Library/Frameworks/Python.framework/Versions/3.13/lib/python3.13/site-packages/telegram/ext/_extbot.py", line 647, in get_updates
    updates = await super().get_updates(
              ^^^^^^^^^^^^^^^^^^^^^^^^^^
    ...<9 lines>...
    )
    ^
  File "/Library/Frameworks/Python.framework/Versions/3.13/lib/python3.13/site-packages/telegram/_bot.py", line 4421, in get_updates
    await self._post(
    ^^^^^^^^^^^^^^^^^
    ...<7 lines>...
    ),
    ^
  File "/Library/Frameworks/Python.framework/Versions/3.13/lib/python3.13/site-packages/telegram/_bot.py", line 617, in _post
    return await self._do_post(
           ^^^^^^^^^^^^^^^^^^^^
    ...<6 lines>...
    )
    ^
  File "/Library/Frameworks/Python.framework/Versions/3.13/lib/python3.13/site-packages/telegram/ext/_extbot.py", line 351, in _do_post
    return await super()._do_post(
           ^^^^^^^^^^^^^^^^^^^^^^^
    ...<6 lines>...
    )
    ^
  File "/Library/Frameworks/Python.framework/Versions/3.13/lib/python3.13/site-packages/telegram/_bot.py", line 646, in _do_post
    result = await request.post(
             ^^^^^^^^^^^^^^^^^^^
    ...<6 lines>...
    )
    ^
  File "/Library/Frameworks/Python.framework/Versions/3.13/lib/python3.13/site-packages/telegram/request/_baserequest.py", line 202, in post
    result = await self._request_wrapper(
             ^^^^^^^^^^^^^^^^^^^^^^^^^^^^
    ...<7 lines>...
    )
    ^
  File "/Library/Frameworks/Python.framework/Versions/3.13/lib/python3.13/site-packages/telegram/request/_baserequest.py", line 385, in _request_wrapper
    raise Conflict(message)
telegram.error.Conflict: Conflict: terminated by other getUpdates request; make sure that only one bot instance is running
2025-10-15 20:31:59,815 - httpx - INFO - HTTP Request: POST https://api.telegram.org/bot8242076298:AAGnHplpi7Ad4hOo9z4zTugjqcCEXLJt9to/getUpdates "HTTP/1.1 200 OK"
2025-10-15 20:32:09,890 - httpx - INFO - HTTP Request: POST https://api.telegram.org/bot8242076298:AAGnHplpi7Ad4hOo9z4zTugjqcCEXLJt9to/getUpdates "HTTP/1.1 200 OK"
2025-10-15 20:32:20,026 - httpx - INFO - HTTP Request: POST https://api.telegram.org/bot8242076298:AAGnHplpi7Ad4hOo9z4zTugjqcCEXLJt9to/getUpdates "HTTP/1.1 200 OK"
2025-10-15 20:32:23,032 - httpx - INFO - HTTP Request: POST https://api.telegram.org/bot8242076298:AAGnHplpi7Ad4hOo9z4zTugjqcCEXLJt9to/getUpdates "HTTP/1.1 409 Conflict"
2025-10-15 20:32:23,033 - telegram.ext.Application - ERROR - No error handlers are registered, logging exception.
Traceback (most recent call last):
  File "/Library/Frameworks/Python.framework/Versions/3.13/lib/python3.13/site-packages/telegram/ext/_updater.py", line 743, in _network_loop_retry
    if not await do_action():
           ^^^^^^^^^^^^^^^^^
  File "/Library/Frameworks/Python.framework/Versions/3.13/lib/python3.13/site-packages/telegram/ext/_updater.py", line 737, in do_action
    return action_cb_task.result()
           ~~~~~~~~~~~~~~~~~~~~~^^
  File "/Library/Frameworks/Python.framework/Versions/3.13/lib/python3.13/site-packages/telegram/ext/_updater.py", line 367, in polling_action_cb
    updates = await self.bot.get_updates(
              ^^^^^^^^^^^^^^^^^^^^^^^^^^^
    ...<7 lines>...
    )
    ^
  File "/Library/Frameworks/Python.framework/Versions/3.13/lib/python3.13/site-packages/telegram/ext/_extbot.py", line 647, in get_updates
    updates = await super().get_updates(
              ^^^^^^^^^^^^^^^^^^^^^^^^^^
    ...<9 lines>...
    )
    ^
  File "/Library/Frameworks/Python.framework/Versions/3.13/lib/python3.13/site-packages/telegram/_bot.py", line 4421, in get_updates
    await self._post(
    ^^^^^^^^^^^^^^^^^
    ...<7 lines>...
    ),
    ^
  File "/Library/Frameworks/Python.framework/Versions/3.13/lib/python3.13/site-packages/telegram/_bot.py", line 617, in _post
    return await self._do_post(
           ^^^^^^^^^^^^^^^^^^^^
    ...<6 lines>...
    )
    ^
  File "/Library/Frameworks/Python.framework/Versions/3.13/lib/python3.13/site-packages/telegram/ext/_extbot.py", line 351, in _do_post
    return await super()._do_post(
           ^^^^^^^^^^^^^^^^^^^^^^^
    ...<6 lines>...
    )
    ^
  File "/Library/Frameworks/Python.framework/Versions/3.13/lib/python3.13/site-packages/telegram/_bot.py", line 646, in _do_post
    result = await request.post(
             ^^^^^^^^^^^^^^^^^^^
    ...<6 lines>...
    )
    ^
  File "/Library/Frameworks/Python.framework/Versions/3.13/lib/python3.13/site-packages/telegram/request/_baserequest.py", line 202, in post
    result = await self._request_wrapper(
             ^^^^^^^^^^^^^^^^^^^^^^^^^^^^
    ...<7 lines>...
    )
    ^
  File "/Library/Frameworks/Python.framework/Versions/3.13/lib/python3.13/site-packages/telegram/request/_baserequest.py", line 385, in _request_wrapper
    raise Conflict(message)
telegram.error.Conflict: Conflict: terminated by other getUpdates request; make sure that only one bot instance is running
2025-10-15 20:32:33,054 - httpx - INFO - HTTP Request: POST https://api.telegram.org/bot8242076298:AAGnHplpi7Ad4hOo9z4zTugjqcCEXLJt9to/getUpdates "HTTP/1.1 200 OK"
2025-10-15 20:32:33,057 - __main__ - INFO - üöÄ START COMMAND CALLED!
2025-10-15 20:32:33,057 - __main__ - INFO - User 937011437 (shadowskydie) started the bot
2025-10-15 20:32:33,279 - httpx - INFO - HTTP Request: POST https://api.telegram.org/bot8242076298:AAGnHplpi7Ad4hOo9z4zTugjqcCEXLJt9to/sendMessage "HTTP/1.1 200 OK"
2025-10-15 20:32:43,170 - httpx - INFO - HTTP Request: POST https://api.telegram.org/bot8242076298:AAGnHplpi7Ad4hOo9z4zTugjqcCEXLJt9to/getUpdates "HTTP/1.1 200 OK"
2025-10-15 20:32:53,236 - httpx - INFO - HTTP Request: POST https://api.telegram.org/bot8242076298:AAGnHplpi7Ad4hOo9z4zTugjqcCEXLJt9to/getUpdates "HTTP/1.1 200 OK"
2025-10-15 20:32:57,422 - httpx - INFO - HTTP Request: POST https://api.telegram.org/bot8242076298:AAGnHplpi7Ad4hOo9z4zTugjqcCEXLJt9to/getUpdates "HTTP/1.1 409 Conflict"
2025-10-15 20:32:57,423 - telegram.ext.Application - ERROR - No error handlers are registered, logging exception.
Traceback (most recent call last):
  File "/Library/Frameworks/Python.framework/Versions/3.13/lib/python3.13/site-packages/telegram/ext/_updater.py", line 743, in _network_loop_retry
    if not await do_action():
           ^^^^^^^^^^^^^^^^^
  File "/Library/Frameworks/Python.framework/Versions/3.13/lib/python3.13/site-packages/telegram/ext/_updater.py", line 737, in do_action
    return action_cb_task.result()
           ~~~~~~~~~~~~~~~~~~~~~^^
  File "/Library/Frameworks/Python.framework/Versions/3.13/lib/python3.13/site-packages/telegram/ext/_updater.py", line 367, in polling_action_cb
    updates = await self.bot.get_updates(
              ^^^^^^^^^^^^^^^^^^^^^^^^^^^
    ...<7 lines>...
    )
    ^
  File "/Library/Frameworks/Python.framework/Versions/3.13/lib/python3.13/site-packages/telegram/ext/_extbot.py", line 647, in get_updates
    updates = await super().get_updates(
              ^^^^^^^^^^^^^^^^^^^^^^^^^^
    ...<9 lines>...
    )
    ^
  File "/Library/Frameworks/Python.framework/Versions/3.13/lib/python3.13/site-packages/telegram/_bot.py", line 4421, in get_updates
    await self._post(
    ^^^^^^^^^^^^^^^^^
    ...<7 lines>...
    ),
    ^
  File "/Library/Frameworks/Python.framework/Versions/3.13/lib/python3.13/site-packages/telegram/_bot.py", line 617, in _post
    return await self._do_post(
           ^^^^^^^^^^^^^^^^^^^^
    ...<6 lines>...
    )
    ^
  File "/Library/Frameworks/Python.framework/Versions/3.13/lib/python3.13/site-packages/telegram/ext/_extbot.py", line 351, in _do_post
    return await super()._do_post(
           ^^^^^^^^^^^^^^^^^^^^^^^
    ...<6 lines>...
    )
    ^
  File "/Library/Frameworks/Python.framework/Versions/3.13/lib/python3.13/site-packages/telegram/_bot.py", line 646, in _do_post
    result = await request.post(
             ^^^^^^^^^^^^^^^^^^^
    ...<6 lines>...
    )
    ^
  File "/Library/Frameworks/Python.framework/Versions/3.13/lib/python3.13/site-packages/telegram/request/_baserequest.py", line 202, in post
    result = await self._request_wrapper(
             ^^^^^^^^^^^^^^^^^^^^^^^^^^^^
    ...<7 lines>...
    )
    ^
  File "/Library/Frameworks/Python.framework/Versions/3.13/lib/python3.13/site-packages/telegram/request/_baserequest.py", line 385, in _request_wrapper
    raise Conflict(message)
telegram.error.Conflict: Conflict: terminated by other getUpdates request; make sure that only one bot instance is running
2025-10-15 20:33:08,564 - httpx - INFO - HTTP Request: POST https://api.telegram.org/bot8242076298:AAGnHplpi7Ad4hOo9z4zTugjqcCEXLJt9to/getUpdates "HTTP/1.1 200 OK"
2025-10-15 20:33:18,632 - httpx - INFO - HTTP Request: POST https://api.telegram.org/bot8242076298:AAGnHplpi7Ad4hOo9z4zTugjqcCEXLJt9to/getUpdates "HTTP/1.1 200 OK"
2025-10-15 20:33:28,712 - httpx - INFO - HTTP Request: POST https://api.telegram.org/bot8242076298:AAGnHplpi7Ad4hOo9z4zTugjqcCEXLJt9to/getUpdates "HTTP/1.1 200 OK"
2025-10-15 20:33:31,820 - httpx - INFO - HTTP Request: POST https://api.telegram.org/bot8242076298:AAGnHplpi7Ad4hOo9z4zTugjqcCEXLJt9to/getUpdates "HTTP/1.1 409 Conflict"
2025-10-15 20:33:31,821 - telegram.ext.Application - ERROR - No error handlers are registered, logging exception.
Traceback (most recent call last):
  File "/Library/Frameworks/Python.framework/Versions/3.13/lib/python3.13/site-packages/telegram/ext/_updater.py", line 743, in _network_loop_retry
    if not await do_action():
           ^^^^^^^^^^^^^^^^^
  File "/Library/Frameworks/Python.framework/Versions/3.13/lib/python3.13/site-packages/telegram/ext/_updater.py", line 737, in do_action
    return action_cb_task.result()
           ~~~~~~~~~~~~~~~~~~~~~^^
  File "/Library/Frameworks/Python.framework/Versions/3.13/lib/python3.13/site-packages/telegram/ext/_updater.py", line 367, in polling_action_cb
    updates = await self.bot.get_updates(
              ^^^^^^^^^^^^^^^^^^^^^^^^^^^
    ...<7 lines>...
    )
    ^
  File "/Library/Frameworks/Python.framework/Versions/3.13/lib/python3.13/site-packages/telegram/ext/_extbot.py", line 647, in get_updates
    updates = await super().get_updates(
              ^^^^^^^^^^^^^^^^^^^^^^^^^^
    ...<9 lines>...
    )
    ^
  File "/Library/Frameworks/Python.framework/Versions/3.13/lib/python3.13/site-packages/telegram/_bot.py", line 4421, in get_updates
    await self._post(
    ^^^^^^^^^^^^^^^^^
    ...<7 lines>...
    ),
    ^
  File "/Library/Frameworks/Python.framework/Versions/3.13/lib/python3.13/site-packages/telegram/_bot.py", line 617, in _post
    return await self._do_post(
           ^^^^^^^^^^^^^^^^^^^^
    ...<6 lines>...
    )
    ^
  File "/Library/Frameworks/Python.framework/Versions/3.13/lib/python3.13/site-packages/telegram/ext/_extbot.py", line 351, in _do_post
    return await super()._do_post(
           ^^^^^^^^^^^^^^^^^^^^^^^
    ...<6 lines>...
    )
    ^
  File "/Library/Frameworks/Python.framework/Versions/3.13/lib/python3.13/site-packages/telegram/_bot.py", line 646, in _do_post
    result = await request.post(
             ^^^^^^^^^^^^^^^^^^^
    ...<6 lines>...
    )
    ^
  File "/Library/Frameworks/Python.framework/Versions/3.13/lib/python3.13/site-packages/telegram/request/_baserequest.py", line 202, in post
    result = await self._request_wrapper(
             ^^^^^^^^^^^^^^^^^^^^^^^^^^^^
    ...<7 lines>...
    )
    ^
  File "/Library/Frameworks/Python.framework/Versions/3.13/lib/python3.13/site-packages/telegram/request/_baserequest.py", line 385, in _request_wrapper
    raise Conflict(message)
telegram.error.Conflict: Conflict: terminated by other getUpdates request; make sure that only one bot instance is running
2025-10-15 20:33:42,885 - httpx - INFO - HTTP Request: POST https://api.telegram.org/bot8242076298:AAGnHplpi7Ad4hOo9z4zTugjqcCEXLJt9to/getUpdates "HTTP/1.1 200 OK"
2025-10-15 20:33:53,006 - httpx - INFO - HTTP Request: POST https://api.telegram.org/bot8242076298:AAGnHplpi7Ad4hOo9z4zTugjqcCEXLJt9to/getUpdates "HTTP/1.1 200 OK"
2025-10-15 20:34:03,075 - httpx - INFO - HTTP Request: POST https://api.telegram.org/bot8242076298:AAGnHplpi7Ad4hOo9z4zTugjqcCEXLJt9to/getUpdates "HTTP/1.1 200 OK"
2025-10-15 20:34:06,102 - httpx - INFO - HTTP Request: POST https://api.telegram.org/bot8242076298:AAGnHplpi7Ad4hOo9z4zTugjqcCEXLJt9to/getUpdates "HTTP/1.1 409 Conflict"
2025-10-15 20:34:06,103 - telegram.ext.Application - ERROR - No error handlers are registered, logging exception.
Traceback (most recent call last):
  File "/Library/Frameworks/Python.framework/Versions/3.13/lib/python3.13/site-packages/telegram/ext/_updater.py", line 743, in _network_loop_retry
    if not await do_action():
           ^^^^^^^^^^^^^^^^^
  File "/Library/Frameworks/Python.framework/Versions/3.13/lib/python3.13/site-packages/telegram/ext/_updater.py", line 737, in do_action
    return action_cb_task.result()
           ~~~~~~~~~~~~~~~~~~~~~^^
  File "/Library/Frameworks/Python.framework/Versions/3.13/lib/python3.13/site-packages/telegram/ext/_updater.py", line 367, in polling_action_cb
    updates = await self.bot.get_updates(
              ^^^^^^^^^^^^^^^^^^^^^^^^^^^
    ...<7 lines>...
    )
    ^
  File "/Library/Frameworks/Python.framework/Versions/3.13/lib/python3.13/site-packages/telegram/ext/_extbot.py", line 647, in get_updates
    updates = await super().get_updates(
              ^^^^^^^^^^^^^^^^^^^^^^^^^^
    ...<9 lines>...
    )
    ^
  File "/Library/Frameworks/Python.framework/Versions/3.13/lib/python3.13/site-packages/telegram/_bot.py", line 4421, in get_updates
    await self._post(
    ^^^^^^^^^^^^^^^^^
    ...<7 lines>...
    ),
    ^
  File "/Library/Frameworks/Python.framework/Versions/3.13/lib/python3.13/site-packages/telegram/_bot.py", line 617, in _post
    return await self._do_post(
           ^^^^^^^^^^^^^^^^^^^^
    ...<6 lines>...
    )
    ^
  File "/Library/Frameworks/Python.framework/Versions/3.13/lib/python3.13/site-packages/telegram/ext/_extbot.py", line 351, in _do_post
    return await super()._do_post(
           ^^^^^^^^^^^^^^^^^^^^^^^
    ...<6 lines>...
    )
    ^
  File "/Library/Frameworks/Python.framework/Versions/3.13/lib/python3.13/site-packages/telegram/_bot.py", line 646, in _do_post
    result = await request.post(
             ^^^^^^^^^^^^^^^^^^^
    ...<6 lines>...
    )
    ^
  File "/Library/Frameworks/Python.framework/Versions/3.13/lib/python3.13/site-packages/telegram/request/_baserequest.py", line 202, in post
    result = await self._request_wrapper(
             ^^^^^^^^^^^^^^^^^^^^^^^^^^^^
    ...<7 lines>...
    )
    ^
  File "/Library/Frameworks/Python.framework/Versions/3.13/lib/python3.13/site-packages/telegram/request/_baserequest.py", line 385, in _request_wrapper
    raise Conflict(message)
telegram.error.Conflict: Conflict: terminated by other getUpdates request; make sure that only one bot instance is running
2025-10-15 20:34:17,272 - httpx - INFO - HTTP Request: POST https://api.telegram.org/bot8242076298:AAGnHplpi7Ad4hOo9z4zTugjqcCEXLJt9to/getUpdates "HTTP/1.1 200 OK"
2025-10-15 20:34:27,339 - httpx - INFO - HTTP Request: POST https://api.telegram.org/bot8242076298:AAGnHplpi7Ad4hOo9z4zTugjqcCEXLJt9to/getUpdates "HTTP/1.1 200 OK"
2025-10-15 20:34:37,447 - httpx - INFO - HTTP Request: POST https://api.telegram.org/bot8242076298:AAGnHplpi7Ad4hOo9z4zTugjqcCEXLJt9to/getUpdates "HTTP/1.1 200 OK"
2025-10-15 20:34:40,382 - httpx - INFO - HTTP Request: POST https://api.telegram.org/bot8242076298:AAGnHplpi7Ad4hOo9z4zTugjqcCEXLJt9to/getUpdates "HTTP/1.1 409 Conflict"
2025-10-15 20:34:40,383 - telegram.ext.Application - ERROR - No error handlers are registered, logging exception.
Traceback (most recent call last):
  File "/Library/Frameworks/Python.framework/Versions/3.13/lib/python3.13/site-packages/telegram/ext/_updater.py", line 743, in _network_loop_retry
    if not await do_action():
           ^^^^^^^^^^^^^^^^^
  File "/Library/Frameworks/Python.framework/Versions/3.13/lib/python3.13/site-packages/telegram/ext/_updater.py", line 737, in do_action
    return action_cb_task.result()
           ~~~~~~~~~~~~~~~~~~~~~^^
  File "/Library/Frameworks/Python.framework/Versions/3.13/lib/python3.13/site-packages/telegram/ext/_updater.py", line 367, in polling_action_cb
    updates = await self.bot.get_updates(
              ^^^^^^^^^^^^^^^^^^^^^^^^^^^
    ...<7 lines>...
    )
    ^
  File "/Library/Frameworks/Python.framework/Versions/3.13/lib/python3.13/site-packages/telegram/ext/_extbot.py", line 647, in get_updates
    updates = await super().get_updates(
              ^^^^^^^^^^^^^^^^^^^^^^^^^^
    ...<9 lines>...
    )
    ^
  File "/Library/Frameworks/Python.framework/Versions/3.13/lib/python3.13/site-packages/telegram/_bot.py", line 4421, in get_updates
    await self._post(
    ^^^^^^^^^^^^^^^^^
    ...<7 lines>...
    ),
    ^
  File "/Library/Frameworks/Python.framework/Versions/3.13/lib/python3.13/site-packages/telegram/_bot.py", line 617, in _post
    return await self._do_post(
           ^^^^^^^^^^^^^^^^^^^^
    ...<6 lines>...
    )
    ^
  File "/Library/Frameworks/Python.framework/Versions/3.13/lib/python3.13/site-packages/telegram/ext/_extbot.py", line 351, in _do_post
    return await super()._do_post(
           ^^^^^^^^^^^^^^^^^^^^^^^
    ...<6 lines>...
    )
    ^
  File "/Library/Frameworks/Python.framework/Versions/3.13/lib/python3.13/site-packages/telegram/_bot.py", line 646, in _do_post
    result = await request.post(
             ^^^^^^^^^^^^^^^^^^^
    ...<6 lines>...
    )
    ^
  File "/Library/Frameworks/Python.framework/Versions/3.13/lib/python3.13/site-packages/telegram/request/_baserequest.py", line 202, in post
    result = await self._request_wrapper(
             ^^^^^^^^^^^^^^^^^^^^^^^^^^^^
    ...<7 lines>...
    )
    ^
  File "/Library/Frameworks/Python.framework/Versions/3.13/lib/python3.13/site-packages/telegram/request/_baserequest.py", line 385, in _request_wrapper
    raise Conflict(message)
telegram.error.Conflict: Conflict: terminated by other getUpdates request; make sure that only one bot instance is running
2025-10-15 20:34:51,453 - httpx - INFO - HTTP Request: POST https://api.telegram.org/bot8242076298:AAGnHplpi7Ad4hOo9z4zTugjqcCEXLJt9to/getUpdates "HTTP/1.1 200 OK"
2025-10-15 20:35:01,614 - httpx - INFO - HTTP Request: POST https://api.telegram.org/bot8242076298:AAGnHplpi7Ad4hOo9z4zTugjqcCEXLJt9to/getUpdates "HTTP/1.1 200 OK"
2025-10-15 20:35:11,751 - httpx - INFO - HTTP Request: POST https://api.telegram.org/bot8242076298:AAGnHplpi7Ad4hOo9z4zTugjqcCEXLJt9to/getUpdates "HTTP/1.1 200 OK"
2025-10-15 20:35:14,656 - httpx - INFO - HTTP Request: POST https://api.telegram.org/bot8242076298:AAGnHplpi7Ad4hOo9z4zTugjqcCEXLJt9to/getUpdates "HTTP/1.1 409 Conflict"
2025-10-15 20:35:14,656 - telegram.ext.Application - ERROR - No error handlers are registered, logging exception.
Traceback (most recent call last):
  File "/Library/Frameworks/Python.framework/Versions/3.13/lib/python3.13/site-packages/telegram/ext/_updater.py", line 743, in _network_loop_retry
    if not await do_action():
           ^^^^^^^^^^^^^^^^^
  File "/Library/Frameworks/Python.framework/Versions/3.13/lib/python3.13/site-packages/telegram/ext/_updater.py", line 737, in do_action
    return action_cb_task.result()
           ~~~~~~~~~~~~~~~~~~~~~^^
  File "/Library/Frameworks/Python.framework/Versions/3.13/lib/python3.13/site-packages/telegram/ext/_updater.py", line 367, in polling_action_cb
    updates = await self.bot.get_updates(
              ^^^^^^^^^^^^^^^^^^^^^^^^^^^
    ...<7 lines>...
    )
    ^
  File "/Library/Frameworks/Python.framework/Versions/3.13/lib/python3.13/site-packages/telegram/ext/_extbot.py", line 647, in get_updates
    updates = await super().get_updates(
              ^^^^^^^^^^^^^^^^^^^^^^^^^^
    ...<9 lines>...
    )
    ^
  File "/Library/Frameworks/Python.framework/Versions/3.13/lib/python3.13/site-packages/telegram/_bot.py", line 4421, in get_updates
    await self._post(
    ^^^^^^^^^^^^^^^^^
    ...<7 lines>...
    ),
    ^
  File "/Library/Frameworks/Python.framework/Versions/3.13/lib/python3.13/site-packages/telegram/_bot.py", line 617, in _post
    return await self._do_post(
           ^^^^^^^^^^^^^^^^^^^^
    ...<6 lines>...
    )
    ^
  File "/Library/Frameworks/Python.framework/Versions/3.13/lib/python3.13/site-packages/telegram/ext/_extbot.py", line 351, in _do_post
    return await super()._do_post(
           ^^^^^^^^^^^^^^^^^^^^^^^
    ...<6 lines>...
    )
    ^
  File "/Library/Frameworks/Python.framework/Versions/3.13/lib/python3.13/site-packages/telegram/_bot.py", line 646, in _do_post
    result = await request.post(
             ^^^^^^^^^^^^^^^^^^^
    ...<6 lines>...
    )
    ^
  File "/Library/Frameworks/Python.framework/Versions/3.13/lib/python3.13/site-packages/telegram/request/_baserequest.py", line 202, in post
    result = await self._request_wrapper(
             ^^^^^^^^^^^^^^^^^^^^^^^^^^^^
    ...<7 lines>...
    )
    ^
  File "/Library/Frameworks/Python.framework/Versions/3.13/lib/python3.13/site-packages/telegram/request/_baserequest.py", line 385, in _request_wrapper
    raise Conflict(message)
telegram.error.Conflict: Conflict: terminated by other getUpdates request; make sure that only one bot instance is running
2025-10-15 20:35:25,721 - httpx - INFO - HTTP Request: POST https://api.telegram.org/bot8242076298:AAGnHplpi7Ad4hOo9z4zTugjqcCEXLJt9to/getUpdates "HTTP/1.1 200 OK"
2025-10-15 20:35:35,785 - httpx - INFO - HTTP Request: POST https://api.telegram.org/bot8242076298:AAGnHplpi7Ad4hOo9z4zTugjqcCEXLJt9to/getUpdates "HTTP/1.1 200 OK"
2025-10-15 20:35:45,853 - httpx - INFO - HTTP Request: POST https://api.telegram.org/bot8242076298:AAGnHplpi7Ad4hOo9z4zTugjqcCEXLJt9to/getUpdates "HTTP/1.1 200 OK"
2025-10-15 20:35:48,930 - httpx - INFO - HTTP Request: POST https://api.telegram.org/bot8242076298:AAGnHplpi7Ad4hOo9z4zTugjqcCEXLJt9to/getUpdates "HTTP/1.1 409 Conflict"
2025-10-15 20:35:48,931 - telegram.ext.Application - ERROR - No error handlers are registered, logging exception.
Traceback (most recent call last):
  File "/Library/Frameworks/Python.framework/Versions/3.13/lib/python3.13/site-packages/telegram/ext/_updater.py", line 743, in _network_loop_retry
    if not await do_action():
           ^^^^^^^^^^^^^^^^^
  File "/Library/Frameworks/Python.framework/Versions/3.13/lib/python3.13/site-packages/telegram/ext/_updater.py", line 737, in do_action
    return action_cb_task.result()
           ~~~~~~~~~~~~~~~~~~~~~^^
  File "/Library/Frameworks/Python.framework/Versions/3.13/lib/python3.13/site-packages/telegram/ext/_updater.py", line 367, in polling_action_cb
    updates = await self.bot.get_updates(
              ^^^^^^^^^^^^^^^^^^^^^^^^^^^
    ...<7 lines>...
    )
    ^
  File "/Library/Frameworks/Python.framework/Versions/3.13/lib/python3.13/site-packages/telegram/ext/_extbot.py", line 647, in get_updates
    updates = await super().get_updates(
              ^^^^^^^^^^^^^^^^^^^^^^^^^^
    ...<9 lines>...
    )
    ^
  File "/Library/Frameworks/Python.framework/Versions/3.13/lib/python3.13/site-packages/telegram/_bot.py", line 4421, in get_updates
    await self._post(
    ^^^^^^^^^^^^^^^^^
    ...<7 lines>...
    ),
    ^
  File "/Library/Frameworks/Python.framework/Versions/3.13/lib/python3.13/site-packages/telegram/_bot.py", line 617, in _post
    return await self._do_post(
           ^^^^^^^^^^^^^^^^^^^^
    ...<6 lines>...
    )
    ^
  File "/Library/Frameworks/Python.framework/Versions/3.13/lib/python3.13/site-packages/telegram/ext/_extbot.py", line 351, in _do_post
    return await super()._do_post(
           ^^^^^^^^^^^^^^^^^^^^^^^
    ...<6 lines>...
    )
    ^
  File "/Library/Frameworks/Python.framework/Versions/3.13/lib/python3.13/site-packages/telegram/_bot.py", line 646, in _do_post
    result = await request.post(
             ^^^^^^^^^^^^^^^^^^^
    ...<6 lines>...
    )
    ^
  File "/Library/Frameworks/Python.framework/Versions/3.13/lib/python3.13/site-packages/telegram/request/_baserequest.py", line 202, in post
    result = await self._request_wrapper(
             ^^^^^^^^^^^^^^^^^^^^^^^^^^^^
    ...<7 lines>...
    )
    ^
  File "/Library/Frameworks/Python.framework/Versions/3.13/lib/python3.13/site-packages/telegram/request/_baserequest.py", line 385, in _request_wrapper
    raise Conflict(message)
telegram.error.Conflict: Conflict: terminated by other getUpdates request; make sure that only one bot instance is running
2025-10-15 20:36:00,085 - httpx - INFO - HTTP Request: POST https://api.telegram.org/bot8242076298:AAGnHplpi7Ad4hOo9z4zTugjqcCEXLJt9to/getUpdates "HTTP/1.1 200 OK"
2025-10-15 20:36:10,152 - httpx - INFO - HTTP Request: POST https://api.telegram.org/bot8242076298:AAGnHplpi7Ad4hOo9z4zTugjqcCEXLJt9to/getUpdates "HTTP/1.1 200 OK"
2025-10-15 20:36:20,260 - httpx - INFO - HTTP Request: POST https://api.telegram.org/bot8242076298:AAGnHplpi7Ad4hOo9z4zTugjqcCEXLJt9to/getUpdates "HTTP/1.1 200 OK"
2025-10-15 20:36:23,233 - httpx - INFO - HTTP Request: POST https://api.telegram.org/bot8242076298:AAGnHplpi7Ad4hOo9z4zTugjqcCEXLJt9to/getUpdates "HTTP/1.1 409 Conflict"
2025-10-15 20:36:23,233 - telegram.ext.Application - ERROR - No error handlers are registered, logging exception.
Traceback (most recent call last):
  File "/Library/Frameworks/Python.framework/Versions/3.13/lib/python3.13/site-packages/telegram/ext/_updater.py", line 743, in _network_loop_retry
    if not await do_action():
           ^^^^^^^^^^^^^^^^^
  File "/Library/Frameworks/Python.framework/Versions/3.13/lib/python3.13/site-packages/telegram/ext/_updater.py", line 737, in do_action
    return action_cb_task.result()
           ~~~~~~~~~~~~~~~~~~~~~^^
  File "/Library/Frameworks/Python.framework/Versions/3.13/lib/python3.13/site-packages/telegram/ext/_updater.py", line 367, in polling_action_cb
    updates = await self.bot.get_updates(
              ^^^^^^^^^^^^^^^^^^^^^^^^^^^
    ...<7 lines>...
    )
    ^
  File "/Library/Frameworks/Python.framework/Versions/3.13/lib/python3.13/site-packages/telegram/ext/_extbot.py", line 647, in get_updates
    updates = await super().get_updates(
              ^^^^^^^^^^^^^^^^^^^^^^^^^^
    ...<9 lines>...
    )
    ^
  File "/Library/Frameworks/Python.framework/Versions/3.13/lib/python3.13/site-packages/telegram/_bot.py", line 4421, in get_updates
    await self._post(
    ^^^^^^^^^^^^^^^^^
    ...<7 lines>...
    ),
    ^
  File "/Library/Frameworks/Python.framework/Versions/3.13/lib/python3.13/site-packages/telegram/_bot.py", line 617, in _post
    return await self._do_post(
           ^^^^^^^^^^^^^^^^^^^^
    ...<6 lines>...
    )
    ^
  File "/Library/Frameworks/Python.framework/Versions/3.13/lib/python3.13/site-packages/telegram/ext/_extbot.py", line 351, in _do_post
    return await super()._do_post(
           ^^^^^^^^^^^^^^^^^^^^^^^
    ...<6 lines>...
    )
    ^
  File "/Library/Frameworks/Python.framework/Versions/3.13/lib/python3.13/site-packages/telegram/_bot.py", line 646, in _do_post
    result = await request.post(
             ^^^^^^^^^^^^^^^^^^^
    ...<6 lines>...
    )
    ^
  File "/Library/Frameworks/Python.framework/Versions/3.13/lib/python3.13/site-packages/telegram/request/_baserequest.py", line 202, in post
    result = await self._request_wrapper(
             ^^^^^^^^^^^^^^^^^^^^^^^^^^^^
    ...<7 lines>...
    )
    ^
  File "/Library/Frameworks/Python.framework/Versions/3.13/lib/python3.13/site-packages/telegram/request/_baserequest.py", line 385, in _request_wrapper
    raise Conflict(message)
telegram.error.Conflict: Conflict: terminated by other getUpdates request; make sure that only one bot instance is running
2025-10-15 20:36:34,306 - httpx - INFO - HTTP Request: POST https://api.telegram.org/bot8242076298:AAGnHplpi7Ad4hOo9z4zTugjqcCEXLJt9to/getUpdates "HTTP/1.1 200 OK"
2025-10-15 20:36:44,371 - httpx - INFO - HTTP Request: POST https://api.telegram.org/bot8242076298:AAGnHplpi7Ad4hOo9z4zTugjqcCEXLJt9to/getUpdates "HTTP/1.1 200 OK"
2025-10-15 20:36:54,459 - httpx - INFO - HTTP Request: POST https://api.telegram.org/bot8242076298:AAGnHplpi7Ad4hOo9z4zTugjqcCEXLJt9to/getUpdates "HTTP/1.1 200 OK"
2025-10-15 20:36:57,524 - httpx - INFO - HTTP Request: POST https://api.telegram.org/bot8242076298:AAGnHplpi7Ad4hOo9z4zTugjqcCEXLJt9to/getUpdates "HTTP/1.1 409 Conflict"
2025-10-15 20:36:57,526 - telegram.ext.Application - ERROR - No error handlers are registered, logging exception.
Traceback (most recent call last):
  File "/Library/Frameworks/Python.framework/Versions/3.13/lib/python3.13/site-packages/telegram/ext/_updater.py", line 743, in _network_loop_retry
    if not await do_action():
           ^^^^^^^^^^^^^^^^^
  File "/Library/Frameworks/Python.framework/Versions/3.13/lib/python3.13/site-packages/telegram/ext/_updater.py", line 737, in do_action
    return action_cb_task.result()
           ~~~~~~~~~~~~~~~~~~~~~^^
  File "/Library/Frameworks/Python.framework/Versions/3.13/lib/python3.13/site-packages/telegram/ext/_updater.py", line 367, in polling_action_cb
    updates = await self.bot.get_updates(
              ^^^^^^^^^^^^^^^^^^^^^^^^^^^
    ...<7 lines>...
    )
    ^
  File "/Library/Frameworks/Python.framework/Versions/3.13/lib/python3.13/site-packages/telegram/ext/_extbot.py", line 647, in get_updates
    updates = await super().get_updates(
              ^^^^^^^^^^^^^^^^^^^^^^^^^^
    ...<9 lines>...
    )
    ^
  File "/Library/Frameworks/Python.framework/Versions/3.13/lib/python3.13/site-packages/telegram/_bot.py", line 4421, in get_updates
    await self._post(
    ^^^^^^^^^^^^^^^^^
    ...<7 lines>...
    ),
    ^
  File "/Library/Frameworks/Python.framework/Versions/3.13/lib/python3.13/site-packages/telegram/_bot.py", line 617, in _post
    return await self._do_post(
           ^^^^^^^^^^^^^^^^^^^^
    ...<6 lines>...
    )
    ^
  File "/Library/Frameworks/Python.framework/Versions/3.13/lib/python3.13/site-packages/telegram/ext/_extbot.py", line 351, in _do_post
    return await super()._do_post(
           ^^^^^^^^^^^^^^^^^^^^^^^
    ...<6 lines>...
    )
    ^
  File "/Library/Frameworks/Python.framework/Versions/3.13/lib/python3.13/site-packages/telegram/_bot.py", line 646, in _do_post
    result = await request.post(
             ^^^^^^^^^^^^^^^^^^^
    ...<6 lines>...
    )
    ^
  File "/Library/Frameworks/Python.framework/Versions/3.13/lib/python3.13/site-packages/telegram/request/_baserequest.py", line 202, in post
    result = await self._request_wrapper(
             ^^^^^^^^^^^^^^^^^^^^^^^^^^^^
    ...<7 lines>...
    )
    ^
  File "/Library/Frameworks/Python.framework/Versions/3.13/lib/python3.13/site-packages/telegram/request/_baserequest.py", line 385, in _request_wrapper
    raise Conflict(message)
telegram.error.Conflict: Conflict: terminated by other getUpdates request; make sure that only one bot instance is running
2025-10-15 20:37:08,600 - httpx - INFO - HTTP Request: POST https://api.telegram.org/bot8242076298:AAGnHplpi7Ad4hOo9z4zTugjqcCEXLJt9to/getUpdates "HTTP/1.1 200 OK"
2025-10-15 20:37:18,672 - httpx - INFO - HTTP Request: POST https://api.telegram.org/bot8242076298:AAGnHplpi7Ad4hOo9z4zTugjqcCEXLJt9to/getUpdates "HTTP/1.1 200 OK"
2025-10-15 20:37:28,742 - httpx - INFO - HTTP Request: POST https://api.telegram.org/bot8242076298:AAGnHplpi7Ad4hOo9z4zTugjqcCEXLJt9to/getUpdates "HTTP/1.1 200 OK"
2025-10-15 20:37:31,828 - httpx - INFO - HTTP Request: POST https://api.telegram.org/bot8242076298:AAGnHplpi7Ad4hOo9z4zTugjqcCEXLJt9to/getUpdates "HTTP/1.1 409 Conflict"
2025-10-15 20:37:31,829 - telegram.ext.Application - ERROR - No error handlers are registered, logging exception.
Traceback (most recent call last):
  File "/Library/Frameworks/Python.framework/Versions/3.13/lib/python3.13/site-packages/telegram/ext/_updater.py", line 743, in _network_loop_retry
    if not await do_action():
           ^^^^^^^^^^^^^^^^^
  File "/Library/Frameworks/Python.framework/Versions/3.13/lib/python3.13/site-packages/telegram/ext/_updater.py", line 737, in do_action
    return action_cb_task.result()
           ~~~~~~~~~~~~~~~~~~~~~^^
  File "/Library/Frameworks/Python.framework/Versions/3.13/lib/python3.13/site-packages/telegram/ext/_updater.py", line 367, in polling_action_cb
    updates = await self.bot.get_updates(
              ^^^^^^^^^^^^^^^^^^^^^^^^^^^
    ...<7 lines>...
    )
    ^
  File "/Library/Frameworks/Python.framework/Versions/3.13/lib/python3.13/site-packages/telegram/ext/_extbot.py", line 647, in get_updates
    updates = await super().get_updates(
              ^^^^^^^^^^^^^^^^^^^^^^^^^^
    ...<9 lines>...
    )
    ^
  File "/Library/Frameworks/Python.framework/Versions/3.13/lib/python3.13/site-packages/telegram/_bot.py", line 4421, in get_updates
    await self._post(
    ^^^^^^^^^^^^^^^^^
    ...<7 lines>...
    ),
    ^
  File "/Library/Frameworks/Python.framework/Versions/3.13/lib/python3.13/site-packages/telegram/_bot.py", line 617, in _post
    return await self._do_post(
           ^^^^^^^^^^^^^^^^^^^^
    ...<6 lines>...
    )
    ^
  File "/Library/Frameworks/Python.framework/Versions/3.13/lib/python3.13/site-packages/telegram/ext/_extbot.py", line 351, in _do_post
    return await super()._do_post(
           ^^^^^^^^^^^^^^^^^^^^^^^
    ...<6 lines>...
    )
    ^
  File "/Library/Frameworks/Python.framework/Versions/3.13/lib/python3.13/site-packages/telegram/_bot.py", line 646, in _do_post
    result = await request.post(
             ^^^^^^^^^^^^^^^^^^^
    ...<6 lines>...
    )
    ^
  File "/Library/Frameworks/Python.framework/Versions/3.13/lib/python3.13/site-packages/telegram/request/_baserequest.py", line 202, in post
    result = await self._request_wrapper(
             ^^^^^^^^^^^^^^^^^^^^^^^^^^^^
    ...<7 lines>...
    )
    ^
  File "/Library/Frameworks/Python.framework/Versions/3.13/lib/python3.13/site-packages/telegram/request/_baserequest.py", line 385, in _request_wrapper
    raise Conflict(message)
telegram.error.Conflict: Conflict: terminated by other getUpdates request; make sure that only one bot instance is running
2025-10-15 20:37:42,902 - httpx - INFO - HTTP Request: POST https://api.telegram.org/bot8242076298:AAGnHplpi7Ad4hOo9z4zTugjqcCEXLJt9to/getUpdates "HTTP/1.1 200 OK"
2025-10-15 20:37:52,979 - httpx - INFO - HTTP Request: POST https://api.telegram.org/bot8242076298:AAGnHplpi7Ad4hOo9z4zTugjqcCEXLJt9to/getUpdates "HTTP/1.1 200 OK"
2025-10-15 20:38:03,050 - httpx - INFO - HTTP Request: POST https://api.telegram.org/bot8242076298:AAGnHplpi7Ad4hOo9z4zTugjqcCEXLJt9to/getUpdates "HTTP/1.1 200 OK"
2025-10-15 20:38:06,113 - httpx - INFO - HTTP Request: POST https://api.telegram.org/bot8242076298:AAGnHplpi7Ad4hOo9z4zTugjqcCEXLJt9to/getUpdates "HTTP/1.1 409 Conflict"
2025-10-15 20:38:06,113 - telegram.ext.Application - ERROR - No error handlers are registered, logging exception.
Traceback (most recent call last):
  File "/Library/Frameworks/Python.framework/Versions/3.13/lib/python3.13/site-packages/telegram/ext/_updater.py", line 743, in _network_loop_retry
    if not await do_action():
           ^^^^^^^^^^^^^^^^^
  File "/Library/Frameworks/Python.framework/Versions/3.13/lib/python3.13/site-packages/telegram/ext/_updater.py", line 737, in do_action
    return action_cb_task.result()
           ~~~~~~~~~~~~~~~~~~~~~^^
  File "/Library/Frameworks/Python.framework/Versions/3.13/lib/python3.13/site-packages/telegram/ext/_updater.py", line 367, in polling_action_cb
    updates = await self.bot.get_updates(
              ^^^^^^^^^^^^^^^^^^^^^^^^^^^
    ...<7 lines>...
    )
    ^
  File "/Library/Frameworks/Python.framework/Versions/3.13/lib/python3.13/site-packages/telegram/ext/_extbot.py", line 647, in get_updates
    updates = await super().get_updates(
              ^^^^^^^^^^^^^^^^^^^^^^^^^^
    ...<9 lines>...
    )
    ^
  File "/Library/Frameworks/Python.framework/Versions/3.13/lib/python3.13/site-packages/telegram/_bot.py", line 4421, in get_updates
    await self._post(
    ^^^^^^^^^^^^^^^^^
    ...<7 lines>...
    ),
    ^
  File "/Library/Frameworks/Python.framework/Versions/3.13/lib/python3.13/site-packages/telegram/_bot.py", line 617, in _post
    return await self._do_post(
           ^^^^^^^^^^^^^^^^^^^^
    ...<6 lines>...
    )
    ^
  File "/Library/Frameworks/Python.framework/Versions/3.13/lib/python3.13/site-packages/telegram/ext/_extbot.py", line 351, in _do_post
    return await super()._do_post(
           ^^^^^^^^^^^^^^^^^^^^^^^
    ...<6 lines>...
    )
    ^
  File "/Library/Frameworks/Python.framework/Versions/3.13/lib/python3.13/site-packages/telegram/_bot.py", line 646, in _do_post
    result = await request.post(
             ^^^^^^^^^^^^^^^^^^^
    ...<6 lines>...
    )
    ^
  File "/Library/Frameworks/Python.framework/Versions/3.13/lib/python3.13/site-packages/telegram/request/_baserequest.py", line 202, in post
    result = await self._request_wrapper(
             ^^^^^^^^^^^^^^^^^^^^^^^^^^^^
    ...<7 lines>...
    )
    ^
  File "/Library/Frameworks/Python.framework/Versions/3.13/lib/python3.13/site-packages/telegram/request/_baserequest.py", line 385, in _request_wrapper
    raise Conflict(message)
telegram.error.Conflict: Conflict: terminated by other getUpdates request; make sure that only one bot instance is running
2025-10-15 20:38:17,181 - httpx - INFO - HTTP Request: POST https://api.telegram.org/bot8242076298:AAGnHplpi7Ad4hOo9z4zTugjqcCEXLJt9to/getUpdates "HTTP/1.1 200 OK"
2025-10-15 20:38:27,337 - httpx - INFO - HTTP Request: POST https://api.telegram.org/bot8242076298:AAGnHplpi7Ad4hOo9z4zTugjqcCEXLJt9to/getUpdates "HTTP/1.1 200 OK"
2025-10-15 20:38:37,476 - httpx - INFO - HTTP Request: POST https://api.telegram.org/bot8242076298:AAGnHplpi7Ad4hOo9z4zTugjqcCEXLJt9to/getUpdates "HTTP/1.1 200 OK"
2025-10-15 20:38:40,409 - httpx - INFO - HTTP Request: POST https://api.telegram.org/bot8242076298:AAGnHplpi7Ad4hOo9z4zTugjqcCEXLJt9to/getUpdates "HTTP/1.1 409 Conflict"
2025-10-15 20:38:40,410 - telegram.ext.Application - ERROR - No error handlers are registered, logging exception.
Traceback (most recent call last):
  File "/Library/Frameworks/Python.framework/Versions/3.13/lib/python3.13/site-packages/telegram/ext/_updater.py", line 743, in _network_loop_retry
    if not await do_action():
           ^^^^^^^^^^^^^^^^^
  File "/Library/Frameworks/Python.framework/Versions/3.13/lib/python3.13/site-packages/telegram/ext/_updater.py", line 737, in do_action
    return action_cb_task.result()
           ~~~~~~~~~~~~~~~~~~~~~^^
  File "/Library/Frameworks/Python.framework/Versions/3.13/lib/python3.13/site-packages/telegram/ext/_updater.py", line 367, in polling_action_cb
    updates = await self.bot.get_updates(
              ^^^^^^^^^^^^^^^^^^^^^^^^^^^
    ...<7 lines>...
    )
    ^
  File "/Library/Frameworks/Python.framework/Versions/3.13/lib/python3.13/site-packages/telegram/ext/_extbot.py", line 647, in get_updates
    updates = await super().get_updates(
              ^^^^^^^^^^^^^^^^^^^^^^^^^^
    ...<9 lines>...
    )
    ^
  File "/Library/Frameworks/Python.framework/Versions/3.13/lib/python3.13/site-packages/telegram/_bot.py", line 4421, in get_updates
    await self._post(
    ^^^^^^^^^^^^^^^^^
    ...<7 lines>...
    ),
    ^
  File "/Library/Frameworks/Python.framework/Versions/3.13/lib/python3.13/site-packages/telegram/_bot.py", line 617, in _post
    return await self._do_post(
           ^^^^^^^^^^^^^^^^^^^^
    ...<6 lines>...
    )
    ^
  File "/Library/Frameworks/Python.framework/Versions/3.13/lib/python3.13/site-packages/telegram/ext/_extbot.py", line 351, in _do_post
    return await super()._do_post(
           ^^^^^^^^^^^^^^^^^^^^^^^
    ...<6 lines>...
    )
    ^
  File "/Library/Frameworks/Python.framework/Versions/3.13/lib/python3.13/site-packages/telegram/_bot.py", line 646, in _do_post
    result = await request.post(
             ^^^^^^^^^^^^^^^^^^^
    ...<6 lines>...
    )
    ^
  File "/Library/Frameworks/Python.framework/Versions/3.13/lib/python3.13/site-packages/telegram/request/_baserequest.py", line 202, in post
    result = await self._request_wrapper(
             ^^^^^^^^^^^^^^^^^^^^^^^^^^^^
    ...<7 lines>...
    )
    ^
  File "/Library/Frameworks/Python.framework/Versions/3.13/lib/python3.13/site-packages/telegram/request/_baserequest.py", line 385, in _request_wrapper
    raise Conflict(message)
telegram.error.Conflict: Conflict: terminated by other getUpdates request; make sure that only one bot instance is running
2025-10-15 20:38:51,503 - httpx - INFO - HTTP Request: POST https://api.telegram.org/bot8242076298:AAGnHplpi7Ad4hOo9z4zTugjqcCEXLJt9to/getUpdates "HTTP/1.1 200 OK"
2025-10-15 20:39:01,641 - httpx - INFO - HTTP Request: POST https://api.telegram.org/bot8242076298:AAGnHplpi7Ad4hOo9z4zTugjqcCEXLJt9to/getUpdates "HTTP/1.1 200 OK"
2025-10-15 20:39:11,708 - httpx - INFO - HTTP Request: POST https://api.telegram.org/bot8242076298:AAGnHplpi7Ad4hOo9z4zTugjqcCEXLJt9to/getUpdates "HTTP/1.1 200 OK"
2025-10-15 20:39:14,716 - httpx - INFO - HTTP Request: POST https://api.telegram.org/bot8242076298:AAGnHplpi7Ad4hOo9z4zTugjqcCEXLJt9to/getUpdates "HTTP/1.1 409 Conflict"
2025-10-15 20:39:14,716 - telegram.ext.Application - ERROR - No error handlers are registered, logging exception.
Traceback (most recent call last):
  File "/Library/Frameworks/Python.framework/Versions/3.13/lib/python3.13/site-packages/telegram/ext/_updater.py", line 743, in _network_loop_retry
    if not await do_action():
           ^^^^^^^^^^^^^^^^^
  File "/Library/Frameworks/Python.framework/Versions/3.13/lib/python3.13/site-packages/telegram/ext/_updater.py", line 737, in do_action
    return action_cb_task.result()
           ~~~~~~~~~~~~~~~~~~~~~^^
  File "/Library/Frameworks/Python.framework/Versions/3.13/lib/python3.13/site-packages/telegram/ext/_updater.py", line 367, in polling_action_cb
    updates = await self.bot.get_updates(
              ^^^^^^^^^^^^^^^^^^^^^^^^^^^
    ...<7 lines>...
    )
    ^
  File "/Library/Frameworks/Python.framework/Versions/3.13/lib/python3.13/site-packages/telegram/ext/_extbot.py", line 647, in get_updates
    updates = await super().get_updates(
              ^^^^^^^^^^^^^^^^^^^^^^^^^^
    ...<9 lines>...
    )
    ^
  File "/Library/Frameworks/Python.framework/Versions/3.13/lib/python3.13/site-packages/telegram/_bot.py", line 4421, in get_updates
    await self._post(
    ^^^^^^^^^^^^^^^^^
    ...<7 lines>...
    ),
    ^
  File "/Library/Frameworks/Python.framework/Versions/3.13/lib/python3.13/site-packages/telegram/_bot.py", line 617, in _post
    return await self._do_post(
           ^^^^^^^^^^^^^^^^^^^^
    ...<6 lines>...
    )
    ^
  File "/Library/Frameworks/Python.framework/Versions/3.13/lib/python3.13/site-packages/telegram/ext/_extbot.py", line 351, in _do_post
    return await super()._do_post(
           ^^^^^^^^^^^^^^^^^^^^^^^
    ...<6 lines>...
    )
    ^
  File "/Library/Frameworks/Python.framework/Versions/3.13/lib/python3.13/site-packages/telegram/_bot.py", line 646, in _do_post
    result = await request.post(
             ^^^^^^^^^^^^^^^^^^^
    ...<6 lines>...
    )
    ^
  File "/Library/Frameworks/Python.framework/Versions/3.13/lib/python3.13/site-packages/telegram/request/_baserequest.py", line 202, in post
    result = await self._request_wrapper(
             ^^^^^^^^^^^^^^^^^^^^^^^^^^^^
    ...<7 lines>...
    )
    ^
  File "/Library/Frameworks/Python.framework/Versions/3.13/lib/python3.13/site-packages/telegram/request/_baserequest.py", line 385, in _request_wrapper
    raise Conflict(message)
telegram.error.Conflict: Conflict: terminated by other getUpdates request; make sure that only one bot instance is running
2025-10-15 20:39:25,785 - httpx - INFO - HTTP Request: POST https://api.telegram.org/bot8242076298:AAGnHplpi7Ad4hOo9z4zTugjqcCEXLJt9to/getUpdates "HTTP/1.1 200 OK"
2025-10-15 20:39:35,856 - httpx - INFO - HTTP Request: POST https://api.telegram.org/bot8242076298:AAGnHplpi7Ad4hOo9z4zTugjqcCEXLJt9to/getUpdates "HTTP/1.1 200 OK"
2025-10-15 20:39:45,921 - httpx - INFO - HTTP Request: POST https://api.telegram.org/bot8242076298:AAGnHplpi7Ad4hOo9z4zTugjqcCEXLJt9to/getUpdates "HTTP/1.1 200 OK"
2025-10-15 20:39:48,982 - httpx - INFO - HTTP Request: POST https://api.telegram.org/bot8242076298:AAGnHplpi7Ad4hOo9z4zTugjqcCEXLJt9to/getUpdates "HTTP/1.1 409 Conflict"
2025-10-15 20:39:48,984 - telegram.ext.Application - ERROR - No error handlers are registered, logging exception.
Traceback (most recent call last):
  File "/Library/Frameworks/Python.framework/Versions/3.13/lib/python3.13/site-packages/telegram/ext/_updater.py", line 743, in _network_loop_retry
    if not await do_action():
           ^^^^^^^^^^^^^^^^^
  File "/Library/Frameworks/Python.framework/Versions/3.13/lib/python3.13/site-packages/telegram/ext/_updater.py", line 737, in do_action
    return action_cb_task.result()
           ~~~~~~~~~~~~~~~~~~~~~^^
  File "/Library/Frameworks/Python.framework/Versions/3.13/lib/python3.13/site-packages/telegram/ext/_updater.py", line 367, in polling_action_cb
    updates = await self.bot.get_updates(
              ^^^^^^^^^^^^^^^^^^^^^^^^^^^
    ...<7 lines>...
    )
    ^
  File "/Library/Frameworks/Python.framework/Versions/3.13/lib/python3.13/site-packages/telegram/ext/_extbot.py", line 647, in get_updates
    updates = await super().get_updates(
              ^^^^^^^^^^^^^^^^^^^^^^^^^^
    ...<9 lines>...
    )
    ^
  File "/Library/Frameworks/Python.framework/Versions/3.13/lib/python3.13/site-packages/telegram/_bot.py", line 4421, in get_updates
    await self._post(
    ^^^^^^^^^^^^^^^^^
    ...<7 lines>...
    ),
    ^
  File "/Library/Frameworks/Python.framework/Versions/3.13/lib/python3.13/site-packages/telegram/_bot.py", line 617, in _post
    return await self._do_post(
           ^^^^^^^^^^^^^^^^^^^^
    ...<6 lines>...
    )
    ^
  File "/Library/Frameworks/Python.framework/Versions/3.13/lib/python3.13/site-packages/telegram/ext/_extbot.py", line 351, in _do_post
    return await super()._do_post(
           ^^^^^^^^^^^^^^^^^^^^^^^
    ...<6 lines>...
    )
    ^
  File "/Library/Frameworks/Python.framework/Versions/3.13/lib/python3.13/site-packages/telegram/_bot.py", line 646, in _do_post
    result = await request.post(
             ^^^^^^^^^^^^^^^^^^^
    ...<6 lines>...
    )
    ^
  File "/Library/Frameworks/Python.framework/Versions/3.13/lib/python3.13/site-packages/telegram/request/_baserequest.py", line 202, in post
    result = await self._request_wrapper(
             ^^^^^^^^^^^^^^^^^^^^^^^^^^^^
    ...<7 lines>...
    )
    ^
  File "/Library/Frameworks/Python.framework/Versions/3.13/lib/python3.13/site-packages/telegram/request/_baserequest.py", line 385, in _request_wrapper
    raise Conflict(message)
telegram.error.Conflict: Conflict: terminated by other getUpdates request; make sure that only one bot instance is running
2025-10-15 20:40:00,112 - httpx - INFO - HTTP Request: POST https://api.telegram.org/bot8242076298:AAGnHplpi7Ad4hOo9z4zTugjqcCEXLJt9to/getUpdates "HTTP/1.1 200 OK"
2025-10-15 20:40:10,180 - httpx - INFO - HTTP Request: POST https://api.telegram.org/bot8242076298:AAGnHplpi7Ad4hOo9z4zTugjqcCEXLJt9to/getUpdates "HTTP/1.1 200 OK"
2025-10-15 20:40:20,249 - httpx - INFO - HTTP Request: POST https://api.telegram.org/bot8242076298:AAGnHplpi7Ad4hOo9z4zTugjqcCEXLJt9to/getUpdates "HTTP/1.1 200 OK"
2025-10-15 20:40:23,356 - httpx - INFO - HTTP Request: POST https://api.telegram.org/bot8242076298:AAGnHplpi7Ad4hOo9z4zTugjqcCEXLJt9to/getUpdates "HTTP/1.1 409 Conflict"
2025-10-15 20:40:23,357 - telegram.ext.Application - ERROR - No error handlers are registered, logging exception.
Traceback (most recent call last):
  File "/Library/Frameworks/Python.framework/Versions/3.13/lib/python3.13/site-packages/telegram/ext/_updater.py", line 743, in _network_loop_retry
    if not await do_action():
           ^^^^^^^^^^^^^^^^^
  File "/Library/Frameworks/Python.framework/Versions/3.13/lib/python3.13/site-packages/telegram/ext/_updater.py", line 737, in do_action
    return action_cb_task.result()
           ~~~~~~~~~~~~~~~~~~~~~^^
  File "/Library/Frameworks/Python.framework/Versions/3.13/lib/python3.13/site-packages/telegram/ext/_updater.py", line 367, in polling_action_cb
    updates = await self.bot.get_updates(
              ^^^^^^^^^^^^^^^^^^^^^^^^^^^
    ...<7 lines>...
    )
    ^
  File "/Library/Frameworks/Python.framework/Versions/3.13/lib/python3.13/site-packages/telegram/ext/_extbot.py", line 647, in get_updates
    updates = await super().get_updates(
              ^^^^^^^^^^^^^^^^^^^^^^^^^^
    ...<9 lines>...
    )
    ^
  File "/Library/Frameworks/Python.framework/Versions/3.13/lib/python3.13/site-packages/telegram/_bot.py", line 4421, in get_updates
    await self._post(
    ^^^^^^^^^^^^^^^^^
    ...<7 lines>...
    ),
    ^
  File "/Library/Frameworks/Python.framework/Versions/3.13/lib/python3.13/site-packages/telegram/_bot.py", line 617, in _post
    return await self._do_post(
           ^^^^^^^^^^^^^^^^^^^^
    ...<6 lines>...
    )
    ^
  File "/Library/Frameworks/Python.framework/Versions/3.13/lib/python3.13/site-packages/telegram/ext/_extbot.py", line 351, in _do_post
    return await super()._do_post(
           ^^^^^^^^^^^^^^^^^^^^^^^
    ...<6 lines>...
    )
    ^
  File "/Library/Frameworks/Python.framework/Versions/3.13/lib/python3.13/site-packages/telegram/_bot.py", line 646, in _do_post
    result = await request.post(
             ^^^^^^^^^^^^^^^^^^^
    ...<6 lines>...
    )
    ^
  File "/Library/Frameworks/Python.framework/Versions/3.13/lib/python3.13/site-packages/telegram/request/_baserequest.py", line 202, in post
    result = await self._request_wrapper(
             ^^^^^^^^^^^^^^^^^^^^^^^^^^^^
    ...<7 lines>...
    )
    ^
  File "/Library/Frameworks/Python.framework/Versions/3.13/lib/python3.13/site-packages/telegram/request/_baserequest.py", line 385, in _request_wrapper
    raise Conflict(message)
telegram.error.Conflict: Conflict: terminated by other getUpdates request; make sure that only one bot instance is running
2025-10-15 20:40:34,438 - httpx - INFO - HTTP Request: POST https://api.telegram.org/bot8242076298:AAGnHplpi7Ad4hOo9z4zTugjqcCEXLJt9to/getUpdates "HTTP/1.1 200 OK"
2025-10-15 20:40:44,506 - httpx - INFO - HTTP Request: POST https://api.telegram.org/bot8242076298:AAGnHplpi7Ad4hOo9z4zTugjqcCEXLJt9to/getUpdates "HTTP/1.1 200 OK"
2025-10-15 20:40:54,588 - httpx - INFO - HTTP Request: POST https://api.telegram.org/bot8242076298:AAGnHplpi7Ad4hOo9z4zTugjqcCEXLJt9to/getUpdates "HTTP/1.1 200 OK"
2025-10-15 20:40:57,674 - httpx - INFO - HTTP Request: POST https://api.telegram.org/bot8242076298:AAGnHplpi7Ad4hOo9z4zTugjqcCEXLJt9to/getUpdates "HTTP/1.1 409 Conflict"
2025-10-15 20:40:57,675 - telegram.ext.Application - ERROR - No error handlers are registered, logging exception.
Traceback (most recent call last):
  File "/Library/Frameworks/Python.framework/Versions/3.13/lib/python3.13/site-packages/telegram/ext/_updater.py", line 743, in _network_loop_retry
    if not await do_action():
           ^^^^^^^^^^^^^^^^^
  File "/Library/Frameworks/Python.framework/Versions/3.13/lib/python3.13/site-packages/telegram/ext/_updater.py", line 737, in do_action
    return action_cb_task.result()
           ~~~~~~~~~~~~~~~~~~~~~^^
  File "/Library/Frameworks/Python.framework/Versions/3.13/lib/python3.13/site-packages/telegram/ext/_updater.py", line 367, in polling_action_cb
    updates = await self.bot.get_updates(
              ^^^^^^^^^^^^^^^^^^^^^^^^^^^
    ...<7 lines>...
    )
    ^
  File "/Library/Frameworks/Python.framework/Versions/3.13/lib/python3.13/site-packages/telegram/ext/_extbot.py", line 647, in get_updates
    updates = await super().get_updates(
              ^^^^^^^^^^^^^^^^^^^^^^^^^^
    ...<9 lines>...
    )
    ^
  File "/Library/Frameworks/Python.framework/Versions/3.13/lib/python3.13/site-packages/telegram/_bot.py", line 4421, in get_updates
    await self._post(
    ^^^^^^^^^^^^^^^^^
    ...<7 lines>...
    ),
    ^
  File "/Library/Frameworks/Python.framework/Versions/3.13/lib/python3.13/site-packages/telegram/_bot.py", line 617, in _post
    return await self._do_post(
           ^^^^^^^^^^^^^^^^^^^^
    ...<6 lines>...
    )
    ^
  File "/Library/Frameworks/Python.framework/Versions/3.13/lib/python3.13/site-packages/telegram/ext/_extbot.py", line 351, in _do_post
    return await super()._do_post(
           ^^^^^^^^^^^^^^^^^^^^^^^
    ...<6 lines>...
    )
    ^
  File "/Library/Frameworks/Python.framework/Versions/3.13/lib/python3.13/site-packages/telegram/_bot.py", line 646, in _do_post
    result = await request.post(
             ^^^^^^^^^^^^^^^^^^^
    ...<6 lines>...
    )
    ^
  File "/Library/Frameworks/Python.framework/Versions/3.13/lib/python3.13/site-packages/telegram/request/_baserequest.py", line 202, in post
    result = await self._request_wrapper(
             ^^^^^^^^^^^^^^^^^^^^^^^^^^^^
    ...<7 lines>...
    )
    ^
  File "/Library/Frameworks/Python.framework/Versions/3.13/lib/python3.13/site-packages/telegram/request/_baserequest.py", line 385, in _request_wrapper
    raise Conflict(message)
telegram.error.Conflict: Conflict: terminated by other getUpdates request; make sure that only one bot instance is running
2025-10-15 20:41:08,767 - httpx - INFO - HTTP Request: POST https://api.telegram.org/bot8242076298:AAGnHplpi7Ad4hOo9z4zTugjqcCEXLJt9to/getUpdates "HTTP/1.1 200 OK"
2025-10-15 20:41:18,836 - httpx - INFO - HTTP Request: POST https://api.telegram.org/bot8242076298:AAGnHplpi7Ad4hOo9z4zTugjqcCEXLJt9to/getUpdates "HTTP/1.1 200 OK"
2025-10-15 20:41:28,907 - httpx - INFO - HTTP Request: POST https://api.telegram.org/bot8242076298:AAGnHplpi7Ad4hOo9z4zTugjqcCEXLJt9to/getUpdates "HTTP/1.1 200 OK"
2025-10-15 20:41:32,137 - httpx - INFO - HTTP Request: POST https://api.telegram.org/bot8242076298:AAGnHplpi7Ad4hOo9z4zTugjqcCEXLJt9to/getUpdates "HTTP/1.1 409 Conflict"
2025-10-15 20:41:32,138 - telegram.ext.Application - ERROR - No error handlers are registered, logging exception.
Traceback (most recent call last):
  File "/Library/Frameworks/Python.framework/Versions/3.13/lib/python3.13/site-packages/telegram/ext/_updater.py", line 743, in _network_loop_retry
    if not await do_action():
           ^^^^^^^^^^^^^^^^^
  File "/Library/Frameworks/Python.framework/Versions/3.13/lib/python3.13/site-packages/telegram/ext/_updater.py", line 737, in do_action
    return action_cb_task.result()
           ~~~~~~~~~~~~~~~~~~~~~^^
  File "/Library/Frameworks/Python.framework/Versions/3.13/lib/python3.13/site-packages/telegram/ext/_updater.py", line 367, in polling_action_cb
    updates = await self.bot.get_updates(
              ^^^^^^^^^^^^^^^^^^^^^^^^^^^
    ...<7 lines>...
    )
    ^
  File "/Library/Frameworks/Python.framework/Versions/3.13/lib/python3.13/site-packages/telegram/ext/_extbot.py", line 647, in get_updates
    updates = await super().get_updates(
              ^^^^^^^^^^^^^^^^^^^^^^^^^^
    ...<9 lines>...
    )
    ^
  File "/Library/Frameworks/Python.framework/Versions/3.13/lib/python3.13/site-packages/telegram/_bot.py", line 4421, in get_updates
    await self._post(
    ^^^^^^^^^^^^^^^^^
    ...<7 lines>...
    ),
    ^
  File "/Library/Frameworks/Python.framework/Versions/3.13/lib/python3.13/site-packages/telegram/_bot.py", line 617, in _post
    return await self._do_post(
           ^^^^^^^^^^^^^^^^^^^^
    ...<6 lines>...
    )
    ^
  File "/Library/Frameworks/Python.framework/Versions/3.13/lib/python3.13/site-packages/telegram/ext/_extbot.py", line 351, in _do_post
    return await super()._do_post(
           ^^^^^^^^^^^^^^^^^^^^^^^
    ...<6 lines>...
    )
    ^
  File "/Library/Frameworks/Python.framework/Versions/3.13/lib/python3.13/site-packages/telegram/_bot.py", line 646, in _do_post
    result = await request.post(
             ^^^^^^^^^^^^^^^^^^^
    ...<6 lines>...
    )
    ^
  File "/Library/Frameworks/Python.framework/Versions/3.13/lib/python3.13/site-packages/telegram/request/_baserequest.py", line 202, in post
    result = await self._request_wrapper(
             ^^^^^^^^^^^^^^^^^^^^^^^^^^^^
    ...<7 lines>...
    )
    ^
  File "/Library/Frameworks/Python.framework/Versions/3.13/lib/python3.13/site-packages/telegram/request/_baserequest.py", line 385, in _request_wrapper
    raise Conflict(message)
telegram.error.Conflict: Conflict: terminated by other getUpdates request; make sure that only one bot instance is running
2025-10-15 20:41:43,228 - httpx - INFO - HTTP Request: POST https://api.telegram.org/bot8242076298:AAGnHplpi7Ad4hOo9z4zTugjqcCEXLJt9to/getUpdates "HTTP/1.1 200 OK"
2025-10-15 20:41:53,367 - httpx - INFO - HTTP Request: POST https://api.telegram.org/bot8242076298:AAGnHplpi7Ad4hOo9z4zTugjqcCEXLJt9to/getUpdates "HTTP/1.1 200 OK"
2025-10-15 20:42:03,504 - httpx - INFO - HTTP Request: POST https://api.telegram.org/bot8242076298:AAGnHplpi7Ad4hOo9z4zTugjqcCEXLJt9to/getUpdates "HTTP/1.1 200 OK"
2025-10-15 20:42:06,475 - httpx - INFO - HTTP Request: POST https://api.telegram.org/bot8242076298:AAGnHplpi7Ad4hOo9z4zTugjqcCEXLJt9to/getUpdates "HTTP/1.1 409 Conflict"
2025-10-15 20:42:06,477 - telegram.ext.Application - ERROR - No error handlers are registered, logging exception.
Traceback (most recent call last):
  File "/Library/Frameworks/Python.framework/Versions/3.13/lib/python3.13/site-packages/telegram/ext/_updater.py", line 743, in _network_loop_retry
    if not await do_action():
           ^^^^^^^^^^^^^^^^^
  File "/Library/Frameworks/Python.framework/Versions/3.13/lib/python3.13/site-packages/telegram/ext/_updater.py", line 737, in do_action
    return action_cb_task.result()
           ~~~~~~~~~~~~~~~~~~~~~^^
  File "/Library/Frameworks/Python.framework/Versions/3.13/lib/python3.13/site-packages/telegram/ext/_updater.py", line 367, in polling_action_cb
    updates = await self.bot.get_updates(
              ^^^^^^^^^^^^^^^^^^^^^^^^^^^
    ...<7 lines>...
    )
    ^
  File "/Library/Frameworks/Python.framework/Versions/3.13/lib/python3.13/site-packages/telegram/ext/_extbot.py", line 647, in get_updates
    updates = await super().get_updates(
              ^^^^^^^^^^^^^^^^^^^^^^^^^^
    ...<9 lines>...
    )
    ^
  File "/Library/Frameworks/Python.framework/Versions/3.13/lib/python3.13/site-packages/telegram/_bot.py", line 4421, in get_updates
    await self._post(
    ^^^^^^^^^^^^^^^^^
    ...<7 lines>...
    ),
    ^
  File "/Library/Frameworks/Python.framework/Versions/3.13/lib/python3.13/site-packages/telegram/_bot.py", line 617, in _post
    return await self._do_post(
           ^^^^^^^^^^^^^^^^^^^^
    ...<6 lines>...
    )
    ^
  File "/Library/Frameworks/Python.framework/Versions/3.13/lib/python3.13/site-packages/telegram/ext/_extbot.py", line 351, in _do_post
    return await super()._do_post(
           ^^^^^^^^^^^^^^^^^^^^^^^
    ...<6 lines>...
    )
    ^
  File "/Library/Frameworks/Python.framework/Versions/3.13/lib/python3.13/site-packages/telegram/_bot.py", line 646, in _do_post
    result = await request.post(
             ^^^^^^^^^^^^^^^^^^^
    ...<6 lines>...
    )
    ^
  File "/Library/Frameworks/Python.framework/Versions/3.13/lib/python3.13/site-packages/telegram/request/_baserequest.py", line 202, in post
    result = await self._request_wrapper(
             ^^^^^^^^^^^^^^^^^^^^^^^^^^^^
    ...<7 lines>...
    )
    ^
  File "/Library/Frameworks/Python.framework/Versions/3.13/lib/python3.13/site-packages/telegram/request/_baserequest.py", line 385, in _request_wrapper
    raise Conflict(message)
telegram.error.Conflict: Conflict: terminated by other getUpdates request; make sure that only one bot instance is running
2025-10-15 20:42:17,544 - httpx - INFO - HTTP Request: POST https://api.telegram.org/bot8242076298:AAGnHplpi7Ad4hOo9z4zTugjqcCEXLJt9to/getUpdates "HTTP/1.1 200 OK"
2025-10-15 20:42:27,614 - httpx - INFO - HTTP Request: POST https://api.telegram.org/bot8242076298:AAGnHplpi7Ad4hOo9z4zTugjqcCEXLJt9to/getUpdates "HTTP/1.1 200 OK"
2025-10-15 20:42:37,681 - httpx - INFO - HTTP Request: POST https://api.telegram.org/bot8242076298:AAGnHplpi7Ad4hOo9z4zTugjqcCEXLJt9to/getUpdates "HTTP/1.1 200 OK"
2025-10-15 20:42:40,747 - httpx - INFO - HTTP Request: POST https://api.telegram.org/bot8242076298:AAGnHplpi7Ad4hOo9z4zTugjqcCEXLJt9to/getUpdates "HTTP/1.1 409 Conflict"
2025-10-15 20:42:40,748 - telegram.ext.Application - ERROR - No error handlers are registered, logging exception.
Traceback (most recent call last):
  File "/Library/Frameworks/Python.framework/Versions/3.13/lib/python3.13/site-packages/telegram/ext/_updater.py", line 743, in _network_loop_retry
    if not await do_action():
           ^^^^^^^^^^^^^^^^^
  File "/Library/Frameworks/Python.framework/Versions/3.13/lib/python3.13/site-packages/telegram/ext/_updater.py", line 737, in do_action
    return action_cb_task.result()
           ~~~~~~~~~~~~~~~~~~~~~^^
  File "/Library/Frameworks/Python.framework/Versions/3.13/lib/python3.13/site-packages/telegram/ext/_updater.py", line 367, in polling_action_cb
    updates = await self.bot.get_updates(
              ^^^^^^^^^^^^^^^^^^^^^^^^^^^
    ...<7 lines>...
    )
    ^
  File "/Library/Frameworks/Python.framework/Versions/3.13/lib/python3.13/site-packages/telegram/ext/_extbot.py", line 647, in get_updates
    updates = await super().get_updates(
              ^^^^^^^^^^^^^^^^^^^^^^^^^^
    ...<9 lines>...
    )
    ^
  File "/Library/Frameworks/Python.framework/Versions/3.13/lib/python3.13/site-packages/telegram/_bot.py", line 4421, in get_updates
    await self._post(
    ^^^^^^^^^^^^^^^^^
    ...<7 lines>...
    ),
    ^
  File "/Library/Frameworks/Python.framework/Versions/3.13/lib/python3.13/site-packages/telegram/_bot.py", line 617, in _post
    return await self._do_post(
           ^^^^^^^^^^^^^^^^^^^^
    ...<6 lines>...
    )
    ^
  File "/Library/Frameworks/Python.framework/Versions/3.13/lib/python3.13/site-packages/telegram/ext/_extbot.py", line 351, in _do_post
    return await super()._do_post(
           ^^^^^^^^^^^^^^^^^^^^^^^
    ...<6 lines>...
    )
    ^
  File "/Library/Frameworks/Python.framework/Versions/3.13/lib/python3.13/site-packages/telegram/_bot.py", line 646, in _do_post
    result = await request.post(
             ^^^^^^^^^^^^^^^^^^^
    ...<6 lines>...
    )
    ^
  File "/Library/Frameworks/Python.framework/Versions/3.13/lib/python3.13/site-packages/telegram/request/_baserequest.py", line 202, in post
    result = await self._request_wrapper(
             ^^^^^^^^^^^^^^^^^^^^^^^^^^^^
    ...<7 lines>...
    )
    ^
  File "/Library/Frameworks/Python.framework/Versions/3.13/lib/python3.13/site-packages/telegram/request/_baserequest.py", line 385, in _request_wrapper
    raise Conflict(message)
telegram.error.Conflict: Conflict: terminated by other getUpdates request; make sure that only one bot instance is running
2025-10-15 20:42:51,815 - httpx - INFO - HTTP Request: POST https://api.telegram.org/bot8242076298:AAGnHplpi7Ad4hOo9z4zTugjqcCEXLJt9to/getUpdates "HTTP/1.1 200 OK"
2025-10-15 20:43:01,973 - httpx - INFO - HTTP Request: POST https://api.telegram.org/bot8242076298:AAGnHplpi7Ad4hOo9z4zTugjqcCEXLJt9to/getUpdates "HTTP/1.1 200 OK"
2025-10-15 20:43:12,040 - httpx - INFO - HTTP Request: POST https://api.telegram.org/bot8242076298:AAGnHplpi7Ad4hOo9z4zTugjqcCEXLJt9to/getUpdates "HTTP/1.1 200 OK"
2025-10-15 20:43:15,029 - httpx - INFO - HTTP Request: POST https://api.telegram.org/bot8242076298:AAGnHplpi7Ad4hOo9z4zTugjqcCEXLJt9to/getUpdates "HTTP/1.1 409 Conflict"
2025-10-15 20:43:15,030 - telegram.ext.Application - ERROR - No error handlers are registered, logging exception.
Traceback (most recent call last):
  File "/Library/Frameworks/Python.framework/Versions/3.13/lib/python3.13/site-packages/telegram/ext/_updater.py", line 743, in _network_loop_retry
    if not await do_action():
           ^^^^^^^^^^^^^^^^^
  File "/Library/Frameworks/Python.framework/Versions/3.13/lib/python3.13/site-packages/telegram/ext/_updater.py", line 737, in do_action
    return action_cb_task.result()
           ~~~~~~~~~~~~~~~~~~~~~^^
  File "/Library/Frameworks/Python.framework/Versions/3.13/lib/python3.13/site-packages/telegram/ext/_updater.py", line 367, in polling_action_cb
    updates = await self.bot.get_updates(
              ^^^^^^^^^^^^^^^^^^^^^^^^^^^
    ...<7 lines>...
    )
    ^
  File "/Library/Frameworks/Python.framework/Versions/3.13/lib/python3.13/site-packages/telegram/ext/_extbot.py", line 647, in get_updates
    updates = await super().get_updates(
              ^^^^^^^^^^^^^^^^^^^^^^^^^^
    ...<9 lines>...
    )
    ^
  File "/Library/Frameworks/Python.framework/Versions/3.13/lib/python3.13/site-packages/telegram/_bot.py", line 4421, in get_updates
    await self._post(
    ^^^^^^^^^^^^^^^^^
    ...<7 lines>...
    ),
    ^
  File "/Library/Frameworks/Python.framework/Versions/3.13/lib/python3.13/site-packages/telegram/_bot.py", line 617, in _post
    return await self._do_post(
           ^^^^^^^^^^^^^^^^^^^^
    ...<6 lines>...
    )
    ^
  File "/Library/Frameworks/Python.framework/Versions/3.13/lib/python3.13/site-packages/telegram/ext/_extbot.py", line 351, in _do_post
    return await super()._do_post(
           ^^^^^^^^^^^^^^^^^^^^^^^
    ...<6 lines>...
    )
    ^
  File "/Library/Frameworks/Python.framework/Versions/3.13/lib/python3.13/site-packages/telegram/_bot.py", line 646, in _do_post
    result = await request.post(
             ^^^^^^^^^^^^^^^^^^^
    ...<6 lines>...
    )
    ^
  File "/Library/Frameworks/Python.framework/Versions/3.13/lib/python3.13/site-packages/telegram/request/_baserequest.py", line 202, in post
    result = await self._request_wrapper(
             ^^^^^^^^^^^^^^^^^^^^^^^^^^^^
    ...<7 lines>...
    )
    ^
  File "/Library/Frameworks/Python.framework/Versions/3.13/lib/python3.13/site-packages/telegram/request/_baserequest.py", line 385, in _request_wrapper
    raise Conflict(message)
telegram.error.Conflict: Conflict: terminated by other getUpdates request; make sure that only one bot instance is running
2025-10-15 20:43:26,096 - httpx - INFO - HTTP Request: POST https://api.telegram.org/bot8242076298:AAGnHplpi7Ad4hOo9z4zTugjqcCEXLJt9to/getUpdates "HTTP/1.1 200 OK"
2025-10-15 20:43:36,162 - httpx - INFO - HTTP Request: POST https://api.telegram.org/bot8242076298:AAGnHplpi7Ad4hOo9z4zTugjqcCEXLJt9to/getUpdates "HTTP/1.1 200 OK"
2025-10-15 20:43:46,363 - httpx - INFO - HTTP Request: POST https://api.telegram.org/bot8242076298:AAGnHplpi7Ad4hOo9z4zTugjqcCEXLJt9to/getUpdates "HTTP/1.1 200 OK"
2025-10-15 20:43:49,309 - httpx - INFO - HTTP Request: POST https://api.telegram.org/bot8242076298:AAGnHplpi7Ad4hOo9z4zTugjqcCEXLJt9to/getUpdates "HTTP/1.1 409 Conflict"
2025-10-15 20:43:49,310 - telegram.ext.Application - ERROR - No error handlers are registered, logging exception.
Traceback (most recent call last):
  File "/Library/Frameworks/Python.framework/Versions/3.13/lib/python3.13/site-packages/telegram/ext/_updater.py", line 743, in _network_loop_retry
    if not await do_action():
           ^^^^^^^^^^^^^^^^^
  File "/Library/Frameworks/Python.framework/Versions/3.13/lib/python3.13/site-packages/telegram/ext/_updater.py", line 737, in do_action
    return action_cb_task.result()
           ~~~~~~~~~~~~~~~~~~~~~^^
  File "/Library/Frameworks/Python.framework/Versions/3.13/lib/python3.13/site-packages/telegram/ext/_updater.py", line 367, in polling_action_cb
    updates = await self.bot.get_updates(
              ^^^^^^^^^^^^^^^^^^^^^^^^^^^
    ...<7 lines>...
    )
    ^
  File "/Library/Frameworks/Python.framework/Versions/3.13/lib/python3.13/site-packages/telegram/ext/_extbot.py", line 647, in get_updates
    updates = await super().get_updates(
              ^^^^^^^^^^^^^^^^^^^^^^^^^^
    ...<9 lines>...
    )
    ^
  File "/Library/Frameworks/Python.framework/Versions/3.13/lib/python3.13/site-packages/telegram/_bot.py", line 4421, in get_updates
    await self._post(
    ^^^^^^^^^^^^^^^^^
    ...<7 lines>...
    ),
    ^
  File "/Library/Frameworks/Python.framework/Versions/3.13/lib/python3.13/site-packages/telegram/_bot.py", line 617, in _post
    return await self._do_post(
           ^^^^^^^^^^^^^^^^^^^^
    ...<6 lines>...
    )
    ^
  File "/Library/Frameworks/Python.framework/Versions/3.13/lib/python3.13/site-packages/telegram/ext/_extbot.py", line 351, in _do_post
    return await super()._do_post(
           ^^^^^^^^^^^^^^^^^^^^^^^
    ...<6 lines>...
    )
    ^
  File "/Library/Frameworks/Python.framework/Versions/3.13/lib/python3.13/site-packages/telegram/_bot.py", line 646, in _do_post
    result = await request.post(
             ^^^^^^^^^^^^^^^^^^^
    ...<6 lines>...
    )
    ^
  File "/Library/Frameworks/Python.framework/Versions/3.13/lib/python3.13/site-packages/telegram/request/_baserequest.py", line 202, in post
    result = await self._request_wrapper(
             ^^^^^^^^^^^^^^^^^^^^^^^^^^^^
    ...<7 lines>...
    )
    ^
  File "/Library/Frameworks/Python.framework/Versions/3.13/lib/python3.13/site-packages/telegram/request/_baserequest.py", line 385, in _request_wrapper
    raise Conflict(message)
telegram.error.Conflict: Conflict: terminated by other getUpdates request; make sure that only one bot instance is running
2025-10-15 20:44:00,444 - httpx - INFO - HTTP Request: POST https://api.telegram.org/bot8242076298:AAGnHplpi7Ad4hOo9z4zTugjqcCEXLJt9to/getUpdates "HTTP/1.1 200 OK"
2025-10-15 20:44:10,644 - httpx - INFO - HTTP Request: POST https://api.telegram.org/bot8242076298:AAGnHplpi7Ad4hOo9z4zTugjqcCEXLJt9to/getUpdates "HTTP/1.1 200 OK"
2025-10-15 20:44:20,712 - httpx - INFO - HTTP Request: POST https://api.telegram.org/bot8242076298:AAGnHplpi7Ad4hOo9z4zTugjqcCEXLJt9to/getUpdates "HTTP/1.1 200 OK"
2025-10-15 20:44:23,810 - httpx - INFO - HTTP Request: POST https://api.telegram.org/bot8242076298:AAGnHplpi7Ad4hOo9z4zTugjqcCEXLJt9to/getUpdates "HTTP/1.1 409 Conflict"
2025-10-15 20:44:23,811 - telegram.ext.Application - ERROR - No error handlers are registered, logging exception.
Traceback (most recent call last):
  File "/Library/Frameworks/Python.framework/Versions/3.13/lib/python3.13/site-packages/telegram/ext/_updater.py", line 743, in _network_loop_retry
    if not await do_action():
           ^^^^^^^^^^^^^^^^^
  File "/Library/Frameworks/Python.framework/Versions/3.13/lib/python3.13/site-packages/telegram/ext/_updater.py", line 737, in do_action
    return action_cb_task.result()
           ~~~~~~~~~~~~~~~~~~~~~^^
  File "/Library/Frameworks/Python.framework/Versions/3.13/lib/python3.13/site-packages/telegram/ext/_updater.py", line 367, in polling_action_cb
    updates = await self.bot.get_updates(
              ^^^^^^^^^^^^^^^^^^^^^^^^^^^
    ...<7 lines>...
    )
    ^
  File "/Library/Frameworks/Python.framework/Versions/3.13/lib/python3.13/site-packages/telegram/ext/_extbot.py", line 647, in get_updates
    updates = await super().get_updates(
              ^^^^^^^^^^^^^^^^^^^^^^^^^^
    ...<9 lines>...
    )
    ^
  File "/Library/Frameworks/Python.framework/Versions/3.13/lib/python3.13/site-packages/telegram/_bot.py", line 4421, in get_updates
    await self._post(
    ^^^^^^^^^^^^^^^^^
    ...<7 lines>...
    ),
    ^
  File "/Library/Frameworks/Python.framework/Versions/3.13/lib/python3.13/site-packages/telegram/_bot.py", line 617, in _post
    return await self._do_post(
           ^^^^^^^^^^^^^^^^^^^^
    ...<6 lines>...
    )
    ^
  File "/Library/Frameworks/Python.framework/Versions/3.13/lib/python3.13/site-packages/telegram/ext/_extbot.py", line 351, in _do_post
    return await super()._do_post(
           ^^^^^^^^^^^^^^^^^^^^^^^
    ...<6 lines>...
    )
    ^
  File "/Library/Frameworks/Python.framework/Versions/3.13/lib/python3.13/site-packages/telegram/_bot.py", line 646, in _do_post
    result = await request.post(
             ^^^^^^^^^^^^^^^^^^^
    ...<6 lines>...
    )
    ^
  File "/Library/Frameworks/Python.framework/Versions/3.13/lib/python3.13/site-packages/telegram/request/_baserequest.py", line 202, in post
    result = await self._request_wrapper(
             ^^^^^^^^^^^^^^^^^^^^^^^^^^^^
    ...<7 lines>...
    )
    ^
  File "/Library/Frameworks/Python.framework/Versions/3.13/lib/python3.13/site-packages/telegram/request/_baserequest.py", line 385, in _request_wrapper
    raise Conflict(message)
telegram.error.Conflict: Conflict: terminated by other getUpdates request; make sure that only one bot instance is running
2025-10-15 20:44:34,881 - httpx - INFO - HTTP Request: POST https://api.telegram.org/bot8242076298:AAGnHplpi7Ad4hOo9z4zTugjqcCEXLJt9to/getUpdates "HTTP/1.1 200 OK"
2025-10-15 20:44:44,949 - httpx - INFO - HTTP Request: POST https://api.telegram.org/bot8242076298:AAGnHplpi7Ad4hOo9z4zTugjqcCEXLJt9to/getUpdates "HTTP/1.1 200 OK"
2025-10-15 20:44:55,018 - httpx - INFO - HTTP Request: POST https://api.telegram.org/bot8242076298:AAGnHplpi7Ad4hOo9z4zTugjqcCEXLJt9to/getUpdates "HTTP/1.1 200 OK"
2025-10-15 20:44:58,116 - httpx - INFO - HTTP Request: POST https://api.telegram.org/bot8242076298:AAGnHplpi7Ad4hOo9z4zTugjqcCEXLJt9to/getUpdates "HTTP/1.1 409 Conflict"
2025-10-15 20:44:58,117 - telegram.ext.Application - ERROR - No error handlers are registered, logging exception.
Traceback (most recent call last):
  File "/Library/Frameworks/Python.framework/Versions/3.13/lib/python3.13/site-packages/telegram/ext/_updater.py", line 743, in _network_loop_retry
    if not await do_action():
           ^^^^^^^^^^^^^^^^^
  File "/Library/Frameworks/Python.framework/Versions/3.13/lib/python3.13/site-packages/telegram/ext/_updater.py", line 737, in do_action
    return action_cb_task.result()
           ~~~~~~~~~~~~~~~~~~~~~^^
  File "/Library/Frameworks/Python.framework/Versions/3.13/lib/python3.13/site-packages/telegram/ext/_updater.py", line 367, in polling_action_cb
    updates = await self.bot.get_updates(
              ^^^^^^^^^^^^^^^^^^^^^^^^^^^
    ...<7 lines>...
    )
    ^
  File "/Library/Frameworks/Python.framework/Versions/3.13/lib/python3.13/site-packages/telegram/ext/_extbot.py", line 647, in get_updates
    updates = await super().get_updates(
              ^^^^^^^^^^^^^^^^^^^^^^^^^^
    ...<9 lines>...
    )
    ^
  File "/Library/Frameworks/Python.framework/Versions/3.13/lib/python3.13/site-packages/telegram/_bot.py", line 4421, in get_updates
    await self._post(
    ^^^^^^^^^^^^^^^^^
    ...<7 lines>...
    ),
    ^
  File "/Library/Frameworks/Python.framework/Versions/3.13/lib/python3.13/site-packages/telegram/_bot.py", line 617, in _post
    return await self._do_post(
           ^^^^^^^^^^^^^^^^^^^^
    ...<6 lines>...
    )
    ^
  File "/Library/Frameworks/Python.framework/Versions/3.13/lib/python3.13/site-packages/telegram/ext/_extbot.py", line 351, in _do_post
    return await super()._do_post(
           ^^^^^^^^^^^^^^^^^^^^^^^
    ...<6 lines>...
    )
    ^
  File "/Library/Frameworks/Python.framework/Versions/3.13/lib/python3.13/site-packages/telegram/_bot.py", line 646, in _do_post
    result = await request.post(
             ^^^^^^^^^^^^^^^^^^^
    ...<6 lines>...
    )
    ^
  File "/Library/Frameworks/Python.framework/Versions/3.13/lib/python3.13/site-packages/telegram/request/_baserequest.py", line 202, in post
    result = await self._request_wrapper(
             ^^^^^^^^^^^^^^^^^^^^^^^^^^^^
    ...<7 lines>...
    )
    ^
  File "/Library/Frameworks/Python.framework/Versions/3.13/lib/python3.13/site-packages/telegram/request/_baserequest.py", line 385, in _request_wrapper
    raise Conflict(message)
telegram.error.Conflict: Conflict: terminated by other getUpdates request; make sure that only one bot instance is running
2025-10-15 20:45:09,185 - httpx - INFO - HTTP Request: POST https://api.telegram.org/bot8242076298:AAGnHplpi7Ad4hOo9z4zTugjqcCEXLJt9to/getUpdates "HTTP/1.1 200 OK"
2025-10-15 20:45:19,252 - httpx - INFO - HTTP Request: POST https://api.telegram.org/bot8242076298:AAGnHplpi7Ad4hOo9z4zTugjqcCEXLJt9to/getUpdates "HTTP/1.1 200 OK"
2025-10-15 20:45:29,321 - httpx - INFO - HTTP Request: POST https://api.telegram.org/bot8242076298:AAGnHplpi7Ad4hOo9z4zTugjqcCEXLJt9to/getUpdates "HTTP/1.1 200 OK"
2025-10-15 20:45:32,413 - httpx - INFO - HTTP Request: POST https://api.telegram.org/bot8242076298:AAGnHplpi7Ad4hOo9z4zTugjqcCEXLJt9to/getUpdates "HTTP/1.1 409 Conflict"
2025-10-15 20:45:32,415 - telegram.ext.Application - ERROR - No error handlers are registered, logging exception.
Traceback (most recent call last):
  File "/Library/Frameworks/Python.framework/Versions/3.13/lib/python3.13/site-packages/telegram/ext/_updater.py", line 743, in _network_loop_retry
    if not await do_action():
           ^^^^^^^^^^^^^^^^^
  File "/Library/Frameworks/Python.framework/Versions/3.13/lib/python3.13/site-packages/telegram/ext/_updater.py", line 737, in do_action
    return action_cb_task.result()
           ~~~~~~~~~~~~~~~~~~~~~^^
  File "/Library/Frameworks/Python.framework/Versions/3.13/lib/python3.13/site-packages/telegram/ext/_updater.py", line 367, in polling_action_cb
    updates = await self.bot.get_updates(
              ^^^^^^^^^^^^^^^^^^^^^^^^^^^
    ...<7 lines>...
    )
    ^
  File "/Library/Frameworks/Python.framework/Versions/3.13/lib/python3.13/site-packages/telegram/ext/_extbot.py", line 647, in get_updates
    updates = await super().get_updates(
              ^^^^^^^^^^^^^^^^^^^^^^^^^^
    ...<9 lines>...
    )
    ^
  File "/Library/Frameworks/Python.framework/Versions/3.13/lib/python3.13/site-packages/telegram/_bot.py", line 4421, in get_updates
    await self._post(
    ^^^^^^^^^^^^^^^^^
    ...<7 lines>...
    ),
    ^
  File "/Library/Frameworks/Python.framework/Versions/3.13/lib/python3.13/site-packages/telegram/_bot.py", line 617, in _post
    return await self._do_post(
           ^^^^^^^^^^^^^^^^^^^^
    ...<6 lines>...
    )
    ^
  File "/Library/Frameworks/Python.framework/Versions/3.13/lib/python3.13/site-packages/telegram/ext/_extbot.py", line 351, in _do_post
    return await super()._do_post(
           ^^^^^^^^^^^^^^^^^^^^^^^
    ...<6 lines>...
    )
    ^
  File "/Library/Frameworks/Python.framework/Versions/3.13/lib/python3.13/site-packages/telegram/_bot.py", line 646, in _do_post
    result = await request.post(
             ^^^^^^^^^^^^^^^^^^^
    ...<6 lines>...
    )
    ^
  File "/Library/Frameworks/Python.framework/Versions/3.13/lib/python3.13/site-packages/telegram/request/_baserequest.py", line 202, in post
    result = await self._request_wrapper(
             ^^^^^^^^^^^^^^^^^^^^^^^^^^^^
    ...<7 lines>...
    )
    ^
  File "/Library/Frameworks/Python.framework/Versions/3.13/lib/python3.13/site-packages/telegram/request/_baserequest.py", line 385, in _request_wrapper
    raise Conflict(message)
telegram.error.Conflict: Conflict: terminated by other getUpdates request; make sure that only one bot instance is running
2025-10-15 20:45:43,499 - httpx - INFO - HTTP Request: POST https://api.telegram.org/bot8242076298:AAGnHplpi7Ad4hOo9z4zTugjqcCEXLJt9to/getUpdates "HTTP/1.1 200 OK"
2025-10-15 20:45:53,594 - httpx - INFO - HTTP Request: POST https://api.telegram.org/bot8242076298:AAGnHplpi7Ad4hOo9z4zTugjqcCEXLJt9to/getUpdates "HTTP/1.1 200 OK"
2025-10-15 20:46:03,758 - httpx - INFO - HTTP Request: POST https://api.telegram.org/bot8242076298:AAGnHplpi7Ad4hOo9z4zTugjqcCEXLJt9to/getUpdates "HTTP/1.1 200 OK"
2025-10-15 20:46:06,722 - httpx - INFO - HTTP Request: POST https://api.telegram.org/bot8242076298:AAGnHplpi7Ad4hOo9z4zTugjqcCEXLJt9to/getUpdates "HTTP/1.1 409 Conflict"
2025-10-15 20:46:06,723 - telegram.ext.Application - ERROR - No error handlers are registered, logging exception.
Traceback (most recent call last):
  File "/Library/Frameworks/Python.framework/Versions/3.13/lib/python3.13/site-packages/telegram/ext/_updater.py", line 743, in _network_loop_retry
    if not await do_action():
           ^^^^^^^^^^^^^^^^^
  File "/Library/Frameworks/Python.framework/Versions/3.13/lib/python3.13/site-packages/telegram/ext/_updater.py", line 737, in do_action
    return action_cb_task.result()
           ~~~~~~~~~~~~~~~~~~~~~^^
  File "/Library/Frameworks/Python.framework/Versions/3.13/lib/python3.13/site-packages/telegram/ext/_updater.py", line 367, in polling_action_cb
    updates = await self.bot.get_updates(
              ^^^^^^^^^^^^^^^^^^^^^^^^^^^
    ...<7 lines>...
    )
    ^
  File "/Library/Frameworks/Python.framework/Versions/3.13/lib/python3.13/site-packages/telegram/ext/_extbot.py", line 647, in get_updates
    updates = await super().get_updates(
              ^^^^^^^^^^^^^^^^^^^^^^^^^^
    ...<9 lines>...
    )
    ^
  File "/Library/Frameworks/Python.framework/Versions/3.13/lib/python3.13/site-packages/telegram/_bot.py", line 4421, in get_updates
    await self._post(
    ^^^^^^^^^^^^^^^^^
    ...<7 lines>...
    ),
    ^
  File "/Library/Frameworks/Python.framework/Versions/3.13/lib/python3.13/site-packages/telegram/_bot.py", line 617, in _post
    return await self._do_post(
           ^^^^^^^^^^^^^^^^^^^^
    ...<6 lines>...
    )
    ^
  File "/Library/Frameworks/Python.framework/Versions/3.13/lib/python3.13/site-packages/telegram/ext/_extbot.py", line 351, in _do_post
    return await super()._do_post(
           ^^^^^^^^^^^^^^^^^^^^^^^
    ...<6 lines>...
    )
    ^
  File "/Library/Frameworks/Python.framework/Versions/3.13/lib/python3.13/site-packages/telegram/_bot.py", line 646, in _do_post
    result = await request.post(
             ^^^^^^^^^^^^^^^^^^^
    ...<6 lines>...
    )
    ^
  File "/Library/Frameworks/Python.framework/Versions/3.13/lib/python3.13/site-packages/telegram/request/_baserequest.py", line 202, in post
    result = await self._request_wrapper(
             ^^^^^^^^^^^^^^^^^^^^^^^^^^^^
    ...<7 lines>...
    )
    ^
  File "/Library/Frameworks/Python.framework/Versions/3.13/lib/python3.13/site-packages/telegram/request/_baserequest.py", line 385, in _request_wrapper
    raise Conflict(message)
telegram.error.Conflict: Conflict: terminated by other getUpdates request; make sure that only one bot instance is running
2025-10-15 20:46:17,790 - httpx - INFO - HTTP Request: POST https://api.telegram.org/bot8242076298:AAGnHplpi7Ad4hOo9z4zTugjqcCEXLJt9to/getUpdates "HTTP/1.1 200 OK"
2025-10-15 20:46:27,856 - httpx - INFO - HTTP Request: POST https://api.telegram.org/bot8242076298:AAGnHplpi7Ad4hOo9z4zTugjqcCEXLJt9to/getUpdates "HTTP/1.1 200 OK"
2025-10-15 20:46:37,922 - httpx - INFO - HTTP Request: POST https://api.telegram.org/bot8242076298:AAGnHplpi7Ad4hOo9z4zTugjqcCEXLJt9to/getUpdates "HTTP/1.1 200 OK"
2025-10-15 20:46:41,004 - httpx - INFO - HTTP Request: POST https://api.telegram.org/bot8242076298:AAGnHplpi7Ad4hOo9z4zTugjqcCEXLJt9to/getUpdates "HTTP/1.1 409 Conflict"
2025-10-15 20:46:41,005 - telegram.ext.Application - ERROR - No error handlers are registered, logging exception.
Traceback (most recent call last):
  File "/Library/Frameworks/Python.framework/Versions/3.13/lib/python3.13/site-packages/telegram/ext/_updater.py", line 743, in _network_loop_retry
    if not await do_action():
           ^^^^^^^^^^^^^^^^^
  File "/Library/Frameworks/Python.framework/Versions/3.13/lib/python3.13/site-packages/telegram/ext/_updater.py", line 737, in do_action
    return action_cb_task.result()
           ~~~~~~~~~~~~~~~~~~~~~^^
  File "/Library/Frameworks/Python.framework/Versions/3.13/lib/python3.13/site-packages/telegram/ext/_updater.py", line 367, in polling_action_cb
    updates = await self.bot.get_updates(
              ^^^^^^^^^^^^^^^^^^^^^^^^^^^
    ...<7 lines>...
    )
    ^
  File "/Library/Frameworks/Python.framework/Versions/3.13/lib/python3.13/site-packages/telegram/ext/_extbot.py", line 647, in get_updates
    updates = await super().get_updates(
              ^^^^^^^^^^^^^^^^^^^^^^^^^^
    ...<9 lines>...
    )
    ^
  File "/Library/Frameworks/Python.framework/Versions/3.13/lib/python3.13/site-packages/telegram/_bot.py", line 4421, in get_updates
    await self._post(
    ^^^^^^^^^^^^^^^^^
    ...<7 lines>...
    ),
    ^
  File "/Library/Frameworks/Python.framework/Versions/3.13/lib/python3.13/site-packages/telegram/_bot.py", line 617, in _post
    return await self._do_post(
           ^^^^^^^^^^^^^^^^^^^^
    ...<6 lines>...
    )
    ^
  File "/Library/Frameworks/Python.framework/Versions/3.13/lib/python3.13/site-packages/telegram/ext/_extbot.py", line 351, in _do_post
    return await super()._do_post(
           ^^^^^^^^^^^^^^^^^^^^^^^
    ...<6 lines>...
    )
    ^
  File "/Library/Frameworks/Python.framework/Versions/3.13/lib/python3.13/site-packages/telegram/_bot.py", line 646, in _do_post
    result = await request.post(
             ^^^^^^^^^^^^^^^^^^^
    ...<6 lines>...
    )
    ^
  File "/Library/Frameworks/Python.framework/Versions/3.13/lib/python3.13/site-packages/telegram/request/_baserequest.py", line 202, in post
    result = await self._request_wrapper(
             ^^^^^^^^^^^^^^^^^^^^^^^^^^^^
    ...<7 lines>...
    )
    ^
  File "/Library/Frameworks/Python.framework/Versions/3.13/lib/python3.13/site-packages/telegram/request/_baserequest.py", line 385, in _request_wrapper
    raise Conflict(message)
telegram.error.Conflict: Conflict: terminated by other getUpdates request; make sure that only one bot instance is running
2025-10-15 20:46:52,071 - httpx - INFO - HTTP Request: POST https://api.telegram.org/bot8242076298:AAGnHplpi7Ad4hOo9z4zTugjqcCEXLJt9to/getUpdates "HTTP/1.1 200 OK"
2025-10-15 20:47:02,231 - httpx - INFO - HTTP Request: POST https://api.telegram.org/bot8242076298:AAGnHplpi7Ad4hOo9z4zTugjqcCEXLJt9to/getUpdates "HTTP/1.1 200 OK"
2025-10-15 20:47:12,299 - httpx - INFO - HTTP Request: POST https://api.telegram.org/bot8242076298:AAGnHplpi7Ad4hOo9z4zTugjqcCEXLJt9to/getUpdates "HTTP/1.1 200 OK"
2025-10-15 20:47:15,328 - httpx - INFO - HTTP Request: POST https://api.telegram.org/bot8242076298:AAGnHplpi7Ad4hOo9z4zTugjqcCEXLJt9to/getUpdates "HTTP/1.1 409 Conflict"
2025-10-15 20:47:15,330 - telegram.ext.Application - ERROR - No error handlers are registered, logging exception.
Traceback (most recent call last):
  File "/Library/Frameworks/Python.framework/Versions/3.13/lib/python3.13/site-packages/telegram/ext/_updater.py", line 743, in _network_loop_retry
    if not await do_action():
           ^^^^^^^^^^^^^^^^^
  File "/Library/Frameworks/Python.framework/Versions/3.13/lib/python3.13/site-packages/telegram/ext/_updater.py", line 737, in do_action
    return action_cb_task.result()
           ~~~~~~~~~~~~~~~~~~~~~^^
  File "/Library/Frameworks/Python.framework/Versions/3.13/lib/python3.13/site-packages/telegram/ext/_updater.py", line 367, in polling_action_cb
    updates = await self.bot.get_updates(
              ^^^^^^^^^^^^^^^^^^^^^^^^^^^
    ...<7 lines>...
    )
    ^
  File "/Library/Frameworks/Python.framework/Versions/3.13/lib/python3.13/site-packages/telegram/ext/_extbot.py", line 647, in get_updates
    updates = await super().get_updates(
              ^^^^^^^^^^^^^^^^^^^^^^^^^^
    ...<9 lines>...
    )
    ^
  File "/Library/Frameworks/Python.framework/Versions/3.13/lib/python3.13/site-packages/telegram/_bot.py", line 4421, in get_updates
    await self._post(
    ^^^^^^^^^^^^^^^^^
    ...<7 lines>...
    ),
    ^
  File "/Library/Frameworks/Python.framework/Versions/3.13/lib/python3.13/site-packages/telegram/_bot.py", line 617, in _post
    return await self._do_post(
           ^^^^^^^^^^^^^^^^^^^^
    ...<6 lines>...
    )
    ^
  File "/Library/Frameworks/Python.framework/Versions/3.13/lib/python3.13/site-packages/telegram/ext/_extbot.py", line 351, in _do_post
    return await super()._do_post(
           ^^^^^^^^^^^^^^^^^^^^^^^
    ...<6 lines>...
    )
    ^
  File "/Library/Frameworks/Python.framework/Versions/3.13/lib/python3.13/site-packages/telegram/_bot.py", line 646, in _do_post
    result = await request.post(
             ^^^^^^^^^^^^^^^^^^^
    ...<6 lines>...
    )
    ^
  File "/Library/Frameworks/Python.framework/Versions/3.13/lib/python3.13/site-packages/telegram/request/_baserequest.py", line 202, in post
    result = await self._request_wrapper(
             ^^^^^^^^^^^^^^^^^^^^^^^^^^^^
    ...<7 lines>...
    )
    ^
  File "/Library/Frameworks/Python.framework/Versions/3.13/lib/python3.13/site-packages/telegram/request/_baserequest.py", line 385, in _request_wrapper
    raise Conflict(message)
telegram.error.Conflict: Conflict: terminated by other getUpdates request; make sure that only one bot instance is running
2025-10-15 20:47:26,400 - httpx - INFO - HTTP Request: POST https://api.telegram.org/bot8242076298:AAGnHplpi7Ad4hOo9z4zTugjqcCEXLJt9to/getUpdates "HTTP/1.1 200 OK"
2025-10-15 20:47:36,467 - httpx - INFO - HTTP Request: POST https://api.telegram.org/bot8242076298:AAGnHplpi7Ad4hOo9z4zTugjqcCEXLJt9to/getUpdates "HTTP/1.1 200 OK"
2025-10-15 20:47:46,533 - httpx - INFO - HTTP Request: POST https://api.telegram.org/bot8242076298:AAGnHplpi7Ad4hOo9z4zTugjqcCEXLJt9to/getUpdates "HTTP/1.1 200 OK"
2025-10-15 20:47:49,611 - httpx - INFO - HTTP Request: POST https://api.telegram.org/bot8242076298:AAGnHplpi7Ad4hOo9z4zTugjqcCEXLJt9to/getUpdates "HTTP/1.1 409 Conflict"
2025-10-15 20:47:49,612 - telegram.ext.Application - ERROR - No error handlers are registered, logging exception.
Traceback (most recent call last):
  File "/Library/Frameworks/Python.framework/Versions/3.13/lib/python3.13/site-packages/telegram/ext/_updater.py", line 743, in _network_loop_retry
    if not await do_action():
           ^^^^^^^^^^^^^^^^^
  File "/Library/Frameworks/Python.framework/Versions/3.13/lib/python3.13/site-packages/telegram/ext/_updater.py", line 737, in do_action
    return action_cb_task.result()
           ~~~~~~~~~~~~~~~~~~~~~^^
  File "/Library/Frameworks/Python.framework/Versions/3.13/lib/python3.13/site-packages/telegram/ext/_updater.py", line 367, in polling_action_cb
    updates = await self.bot.get_updates(
              ^^^^^^^^^^^^^^^^^^^^^^^^^^^
    ...<7 lines>...
    )
    ^
  File "/Library/Frameworks/Python.framework/Versions/3.13/lib/python3.13/site-packages/telegram/ext/_extbot.py", line 647, in get_updates
    updates = await super().get_updates(
              ^^^^^^^^^^^^^^^^^^^^^^^^^^
    ...<9 lines>...
    )
    ^
  File "/Library/Frameworks/Python.framework/Versions/3.13/lib/python3.13/site-packages/telegram/_bot.py", line 4421, in get_updates
    await self._post(
    ^^^^^^^^^^^^^^^^^
    ...<7 lines>...
    ),
    ^
  File "/Library/Frameworks/Python.framework/Versions/3.13/lib/python3.13/site-packages/telegram/_bot.py", line 617, in _post
    return await self._do_post(
           ^^^^^^^^^^^^^^^^^^^^
    ...<6 lines>...
    )
    ^
  File "/Library/Frameworks/Python.framework/Versions/3.13/lib/python3.13/site-packages/telegram/ext/_extbot.py", line 351, in _do_post
    return await super()._do_post(
           ^^^^^^^^^^^^^^^^^^^^^^^
    ...<6 lines>...
    )
    ^
  File "/Library/Frameworks/Python.framework/Versions/3.13/lib/python3.13/site-packages/telegram/_bot.py", line 646, in _do_post
    result = await request.post(
             ^^^^^^^^^^^^^^^^^^^
    ...<6 lines>...
    )
    ^
  File "/Library/Frameworks/Python.framework/Versions/3.13/lib/python3.13/site-packages/telegram/request/_baserequest.py", line 202, in post
    result = await self._request_wrapper(
             ^^^^^^^^^^^^^^^^^^^^^^^^^^^^
    ...<7 lines>...
    )
    ^
  File "/Library/Frameworks/Python.framework/Versions/3.13/lib/python3.13/site-packages/telegram/request/_baserequest.py", line 385, in _request_wrapper
    raise Conflict(message)
telegram.error.Conflict: Conflict: terminated by other getUpdates request; make sure that only one bot instance is running
2025-10-15 20:48:00,701 - httpx - INFO - HTTP Request: POST https://api.telegram.org/bot8242076298:AAGnHplpi7Ad4hOo9z4zTugjqcCEXLJt9to/getUpdates "HTTP/1.1 200 OK"
2025-10-15 20:48:10,770 - httpx - INFO - HTTP Request: POST https://api.telegram.org/bot8242076298:AAGnHplpi7Ad4hOo9z4zTugjqcCEXLJt9to/getUpdates "HTTP/1.1 200 OK"
2025-10-15 20:48:20,836 - httpx - INFO - HTTP Request: POST https://api.telegram.org/bot8242076298:AAGnHplpi7Ad4hOo9z4zTugjqcCEXLJt9to/getUpdates "HTTP/1.1 200 OK"
2025-10-15 20:48:23,903 - httpx - INFO - HTTP Request: POST https://api.telegram.org/bot8242076298:AAGnHplpi7Ad4hOo9z4zTugjqcCEXLJt9to/getUpdates "HTTP/1.1 409 Conflict"
2025-10-15 20:48:23,904 - telegram.ext.Application - ERROR - No error handlers are registered, logging exception.
Traceback (most recent call last):
  File "/Library/Frameworks/Python.framework/Versions/3.13/lib/python3.13/site-packages/telegram/ext/_updater.py", line 743, in _network_loop_retry
    if not await do_action():
           ^^^^^^^^^^^^^^^^^
  File "/Library/Frameworks/Python.framework/Versions/3.13/lib/python3.13/site-packages/telegram/ext/_updater.py", line 737, in do_action
    return action_cb_task.result()
           ~~~~~~~~~~~~~~~~~~~~~^^
  File "/Library/Frameworks/Python.framework/Versions/3.13/lib/python3.13/site-packages/telegram/ext/_updater.py", line 367, in polling_action_cb
    updates = await self.bot.get_updates(
              ^^^^^^^^^^^^^^^^^^^^^^^^^^^
    ...<7 lines>...
    )
    ^
  File "/Library/Frameworks/Python.framework/Versions/3.13/lib/python3.13/site-packages/telegram/ext/_extbot.py", line 647, in get_updates
    updates = await super().get_updates(
              ^^^^^^^^^^^^^^^^^^^^^^^^^^
    ...<9 lines>...
    )
    ^
  File "/Library/Frameworks/Python.framework/Versions/3.13/lib/python3.13/site-packages/telegram/_bot.py", line 4421, in get_updates
    await self._post(
    ^^^^^^^^^^^^^^^^^
    ...<7 lines>...
    ),
    ^
  File "/Library/Frameworks/Python.framework/Versions/3.13/lib/python3.13/site-packages/telegram/_bot.py", line 617, in _post
    return await self._do_post(
           ^^^^^^^^^^^^^^^^^^^^
    ...<6 lines>...
    )
    ^
  File "/Library/Frameworks/Python.framework/Versions/3.13/lib/python3.13/site-packages/telegram/ext/_extbot.py", line 351, in _do_post
    return await super()._do_post(
           ^^^^^^^^^^^^^^^^^^^^^^^
    ...<6 lines>...
    )
    ^
  File "/Library/Frameworks/Python.framework/Versions/3.13/lib/python3.13/site-packages/telegram/_bot.py", line 646, in _do_post
    result = await request.post(
             ^^^^^^^^^^^^^^^^^^^
    ...<6 lines>...
    )
    ^
  File "/Library/Frameworks/Python.framework/Versions/3.13/lib/python3.13/site-packages/telegram/request/_baserequest.py", line 202, in post
    result = await self._request_wrapper(
             ^^^^^^^^^^^^^^^^^^^^^^^^^^^^
    ...<7 lines>...
    )
    ^
  File "/Library/Frameworks/Python.framework/Versions/3.13/lib/python3.13/site-packages/telegram/request/_baserequest.py", line 385, in _request_wrapper
    raise Conflict(message)
telegram.error.Conflict: Conflict: terminated by other getUpdates request; make sure that only one bot instance is running
2025-10-15 20:48:34,984 - httpx - INFO - HTTP Request: POST https://api.telegram.org/bot8242076298:AAGnHplpi7Ad4hOo9z4zTugjqcCEXLJt9to/getUpdates "HTTP/1.1 200 OK"
2025-10-15 20:48:45,144 - httpx - INFO - HTTP Request: POST https://api.telegram.org/bot8242076298:AAGnHplpi7Ad4hOo9z4zTugjqcCEXLJt9to/getUpdates "HTTP/1.1 200 OK"
2025-10-15 20:48:55,211 - httpx - INFO - HTTP Request: POST https://api.telegram.org/bot8242076298:AAGnHplpi7Ad4hOo9z4zTugjqcCEXLJt9to/getUpdates "HTTP/1.1 200 OK"
2025-10-15 20:48:58,188 - httpx - INFO - HTTP Request: POST https://api.telegram.org/bot8242076298:AAGnHplpi7Ad4hOo9z4zTugjqcCEXLJt9to/getUpdates "HTTP/1.1 409 Conflict"
2025-10-15 20:48:58,189 - telegram.ext.Application - ERROR - No error handlers are registered, logging exception.
Traceback (most recent call last):
  File "/Library/Frameworks/Python.framework/Versions/3.13/lib/python3.13/site-packages/telegram/ext/_updater.py", line 743, in _network_loop_retry
    if not await do_action():
           ^^^^^^^^^^^^^^^^^
  File "/Library/Frameworks/Python.framework/Versions/3.13/lib/python3.13/site-packages/telegram/ext/_updater.py", line 737, in do_action
    return action_cb_task.result()
           ~~~~~~~~~~~~~~~~~~~~~^^
  File "/Library/Frameworks/Python.framework/Versions/3.13/lib/python3.13/site-packages/telegram/ext/_updater.py", line 367, in polling_action_cb
    updates = await self.bot.get_updates(
              ^^^^^^^^^^^^^^^^^^^^^^^^^^^
    ...<7 lines>...
    )
    ^
  File "/Library/Frameworks/Python.framework/Versions/3.13/lib/python3.13/site-packages/telegram/ext/_extbot.py", line 647, in get_updates
    updates = await super().get_updates(
              ^^^^^^^^^^^^^^^^^^^^^^^^^^
    ...<9 lines>...
    )
    ^
  File "/Library/Frameworks/Python.framework/Versions/3.13/lib/python3.13/site-packages/telegram/_bot.py", line 4421, in get_updates
    await self._post(
    ^^^^^^^^^^^^^^^^^
    ...<7 lines>...
    ),
    ^
  File "/Library/Frameworks/Python.framework/Versions/3.13/lib/python3.13/site-packages/telegram/_bot.py", line 617, in _post
    return await self._do_post(
           ^^^^^^^^^^^^^^^^^^^^
    ...<6 lines>...
    )
    ^
  File "/Library/Frameworks/Python.framework/Versions/3.13/lib/python3.13/site-packages/telegram/ext/_extbot.py", line 351, in _do_post
    return await super()._do_post(
           ^^^^^^^^^^^^^^^^^^^^^^^
    ...<6 lines>...
    )
    ^
  File "/Library/Frameworks/Python.framework/Versions/3.13/lib/python3.13/site-packages/telegram/_bot.py", line 646, in _do_post
    result = await request.post(
             ^^^^^^^^^^^^^^^^^^^
    ...<6 lines>...
    )
    ^
  File "/Library/Frameworks/Python.framework/Versions/3.13/lib/python3.13/site-packages/telegram/request/_baserequest.py", line 202, in post
    result = await self._request_wrapper(
             ^^^^^^^^^^^^^^^^^^^^^^^^^^^^
    ...<7 lines>...
    )
    ^
  File "/Library/Frameworks/Python.framework/Versions/3.13/lib/python3.13/site-packages/telegram/request/_baserequest.py", line 385, in _request_wrapper
    raise Conflict(message)
telegram.error.Conflict: Conflict: terminated by other getUpdates request; make sure that only one bot instance is running
2025-10-15 20:49:09,311 - httpx - INFO - HTTP Request: POST https://api.telegram.org/bot8242076298:AAGnHplpi7Ad4hOo9z4zTugjqcCEXLJt9to/getUpdates "HTTP/1.1 200 OK"
2025-10-15 20:49:19,379 - httpx - INFO - HTTP Request: POST https://api.telegram.org/bot8242076298:AAGnHplpi7Ad4hOo9z4zTugjqcCEXLJt9to/getUpdates "HTTP/1.1 200 OK"
2025-10-15 20:49:29,445 - httpx - INFO - HTTP Request: POST https://api.telegram.org/bot8242076298:AAGnHplpi7Ad4hOo9z4zTugjqcCEXLJt9to/getUpdates "HTTP/1.1 200 OK"
2025-10-15 20:49:32,558 - httpx - INFO - HTTP Request: POST https://api.telegram.org/bot8242076298:AAGnHplpi7Ad4hOo9z4zTugjqcCEXLJt9to/getUpdates "HTTP/1.1 409 Conflict"
2025-10-15 20:49:32,560 - telegram.ext.Application - ERROR - No error handlers are registered, logging exception.
Traceback (most recent call last):
  File "/Library/Frameworks/Python.framework/Versions/3.13/lib/python3.13/site-packages/telegram/ext/_updater.py", line 743, in _network_loop_retry
    if not await do_action():
           ^^^^^^^^^^^^^^^^^
  File "/Library/Frameworks/Python.framework/Versions/3.13/lib/python3.13/site-packages/telegram/ext/_updater.py", line 737, in do_action
    return action_cb_task.result()
           ~~~~~~~~~~~~~~~~~~~~~^^
  File "/Library/Frameworks/Python.framework/Versions/3.13/lib/python3.13/site-packages/telegram/ext/_updater.py", line 367, in polling_action_cb
    updates = await self.bot.get_updates(
              ^^^^^^^^^^^^^^^^^^^^^^^^^^^
    ...<7 lines>...
    )
    ^
  File "/Library/Frameworks/Python.framework/Versions/3.13/lib/python3.13/site-packages/telegram/ext/_extbot.py", line 647, in get_updates
    updates = await super().get_updates(
              ^^^^^^^^^^^^^^^^^^^^^^^^^^
    ...<9 lines>...
    )
    ^
  File "/Library/Frameworks/Python.framework/Versions/3.13/lib/python3.13/site-packages/telegram/_bot.py", line 4421, in get_updates
    await self._post(
    ^^^^^^^^^^^^^^^^^
    ...<7 lines>...
    ),
    ^
  File "/Library/Frameworks/Python.framework/Versions/3.13/lib/python3.13/site-packages/telegram/_bot.py", line 617, in _post
    return await self._do_post(
           ^^^^^^^^^^^^^^^^^^^^
    ...<6 lines>...
    )
    ^
  File "/Library/Frameworks/Python.framework/Versions/3.13/lib/python3.13/site-packages/telegram/ext/_extbot.py", line 351, in _do_post
    return await super()._do_post(
           ^^^^^^^^^^^^^^^^^^^^^^^
    ...<6 lines>...
    )
    ^
  File "/Library/Frameworks/Python.framework/Versions/3.13/lib/python3.13/site-packages/telegram/_bot.py", line 646, in _do_post
    result = await request.post(
             ^^^^^^^^^^^^^^^^^^^
    ...<6 lines>...
    )
    ^
  File "/Library/Frameworks/Python.framework/Versions/3.13/lib/python3.13/site-packages/telegram/request/_baserequest.py", line 202, in post
    result = await self._request_wrapper(
             ^^^^^^^^^^^^^^^^^^^^^^^^^^^^
    ...<7 lines>...
    )
    ^
  File "/Library/Frameworks/Python.framework/Versions/3.13/lib/python3.13/site-packages/telegram/request/_baserequest.py", line 385, in _request_wrapper
    raise Conflict(message)
telegram.error.Conflict: Conflict: terminated by other getUpdates request; make sure that only one bot instance is running
2025-10-15 20:49:43,695 - httpx - INFO - HTTP Request: POST https://api.telegram.org/bot8242076298:AAGnHplpi7Ad4hOo9z4zTugjqcCEXLJt9to/getUpdates "HTTP/1.1 200 OK"
2025-10-15 20:49:53,761 - httpx - INFO - HTTP Request: POST https://api.telegram.org/bot8242076298:AAGnHplpi7Ad4hOo9z4zTugjqcCEXLJt9to/getUpdates "HTTP/1.1 200 OK"
2025-10-15 20:50:03,891 - httpx - INFO - HTTP Request: POST https://api.telegram.org/bot8242076298:AAGnHplpi7Ad4hOo9z4zTugjqcCEXLJt9to/getUpdates "HTTP/1.1 200 OK"
2025-10-15 20:50:06,840 - httpx - INFO - HTTP Request: POST https://api.telegram.org/bot8242076298:AAGnHplpi7Ad4hOo9z4zTugjqcCEXLJt9to/getUpdates "HTTP/1.1 409 Conflict"
2025-10-15 20:50:06,841 - telegram.ext.Application - ERROR - No error handlers are registered, logging exception.
Traceback (most recent call last):
  File "/Library/Frameworks/Python.framework/Versions/3.13/lib/python3.13/site-packages/telegram/ext/_updater.py", line 743, in _network_loop_retry
    if not await do_action():
           ^^^^^^^^^^^^^^^^^
  File "/Library/Frameworks/Python.framework/Versions/3.13/lib/python3.13/site-packages/telegram/ext/_updater.py", line 737, in do_action
    return action_cb_task.result()
           ~~~~~~~~~~~~~~~~~~~~~^^
  File "/Library/Frameworks/Python.framework/Versions/3.13/lib/python3.13/site-packages/telegram/ext/_updater.py", line 367, in polling_action_cb
    updates = await self.bot.get_updates(
              ^^^^^^^^^^^^^^^^^^^^^^^^^^^
    ...<7 lines>...
    )
    ^
  File "/Library/Frameworks/Python.framework/Versions/3.13/lib/python3.13/site-packages/telegram/ext/_extbot.py", line 647, in get_updates
    updates = await super().get_updates(
              ^^^^^^^^^^^^^^^^^^^^^^^^^^
    ...<9 lines>...
    )
    ^
  File "/Library/Frameworks/Python.framework/Versions/3.13/lib/python3.13/site-packages/telegram/_bot.py", line 4421, in get_updates
    await self._post(
    ^^^^^^^^^^^^^^^^^
    ...<7 lines>...
    ),
    ^
  File "/Library/Frameworks/Python.framework/Versions/3.13/lib/python3.13/site-packages/telegram/_bot.py", line 617, in _post
    return await self._do_post(
           ^^^^^^^^^^^^^^^^^^^^
    ...<6 lines>...
    )
    ^
  File "/Library/Frameworks/Python.framework/Versions/3.13/lib/python3.13/site-packages/telegram/ext/_extbot.py", line 351, in _do_post
    return await super()._do_post(
           ^^^^^^^^^^^^^^^^^^^^^^^
    ...<6 lines>...
    )
    ^
  File "/Library/Frameworks/Python.framework/Versions/3.13/lib/python3.13/site-packages/telegram/_bot.py", line 646, in _do_post
    result = await request.post(
             ^^^^^^^^^^^^^^^^^^^
    ...<6 lines>...
    )
    ^
  File "/Library/Frameworks/Python.framework/Versions/3.13/lib/python3.13/site-packages/telegram/request/_baserequest.py", line 202, in post
    result = await self._request_wrapper(
             ^^^^^^^^^^^^^^^^^^^^^^^^^^^^
    ...<7 lines>...
    )
    ^
  File "/Library/Frameworks/Python.framework/Versions/3.13/lib/python3.13/site-packages/telegram/request/_baserequest.py", line 385, in _request_wrapper
    raise Conflict(message)
telegram.error.Conflict: Conflict: terminated by other getUpdates request; make sure that only one bot instance is running
2025-10-15 20:50:17,920 - httpx - INFO - HTTP Request: POST https://api.telegram.org/bot8242076298:AAGnHplpi7Ad4hOo9z4zTugjqcCEXLJt9to/getUpdates "HTTP/1.1 200 OK"
2025-10-15 20:50:27,992 - httpx - INFO - HTTP Request: POST https://api.telegram.org/bot8242076298:AAGnHplpi7Ad4hOo9z4zTugjqcCEXLJt9to/getUpdates "HTTP/1.1 200 OK"
2025-10-15 20:50:38,095 - httpx - INFO - HTTP Request: POST https://api.telegram.org/bot8242076298:AAGnHplpi7Ad4hOo9z4zTugjqcCEXLJt9to/getUpdates "HTTP/1.1 200 OK"
2025-10-15 20:50:41,132 - httpx - INFO - HTTP Request: POST https://api.telegram.org/bot8242076298:AAGnHplpi7Ad4hOo9z4zTugjqcCEXLJt9to/getUpdates "HTTP/1.1 409 Conflict"
2025-10-15 20:50:41,133 - telegram.ext.Application - ERROR - No error handlers are registered, logging exception.
Traceback (most recent call last):
  File "/Library/Frameworks/Python.framework/Versions/3.13/lib/python3.13/site-packages/telegram/ext/_updater.py", line 743, in _network_loop_retry
    if not await do_action():
           ^^^^^^^^^^^^^^^^^
  File "/Library/Frameworks/Python.framework/Versions/3.13/lib/python3.13/site-packages/telegram/ext/_updater.py", line 737, in do_action
    return action_cb_task.result()
           ~~~~~~~~~~~~~~~~~~~~~^^
  File "/Library/Frameworks/Python.framework/Versions/3.13/lib/python3.13/site-packages/telegram/ext/_updater.py", line 367, in polling_action_cb
    updates = await self.bot.get_updates(
              ^^^^^^^^^^^^^^^^^^^^^^^^^^^
    ...<7 lines>...
    )
    ^
  File "/Library/Frameworks/Python.framework/Versions/3.13/lib/python3.13/site-packages/telegram/ext/_extbot.py", line 647, in get_updates
    updates = await super().get_updates(
              ^^^^^^^^^^^^^^^^^^^^^^^^^^
    ...<9 lines>...
    )
    ^
  File "/Library/Frameworks/Python.framework/Versions/3.13/lib/python3.13/site-packages/telegram/_bot.py", line 4421, in get_updates
    await self._post(
    ^^^^^^^^^^^^^^^^^
    ...<7 lines>...
    ),
    ^
  File "/Library/Frameworks/Python.framework/Versions/3.13/lib/python3.13/site-packages/telegram/_bot.py", line 617, in _post
    return await self._do_post(
           ^^^^^^^^^^^^^^^^^^^^
    ...<6 lines>...
    )
    ^
  File "/Library/Frameworks/Python.framework/Versions/3.13/lib/python3.13/site-packages/telegram/ext/_extbot.py", line 351, in _do_post
    return await super()._do_post(
           ^^^^^^^^^^^^^^^^^^^^^^^
    ...<6 lines>...
    )
    ^
  File "/Library/Frameworks/Python.framework/Versions/3.13/lib/python3.13/site-packages/telegram/_bot.py", line 646, in _do_post
    result = await request.post(
             ^^^^^^^^^^^^^^^^^^^
    ...<6 lines>...
    )
    ^
  File "/Library/Frameworks/Python.framework/Versions/3.13/lib/python3.13/site-packages/telegram/request/_baserequest.py", line 202, in post
    result = await self._request_wrapper(
             ^^^^^^^^^^^^^^^^^^^^^^^^^^^^
    ...<7 lines>...
    )
    ^
  File "/Library/Frameworks/Python.framework/Versions/3.13/lib/python3.13/site-packages/telegram/request/_baserequest.py", line 385, in _request_wrapper
    raise Conflict(message)
telegram.error.Conflict: Conflict: terminated by other getUpdates request; make sure that only one bot instance is running
2025-10-15 20:50:52,227 - httpx - INFO - HTTP Request: POST https://api.telegram.org/bot8242076298:AAGnHplpi7Ad4hOo9z4zTugjqcCEXLJt9to/getUpdates "HTTP/1.1 200 OK"
2025-10-15 20:51:02,364 - httpx - INFO - HTTP Request: POST https://api.telegram.org/bot8242076298:AAGnHplpi7Ad4hOo9z4zTugjqcCEXLJt9to/getUpdates "HTTP/1.1 200 OK"
2025-10-15 20:51:12,501 - httpx - INFO - HTTP Request: POST https://api.telegram.org/bot8242076298:AAGnHplpi7Ad4hOo9z4zTugjqcCEXLJt9to/getUpdates "HTTP/1.1 200 OK"
2025-10-15 20:51:15,472 - httpx - INFO - HTTP Request: POST https://api.telegram.org/bot8242076298:AAGnHplpi7Ad4hOo9z4zTugjqcCEXLJt9to/getUpdates "HTTP/1.1 409 Conflict"
2025-10-15 20:51:15,474 - telegram.ext.Application - ERROR - No error handlers are registered, logging exception.
Traceback (most recent call last):
  File "/Library/Frameworks/Python.framework/Versions/3.13/lib/python3.13/site-packages/telegram/ext/_updater.py", line 743, in _network_loop_retry
    if not await do_action():
           ^^^^^^^^^^^^^^^^^
  File "/Library/Frameworks/Python.framework/Versions/3.13/lib/python3.13/site-packages/telegram/ext/_updater.py", line 737, in do_action
    return action_cb_task.result()
           ~~~~~~~~~~~~~~~~~~~~~^^
  File "/Library/Frameworks/Python.framework/Versions/3.13/lib/python3.13/site-packages/telegram/ext/_updater.py", line 367, in polling_action_cb
    updates = await self.bot.get_updates(
              ^^^^^^^^^^^^^^^^^^^^^^^^^^^
    ...<7 lines>...
    )
    ^
  File "/Library/Frameworks/Python.framework/Versions/3.13/lib/python3.13/site-packages/telegram/ext/_extbot.py", line 647, in get_updates
    updates = await super().get_updates(
              ^^^^^^^^^^^^^^^^^^^^^^^^^^
    ...<9 lines>...
    )
    ^
  File "/Library/Frameworks/Python.framework/Versions/3.13/lib/python3.13/site-packages/telegram/_bot.py", line 4421, in get_updates
    await self._post(
    ^^^^^^^^^^^^^^^^^
    ...<7 lines>...
    ),
    ^
  File "/Library/Frameworks/Python.framework/Versions/3.13/lib/python3.13/site-packages/telegram/_bot.py", line 617, in _post
    return await self._do_post(
           ^^^^^^^^^^^^^^^^^^^^
    ...<6 lines>...
    )
    ^
  File "/Library/Frameworks/Python.framework/Versions/3.13/lib/python3.13/site-packages/telegram/ext/_extbot.py", line 351, in _do_post
    return await super()._do_post(
           ^^^^^^^^^^^^^^^^^^^^^^^
    ...<6 lines>...
    )
    ^
  File "/Library/Frameworks/Python.framework/Versions/3.13/lib/python3.13/site-packages/telegram/_bot.py", line 646, in _do_post
    result = await request.post(
             ^^^^^^^^^^^^^^^^^^^
    ...<6 lines>...
    )
    ^
  File "/Library/Frameworks/Python.framework/Versions/3.13/lib/python3.13/site-packages/telegram/request/_baserequest.py", line 202, in post
    result = await self._request_wrapper(
             ^^^^^^^^^^^^^^^^^^^^^^^^^^^^
    ...<7 lines>...
    )
    ^
  File "/Library/Frameworks/Python.framework/Versions/3.13/lib/python3.13/site-packages/telegram/request/_baserequest.py", line 385, in _request_wrapper
    raise Conflict(message)
telegram.error.Conflict: Conflict: terminated by other getUpdates request; make sure that only one bot instance is running
2025-10-15 20:51:26,563 - httpx - INFO - HTTP Request: POST https://api.telegram.org/bot8242076298:AAGnHplpi7Ad4hOo9z4zTugjqcCEXLJt9to/getUpdates "HTTP/1.1 200 OK"
2025-10-15 20:51:36,670 - httpx - INFO - HTTP Request: POST https://api.telegram.org/bot8242076298:AAGnHplpi7Ad4hOo9z4zTugjqcCEXLJt9to/getUpdates "HTTP/1.1 200 OK"
2025-10-15 20:51:46,755 - httpx - INFO - HTTP Request: POST https://api.telegram.org/bot8242076298:AAGnHplpi7Ad4hOo9z4zTugjqcCEXLJt9to/getUpdates "HTTP/1.1 200 OK"
2025-10-15 20:51:49,749 - httpx - INFO - HTTP Request: POST https://api.telegram.org/bot8242076298:AAGnHplpi7Ad4hOo9z4zTugjqcCEXLJt9to/getUpdates "HTTP/1.1 409 Conflict"
2025-10-15 20:51:49,751 - telegram.ext.Application - ERROR - No error handlers are registered, logging exception.
Traceback (most recent call last):
  File "/Library/Frameworks/Python.framework/Versions/3.13/lib/python3.13/site-packages/telegram/ext/_updater.py", line 743, in _network_loop_retry
    if not await do_action():
           ^^^^^^^^^^^^^^^^^
  File "/Library/Frameworks/Python.framework/Versions/3.13/lib/python3.13/site-packages/telegram/ext/_updater.py", line 737, in do_action
    return action_cb_task.result()
           ~~~~~~~~~~~~~~~~~~~~~^^
  File "/Library/Frameworks/Python.framework/Versions/3.13/lib/python3.13/site-packages/telegram/ext/_updater.py", line 367, in polling_action_cb
    updates = await self.bot.get_updates(
              ^^^^^^^^^^^^^^^^^^^^^^^^^^^
    ...<7 lines>...
    )
    ^
  File "/Library/Frameworks/Python.framework/Versions/3.13/lib/python3.13/site-packages/telegram/ext/_extbot.py", line 647, in get_updates
    updates = await super().get_updates(
              ^^^^^^^^^^^^^^^^^^^^^^^^^^
    ...<9 lines>...
    )
    ^
  File "/Library/Frameworks/Python.framework/Versions/3.13/lib/python3.13/site-packages/telegram/_bot.py", line 4421, in get_updates
    await self._post(
    ^^^^^^^^^^^^^^^^^
    ...<7 lines>...
    ),
    ^
  File "/Library/Frameworks/Python.framework/Versions/3.13/lib/python3.13/site-packages/telegram/_bot.py", line 617, in _post
    return await self._do_post(
           ^^^^^^^^^^^^^^^^^^^^
    ...<6 lines>...
    )
    ^
  File "/Library/Frameworks/Python.framework/Versions/3.13/lib/python3.13/site-packages/telegram/ext/_extbot.py", line 351, in _do_post
    return await super()._do_post(
           ^^^^^^^^^^^^^^^^^^^^^^^
    ...<6 lines>...
    )
    ^
  File "/Library/Frameworks/Python.framework/Versions/3.13/lib/python3.13/site-packages/telegram/_bot.py", line 646, in _do_post
    result = await request.post(
             ^^^^^^^^^^^^^^^^^^^
    ...<6 lines>...
    )
    ^
  File "/Library/Frameworks/Python.framework/Versions/3.13/lib/python3.13/site-packages/telegram/request/_baserequest.py", line 202, in post
    result = await self._request_wrapper(
             ^^^^^^^^^^^^^^^^^^^^^^^^^^^^
    ...<7 lines>...
    )
    ^
  File "/Library/Frameworks/Python.framework/Versions/3.13/lib/python3.13/site-packages/telegram/request/_baserequest.py", line 385, in _request_wrapper
    raise Conflict(message)
telegram.error.Conflict: Conflict: terminated by other getUpdates request; make sure that only one bot instance is running
2025-10-15 20:52:00,820 - httpx - INFO - HTTP Request: POST https://api.telegram.org/bot8242076298:AAGnHplpi7Ad4hOo9z4zTugjqcCEXLJt9to/getUpdates "HTTP/1.1 200 OK"
2025-10-15 20:52:10,901 - httpx - INFO - HTTP Request: POST https://api.telegram.org/bot8242076298:AAGnHplpi7Ad4hOo9z4zTugjqcCEXLJt9to/getUpdates "HTTP/1.1 200 OK"
2025-10-15 20:52:20,969 - httpx - INFO - HTTP Request: POST https://api.telegram.org/bot8242076298:AAGnHplpi7Ad4hOo9z4zTugjqcCEXLJt9to/getUpdates "HTTP/1.1 200 OK"
2025-10-15 20:52:24,028 - httpx - INFO - HTTP Request: POST https://api.telegram.org/bot8242076298:AAGnHplpi7Ad4hOo9z4zTugjqcCEXLJt9to/getUpdates "HTTP/1.1 409 Conflict"
2025-10-15 20:52:24,029 - telegram.ext.Application - ERROR - No error handlers are registered, logging exception.
Traceback (most recent call last):
  File "/Library/Frameworks/Python.framework/Versions/3.13/lib/python3.13/site-packages/telegram/ext/_updater.py", line 743, in _network_loop_retry
    if not await do_action():
           ^^^^^^^^^^^^^^^^^
  File "/Library/Frameworks/Python.framework/Versions/3.13/lib/python3.13/site-packages/telegram/ext/_updater.py", line 737, in do_action
    return action_cb_task.result()
           ~~~~~~~~~~~~~~~~~~~~~^^
  File "/Library/Frameworks/Python.framework/Versions/3.13/lib/python3.13/site-packages/telegram/ext/_updater.py", line 367, in polling_action_cb
    updates = await self.bot.get_updates(
              ^^^^^^^^^^^^^^^^^^^^^^^^^^^
    ...<7 lines>...
    )
    ^
  File "/Library/Frameworks/Python.framework/Versions/3.13/lib/python3.13/site-packages/telegram/ext/_extbot.py", line 647, in get_updates
    updates = await super().get_updates(
              ^^^^^^^^^^^^^^^^^^^^^^^^^^
    ...<9 lines>...
    )
    ^
  File "/Library/Frameworks/Python.framework/Versions/3.13/lib/python3.13/site-packages/telegram/_bot.py", line 4421, in get_updates
    await self._post(
    ^^^^^^^^^^^^^^^^^
    ...<7 lines>...
    ),
    ^
  File "/Library/Frameworks/Python.framework/Versions/3.13/lib/python3.13/site-packages/telegram/_bot.py", line 617, in _post
    return await self._do_post(
           ^^^^^^^^^^^^^^^^^^^^
    ...<6 lines>...
    )
    ^
  File "/Library/Frameworks/Python.framework/Versions/3.13/lib/python3.13/site-packages/telegram/ext/_extbot.py", line 351, in _do_post
    return await super()._do_post(
           ^^^^^^^^^^^^^^^^^^^^^^^
    ...<6 lines>...
    )
    ^
  File "/Library/Frameworks/Python.framework/Versions/3.13/lib/python3.13/site-packages/telegram/_bot.py", line 646, in _do_post
    result = await request.post(
             ^^^^^^^^^^^^^^^^^^^
    ...<6 lines>...
    )
    ^
  File "/Library/Frameworks/Python.framework/Versions/3.13/lib/python3.13/site-packages/telegram/request/_baserequest.py", line 202, in post
    result = await self._request_wrapper(
             ^^^^^^^^^^^^^^^^^^^^^^^^^^^^
    ...<7 lines>...
    )
    ^
  File "/Library/Frameworks/Python.framework/Versions/3.13/lib/python3.13/site-packages/telegram/request/_baserequest.py", line 385, in _request_wrapper
    raise Conflict(message)
telegram.error.Conflict: Conflict: terminated by other getUpdates request; make sure that only one bot instance is running
2025-10-15 20:52:35,100 - httpx - INFO - HTTP Request: POST https://api.telegram.org/bot8242076298:AAGnHplpi7Ad4hOo9z4zTugjqcCEXLJt9to/getUpdates "HTTP/1.1 200 OK"
2025-10-15 20:52:45,175 - httpx - INFO - HTTP Request: POST https://api.telegram.org/bot8242076298:AAGnHplpi7Ad4hOo9z4zTugjqcCEXLJt9to/getUpdates "HTTP/1.1 200 OK"
2025-10-15 20:52:55,313 - httpx - INFO - HTTP Request: POST https://api.telegram.org/bot8242076298:AAGnHplpi7Ad4hOo9z4zTugjqcCEXLJt9to/getUpdates "HTTP/1.1 200 OK"
2025-10-15 20:52:58,318 - httpx - INFO - HTTP Request: POST https://api.telegram.org/bot8242076298:AAGnHplpi7Ad4hOo9z4zTugjqcCEXLJt9to/getUpdates "HTTP/1.1 409 Conflict"
2025-10-15 20:52:58,319 - telegram.ext.Application - ERROR - No error handlers are registered, logging exception.
Traceback (most recent call last):
  File "/Library/Frameworks/Python.framework/Versions/3.13/lib/python3.13/site-packages/telegram/ext/_updater.py", line 743, in _network_loop_retry
    if not await do_action():
           ^^^^^^^^^^^^^^^^^
  File "/Library/Frameworks/Python.framework/Versions/3.13/lib/python3.13/site-packages/telegram/ext/_updater.py", line 737, in do_action
    return action_cb_task.result()
           ~~~~~~~~~~~~~~~~~~~~~^^
  File "/Library/Frameworks/Python.framework/Versions/3.13/lib/python3.13/site-packages/telegram/ext/_updater.py", line 367, in polling_action_cb
    updates = await self.bot.get_updates(
              ^^^^^^^^^^^^^^^^^^^^^^^^^^^
    ...<7 lines>...
    )
    ^
  File "/Library/Frameworks/Python.framework/Versions/3.13/lib/python3.13/site-packages/telegram/ext/_extbot.py", line 647, in get_updates
    updates = await super().get_updates(
              ^^^^^^^^^^^^^^^^^^^^^^^^^^
    ...<9 lines>...
    )
    ^
  File "/Library/Frameworks/Python.framework/Versions/3.13/lib/python3.13/site-packages/telegram/_bot.py", line 4421, in get_updates
    await self._post(
    ^^^^^^^^^^^^^^^^^
    ...<7 lines>...
    ),
    ^
  File "/Library/Frameworks/Python.framework/Versions/3.13/lib/python3.13/site-packages/telegram/_bot.py", line 617, in _post
    return await self._do_post(
           ^^^^^^^^^^^^^^^^^^^^
    ...<6 lines>...
    )
    ^
  File "/Library/Frameworks/Python.framework/Versions/3.13/lib/python3.13/site-packages/telegram/ext/_extbot.py", line 351, in _do_post
    return await super()._do_post(
           ^^^^^^^^^^^^^^^^^^^^^^^
    ...<6 lines>...
    )
    ^
  File "/Library/Frameworks/Python.framework/Versions/3.13/lib/python3.13/site-packages/telegram/_bot.py", line 646, in _do_post
    result = await request.post(
             ^^^^^^^^^^^^^^^^^^^
    ...<6 lines>...
    )
    ^
  File "/Library/Frameworks/Python.framework/Versions/3.13/lib/python3.13/site-packages/telegram/request/_baserequest.py", line 202, in post
    result = await self._request_wrapper(
             ^^^^^^^^^^^^^^^^^^^^^^^^^^^^
    ...<7 lines>...
    )
    ^
  File "/Library/Frameworks/Python.framework/Versions/3.13/lib/python3.13/site-packages/telegram/request/_baserequest.py", line 385, in _request_wrapper
    raise Conflict(message)
telegram.error.Conflict: Conflict: terminated by other getUpdates request; make sure that only one bot instance is running
2025-10-15 20:53:09,401 - httpx - INFO - HTTP Request: POST https://api.telegram.org/bot8242076298:AAGnHplpi7Ad4hOo9z4zTugjqcCEXLJt9to/getUpdates "HTTP/1.1 200 OK"
2025-10-15 20:53:19,469 - httpx - INFO - HTTP Request: POST https://api.telegram.org/bot8242076298:AAGnHplpi7Ad4hOo9z4zTugjqcCEXLJt9to/getUpdates "HTTP/1.1 200 OK"
2025-10-15 20:53:29,620 - httpx - INFO - HTTP Request: POST https://api.telegram.org/bot8242076298:AAGnHplpi7Ad4hOo9z4zTugjqcCEXLJt9to/getUpdates "HTTP/1.1 200 OK"
2025-10-15 20:53:32,595 - httpx - INFO - HTTP Request: POST https://api.telegram.org/bot8242076298:AAGnHplpi7Ad4hOo9z4zTugjqcCEXLJt9to/getUpdates "HTTP/1.1 409 Conflict"
2025-10-15 20:53:32,596 - telegram.ext.Application - ERROR - No error handlers are registered, logging exception.
Traceback (most recent call last):
  File "/Library/Frameworks/Python.framework/Versions/3.13/lib/python3.13/site-packages/telegram/ext/_updater.py", line 743, in _network_loop_retry
    if not await do_action():
           ^^^^^^^^^^^^^^^^^
  File "/Library/Frameworks/Python.framework/Versions/3.13/lib/python3.13/site-packages/telegram/ext/_updater.py", line 737, in do_action
    return action_cb_task.result()
           ~~~~~~~~~~~~~~~~~~~~~^^
  File "/Library/Frameworks/Python.framework/Versions/3.13/lib/python3.13/site-packages/telegram/ext/_updater.py", line 367, in polling_action_cb
    updates = await self.bot.get_updates(
              ^^^^^^^^^^^^^^^^^^^^^^^^^^^
    ...<7 lines>...
    )
    ^
  File "/Library/Frameworks/Python.framework/Versions/3.13/lib/python3.13/site-packages/telegram/ext/_extbot.py", line 647, in get_updates
    updates = await super().get_updates(
              ^^^^^^^^^^^^^^^^^^^^^^^^^^
    ...<9 lines>...
    )
    ^
  File "/Library/Frameworks/Python.framework/Versions/3.13/lib/python3.13/site-packages/telegram/_bot.py", line 4421, in get_updates
    await self._post(
    ^^^^^^^^^^^^^^^^^
    ...<7 lines>...
    ),
    ^
  File "/Library/Frameworks/Python.framework/Versions/3.13/lib/python3.13/site-packages/telegram/_bot.py", line 617, in _post
    return await self._do_post(
           ^^^^^^^^^^^^^^^^^^^^
    ...<6 lines>...
    )
    ^
  File "/Library/Frameworks/Python.framework/Versions/3.13/lib/python3.13/site-packages/telegram/ext/_extbot.py", line 351, in _do_post
    return await super()._do_post(
           ^^^^^^^^^^^^^^^^^^^^^^^
    ...<6 lines>...
    )
    ^
  File "/Library/Frameworks/Python.framework/Versions/3.13/lib/python3.13/site-packages/telegram/_bot.py", line 646, in _do_post
    result = await request.post(
             ^^^^^^^^^^^^^^^^^^^
    ...<6 lines>...
    )
    ^
  File "/Library/Frameworks/Python.framework/Versions/3.13/lib/python3.13/site-packages/telegram/request/_baserequest.py", line 202, in post
    result = await self._request_wrapper(
             ^^^^^^^^^^^^^^^^^^^^^^^^^^^^
    ...<7 lines>...
    )
    ^
  File "/Library/Frameworks/Python.framework/Versions/3.13/lib/python3.13/site-packages/telegram/request/_baserequest.py", line 385, in _request_wrapper
    raise Conflict(message)
telegram.error.Conflict: Conflict: terminated by other getUpdates request; make sure that only one bot instance is running
2025-10-15 20:53:43,665 - httpx - INFO - HTTP Request: POST https://api.telegram.org/bot8242076298:AAGnHplpi7Ad4hOo9z4zTugjqcCEXLJt9to/getUpdates "HTTP/1.1 200 OK"
2025-10-15 20:53:53,735 - httpx - INFO - HTTP Request: POST https://api.telegram.org/bot8242076298:AAGnHplpi7Ad4hOo9z4zTugjqcCEXLJt9to/getUpdates "HTTP/1.1 200 OK"
2025-10-15 20:54:03,820 - httpx - INFO - HTTP Request: POST https://api.telegram.org/bot8242076298:AAGnHplpi7Ad4hOo9z4zTugjqcCEXLJt9to/getUpdates "HTTP/1.1 200 OK"
2025-10-15 20:54:06,880 - httpx - INFO - HTTP Request: POST https://api.telegram.org/bot8242076298:AAGnHplpi7Ad4hOo9z4zTugjqcCEXLJt9to/getUpdates "HTTP/1.1 409 Conflict"
2025-10-15 20:54:06,880 - telegram.ext.Application - ERROR - No error handlers are registered, logging exception.
Traceback (most recent call last):
  File "/Library/Frameworks/Python.framework/Versions/3.13/lib/python3.13/site-packages/telegram/ext/_updater.py", line 743, in _network_loop_retry
    if not await do_action():
           ^^^^^^^^^^^^^^^^^
  File "/Library/Frameworks/Python.framework/Versions/3.13/lib/python3.13/site-packages/telegram/ext/_updater.py", line 737, in do_action
    return action_cb_task.result()
           ~~~~~~~~~~~~~~~~~~~~~^^
  File "/Library/Frameworks/Python.framework/Versions/3.13/lib/python3.13/site-packages/telegram/ext/_updater.py", line 367, in polling_action_cb
    updates = await self.bot.get_updates(
              ^^^^^^^^^^^^^^^^^^^^^^^^^^^
    ...<7 lines>...
    )
    ^
  File "/Library/Frameworks/Python.framework/Versions/3.13/lib/python3.13/site-packages/telegram/ext/_extbot.py", line 647, in get_updates
    updates = await super().get_updates(
              ^^^^^^^^^^^^^^^^^^^^^^^^^^
    ...<9 lines>...
    )
    ^
  File "/Library/Frameworks/Python.framework/Versions/3.13/lib/python3.13/site-packages/telegram/_bot.py", line 4421, in get_updates
    await self._post(
    ^^^^^^^^^^^^^^^^^
    ...<7 lines>...
    ),
    ^
  File "/Library/Frameworks/Python.framework/Versions/3.13/lib/python3.13/site-packages/telegram/_bot.py", line 617, in _post
    return await self._do_post(
           ^^^^^^^^^^^^^^^^^^^^
    ...<6 lines>...
    )
    ^
  File "/Library/Frameworks/Python.framework/Versions/3.13/lib/python3.13/site-packages/telegram/ext/_extbot.py", line 351, in _do_post
    return await super()._do_post(
           ^^^^^^^^^^^^^^^^^^^^^^^
    ...<6 lines>...
    )
    ^
  File "/Library/Frameworks/Python.framework/Versions/3.13/lib/python3.13/site-packages/telegram/_bot.py", line 646, in _do_post
    result = await request.post(
             ^^^^^^^^^^^^^^^^^^^
    ...<6 lines>...
    )
    ^
  File "/Library/Frameworks/Python.framework/Versions/3.13/lib/python3.13/site-packages/telegram/request/_baserequest.py", line 202, in post
    result = await self._request_wrapper(
             ^^^^^^^^^^^^^^^^^^^^^^^^^^^^
    ...<7 lines>...
    )
    ^
  File "/Library/Frameworks/Python.framework/Versions/3.13/lib/python3.13/site-packages/telegram/request/_baserequest.py", line 385, in _request_wrapper
    raise Conflict(message)
telegram.error.Conflict: Conflict: terminated by other getUpdates request; make sure that only one bot instance is running
2025-10-15 20:54:17,950 - httpx - INFO - HTTP Request: POST https://api.telegram.org/bot8242076298:AAGnHplpi7Ad4hOo9z4zTugjqcCEXLJt9to/getUpdates "HTTP/1.1 200 OK"
2025-10-15 20:54:28,013 - httpx - INFO - HTTP Request: POST https://api.telegram.org/bot8242076298:AAGnHplpi7Ad4hOo9z4zTugjqcCEXLJt9to/getUpdates "HTTP/1.1 200 OK"
2025-10-15 20:54:38,117 - httpx - INFO - HTTP Request: POST https://api.telegram.org/bot8242076298:AAGnHplpi7Ad4hOo9z4zTugjqcCEXLJt9to/getUpdates "HTTP/1.1 200 OK"
2025-10-15 20:54:41,199 - httpx - INFO - HTTP Request: POST https://api.telegram.org/bot8242076298:AAGnHplpi7Ad4hOo9z4zTugjqcCEXLJt9to/getUpdates "HTTP/1.1 409 Conflict"
2025-10-15 20:54:41,199 - telegram.ext.Application - ERROR - No error handlers are registered, logging exception.
Traceback (most recent call last):
  File "/Library/Frameworks/Python.framework/Versions/3.13/lib/python3.13/site-packages/telegram/ext/_updater.py", line 743, in _network_loop_retry
    if not await do_action():
           ^^^^^^^^^^^^^^^^^
  File "/Library/Frameworks/Python.framework/Versions/3.13/lib/python3.13/site-packages/telegram/ext/_updater.py", line 737, in do_action
    return action_cb_task.result()
           ~~~~~~~~~~~~~~~~~~~~~^^
  File "/Library/Frameworks/Python.framework/Versions/3.13/lib/python3.13/site-packages/telegram/ext/_updater.py", line 367, in polling_action_cb
    updates = await self.bot.get_updates(
              ^^^^^^^^^^^^^^^^^^^^^^^^^^^
    ...<7 lines>...
    )
    ^
  File "/Library/Frameworks/Python.framework/Versions/3.13/lib/python3.13/site-packages/telegram/ext/_extbot.py", line 647, in get_updates
    updates = await super().get_updates(
              ^^^^^^^^^^^^^^^^^^^^^^^^^^
    ...<9 lines>...
    )
    ^
  File "/Library/Frameworks/Python.framework/Versions/3.13/lib/python3.13/site-packages/telegram/_bot.py", line 4421, in get_updates
    await self._post(
    ^^^^^^^^^^^^^^^^^
    ...<7 lines>...
    ),
    ^
  File "/Library/Frameworks/Python.framework/Versions/3.13/lib/python3.13/site-packages/telegram/_bot.py", line 617, in _post
    return await self._do_post(
           ^^^^^^^^^^^^^^^^^^^^
    ...<6 lines>...
    )
    ^
  File "/Library/Frameworks/Python.framework/Versions/3.13/lib/python3.13/site-packages/telegram/ext/_extbot.py", line 351, in _do_post
    return await super()._do_post(
           ^^^^^^^^^^^^^^^^^^^^^^^
    ...<6 lines>...
    )
    ^
  File "/Library/Frameworks/Python.framework/Versions/3.13/lib/python3.13/site-packages/telegram/_bot.py", line 646, in _do_post
    result = await request.post(
             ^^^^^^^^^^^^^^^^^^^
    ...<6 lines>...
    )
    ^
  File "/Library/Frameworks/Python.framework/Versions/3.13/lib/python3.13/site-packages/telegram/request/_baserequest.py", line 202, in post
    result = await self._request_wrapper(
             ^^^^^^^^^^^^^^^^^^^^^^^^^^^^
    ...<7 lines>...
    )
    ^
  File "/Library/Frameworks/Python.framework/Versions/3.13/lib/python3.13/site-packages/telegram/request/_baserequest.py", line 385, in _request_wrapper
    raise Conflict(message)
telegram.error.Conflict: Conflict: terminated by other getUpdates request; make sure that only one bot instance is running
2025-10-15 20:54:52,268 - httpx - INFO - HTTP Request: POST https://api.telegram.org/bot8242076298:AAGnHplpi7Ad4hOo9z4zTugjqcCEXLJt9to/getUpdates "HTTP/1.1 200 OK"
2025-10-15 20:55:02,342 - httpx - INFO - HTTP Request: POST https://api.telegram.org/bot8242076298:AAGnHplpi7Ad4hOo9z4zTugjqcCEXLJt9to/getUpdates "HTTP/1.1 200 OK"
2025-10-15 20:55:12,461 - httpx - INFO - HTTP Request: POST https://api.telegram.org/bot8242076298:AAGnHplpi7Ad4hOo9z4zTugjqcCEXLJt9to/getUpdates "HTTP/1.1 200 OK"
2025-10-15 20:55:15,487 - httpx - INFO - HTTP Request: POST https://api.telegram.org/bot8242076298:AAGnHplpi7Ad4hOo9z4zTugjqcCEXLJt9to/getUpdates "HTTP/1.1 409 Conflict"
2025-10-15 20:55:15,488 - telegram.ext.Application - ERROR - No error handlers are registered, logging exception.
Traceback (most recent call last):
  File "/Library/Frameworks/Python.framework/Versions/3.13/lib/python3.13/site-packages/telegram/ext/_updater.py", line 743, in _network_loop_retry
    if not await do_action():
           ^^^^^^^^^^^^^^^^^
  File "/Library/Frameworks/Python.framework/Versions/3.13/lib/python3.13/site-packages/telegram/ext/_updater.py", line 737, in do_action
    return action_cb_task.result()
           ~~~~~~~~~~~~~~~~~~~~~^^
  File "/Library/Frameworks/Python.framework/Versions/3.13/lib/python3.13/site-packages/telegram/ext/_updater.py", line 367, in polling_action_cb
    updates = await self.bot.get_updates(
              ^^^^^^^^^^^^^^^^^^^^^^^^^^^
    ...<7 lines>...
    )
    ^
  File "/Library/Frameworks/Python.framework/Versions/3.13/lib/python3.13/site-packages/telegram/ext/_extbot.py", line 647, in get_updates
    updates = await super().get_updates(
              ^^^^^^^^^^^^^^^^^^^^^^^^^^
    ...<9 lines>...
    )
    ^
  File "/Library/Frameworks/Python.framework/Versions/3.13/lib/python3.13/site-packages/telegram/_bot.py", line 4421, in get_updates
    await self._post(
    ^^^^^^^^^^^^^^^^^
    ...<7 lines>...
    ),
    ^
  File "/Library/Frameworks/Python.framework/Versions/3.13/lib/python3.13/site-packages/telegram/_bot.py", line 617, in _post
    return await self._do_post(
           ^^^^^^^^^^^^^^^^^^^^
    ...<6 lines>...
    )
    ^
  File "/Library/Frameworks/Python.framework/Versions/3.13/lib/python3.13/site-packages/telegram/ext/_extbot.py", line 351, in _do_post
    return await super()._do_post(
           ^^^^^^^^^^^^^^^^^^^^^^^
    ...<6 lines>...
    )
    ^
  File "/Library/Frameworks/Python.framework/Versions/3.13/lib/python3.13/site-packages/telegram/_bot.py", line 646, in _do_post
    result = await request.post(
             ^^^^^^^^^^^^^^^^^^^
    ...<6 lines>...
    )
    ^
  File "/Library/Frameworks/Python.framework/Versions/3.13/lib/python3.13/site-packages/telegram/request/_baserequest.py", line 202, in post
    result = await self._request_wrapper(
             ^^^^^^^^^^^^^^^^^^^^^^^^^^^^
    ...<7 lines>...
    )
    ^
  File "/Library/Frameworks/Python.framework/Versions/3.13/lib/python3.13/site-packages/telegram/request/_baserequest.py", line 385, in _request_wrapper
    raise Conflict(message)
telegram.error.Conflict: Conflict: terminated by other getUpdates request; make sure that only one bot instance is running
2025-10-15 20:55:26,664 - httpx - INFO - HTTP Request: POST https://api.telegram.org/bot8242076298:AAGnHplpi7Ad4hOo9z4zTugjqcCEXLJt9to/getUpdates "HTTP/1.1 200 OK"
2025-10-15 20:55:36,804 - httpx - INFO - HTTP Request: POST https://api.telegram.org/bot8242076298:AAGnHplpi7Ad4hOo9z4zTugjqcCEXLJt9to/getUpdates "HTTP/1.1 200 OK"
2025-10-15 20:55:46,869 - httpx - INFO - HTTP Request: POST https://api.telegram.org/bot8242076298:AAGnHplpi7Ad4hOo9z4zTugjqcCEXLJt9to/getUpdates "HTTP/1.1 200 OK"
2025-10-15 20:55:49,798 - httpx - INFO - HTTP Request: POST https://api.telegram.org/bot8242076298:AAGnHplpi7Ad4hOo9z4zTugjqcCEXLJt9to/getUpdates "HTTP/1.1 409 Conflict"
2025-10-15 20:55:49,798 - telegram.ext.Application - ERROR - No error handlers are registered, logging exception.
Traceback (most recent call last):
  File "/Library/Frameworks/Python.framework/Versions/3.13/lib/python3.13/site-packages/telegram/ext/_updater.py", line 743, in _network_loop_retry
    if not await do_action():
           ^^^^^^^^^^^^^^^^^
  File "/Library/Frameworks/Python.framework/Versions/3.13/lib/python3.13/site-packages/telegram/ext/_updater.py", line 737, in do_action
    return action_cb_task.result()
           ~~~~~~~~~~~~~~~~~~~~~^^
  File "/Library/Frameworks/Python.framework/Versions/3.13/lib/python3.13/site-packages/telegram/ext/_updater.py", line 367, in polling_action_cb
    updates = await self.bot.get_updates(
              ^^^^^^^^^^^^^^^^^^^^^^^^^^^
    ...<7 lines>...
    )
    ^
  File "/Library/Frameworks/Python.framework/Versions/3.13/lib/python3.13/site-packages/telegram/ext/_extbot.py", line 647, in get_updates
    updates = await super().get_updates(
              ^^^^^^^^^^^^^^^^^^^^^^^^^^
    ...<9 lines>...
    )
    ^
  File "/Library/Frameworks/Python.framework/Versions/3.13/lib/python3.13/site-packages/telegram/_bot.py", line 4421, in get_updates
    await self._post(
    ^^^^^^^^^^^^^^^^^
    ...<7 lines>...
    ),
    ^
  File "/Library/Frameworks/Python.framework/Versions/3.13/lib/python3.13/site-packages/telegram/_bot.py", line 617, in _post
    return await self._do_post(
           ^^^^^^^^^^^^^^^^^^^^
    ...<6 lines>...
    )
    ^
  File "/Library/Frameworks/Python.framework/Versions/3.13/lib/python3.13/site-packages/telegram/ext/_extbot.py", line 351, in _do_post
    return await super()._do_post(
           ^^^^^^^^^^^^^^^^^^^^^^^
    ...<6 lines>...
    )
    ^
  File "/Library/Frameworks/Python.framework/Versions/3.13/lib/python3.13/site-packages/telegram/_bot.py", line 646, in _do_post
    result = await request.post(
             ^^^^^^^^^^^^^^^^^^^
    ...<6 lines>...
    )
    ^
  File "/Library/Frameworks/Python.framework/Versions/3.13/lib/python3.13/site-packages/telegram/request/_baserequest.py", line 202, in post
    result = await self._request_wrapper(
             ^^^^^^^^^^^^^^^^^^^^^^^^^^^^
    ...<7 lines>...
    )
    ^
  File "/Library/Frameworks/Python.framework/Versions/3.13/lib/python3.13/site-packages/telegram/request/_baserequest.py", line 385, in _request_wrapper
    raise Conflict(message)
telegram.error.Conflict: Conflict: terminated by other getUpdates request; make sure that only one bot instance is running
2025-10-15 20:56:00,916 - httpx - INFO - HTTP Request: POST https://api.telegram.org/bot8242076298:AAGnHplpi7Ad4hOo9z4zTugjqcCEXLJt9to/getUpdates "HTTP/1.1 200 OK"
2025-10-15 20:56:11,003 - httpx - INFO - HTTP Request: POST https://api.telegram.org/bot8242076298:AAGnHplpi7Ad4hOo9z4zTugjqcCEXLJt9to/getUpdates "HTTP/1.1 200 OK"
2025-10-15 20:56:21,124 - httpx - INFO - HTTP Request: POST https://api.telegram.org/bot8242076298:AAGnHplpi7Ad4hOo9z4zTugjqcCEXLJt9to/getUpdates "HTTP/1.1 200 OK"
2025-10-15 20:56:24,070 - httpx - INFO - HTTP Request: POST https://api.telegram.org/bot8242076298:AAGnHplpi7Ad4hOo9z4zTugjqcCEXLJt9to/getUpdates "HTTP/1.1 409 Conflict"
2025-10-15 20:56:24,071 - telegram.ext.Application - ERROR - No error handlers are registered, logging exception.
Traceback (most recent call last):
  File "/Library/Frameworks/Python.framework/Versions/3.13/lib/python3.13/site-packages/telegram/ext/_updater.py", line 743, in _network_loop_retry
    if not await do_action():
           ^^^^^^^^^^^^^^^^^
  File "/Library/Frameworks/Python.framework/Versions/3.13/lib/python3.13/site-packages/telegram/ext/_updater.py", line 737, in do_action
    return action_cb_task.result()
           ~~~~~~~~~~~~~~~~~~~~~^^
  File "/Library/Frameworks/Python.framework/Versions/3.13/lib/python3.13/site-packages/telegram/ext/_updater.py", line 367, in polling_action_cb
    updates = await self.bot.get_updates(
              ^^^^^^^^^^^^^^^^^^^^^^^^^^^
    ...<7 lines>...
    )
    ^
  File "/Library/Frameworks/Python.framework/Versions/3.13/lib/python3.13/site-packages/telegram/ext/_extbot.py", line 647, in get_updates
    updates = await super().get_updates(
              ^^^^^^^^^^^^^^^^^^^^^^^^^^
    ...<9 lines>...
    )
    ^
  File "/Library/Frameworks/Python.framework/Versions/3.13/lib/python3.13/site-packages/telegram/_bot.py", line 4421, in get_updates
    await self._post(
    ^^^^^^^^^^^^^^^^^
    ...<7 lines>...
    ),
    ^
  File "/Library/Frameworks/Python.framework/Versions/3.13/lib/python3.13/site-packages/telegram/_bot.py", line 617, in _post
    return await self._do_post(
           ^^^^^^^^^^^^^^^^^^^^
    ...<6 lines>...
    )
    ^
  File "/Library/Frameworks/Python.framework/Versions/3.13/lib/python3.13/site-packages/telegram/ext/_extbot.py", line 351, in _do_post
    return await super()._do_post(
           ^^^^^^^^^^^^^^^^^^^^^^^
    ...<6 lines>...
    )
    ^
  File "/Library/Frameworks/Python.framework/Versions/3.13/lib/python3.13/site-packages/telegram/_bot.py", line 646, in _do_post
    result = await request.post(
             ^^^^^^^^^^^^^^^^^^^
    ...<6 lines>...
    )
    ^
  File "/Library/Frameworks/Python.framework/Versions/3.13/lib/python3.13/site-packages/telegram/request/_baserequest.py", line 202, in post
    result = await self._request_wrapper(
             ^^^^^^^^^^^^^^^^^^^^^^^^^^^^
    ...<7 lines>...
    )
    ^
  File "/Library/Frameworks/Python.framework/Versions/3.13/lib/python3.13/site-packages/telegram/request/_baserequest.py", line 385, in _request_wrapper
    raise Conflict(message)
telegram.error.Conflict: Conflict: terminated by other getUpdates request; make sure that only one bot instance is running
2025-10-15 20:56:35,137 - httpx - INFO - HTTP Request: POST https://api.telegram.org/bot8242076298:AAGnHplpi7Ad4hOo9z4zTugjqcCEXLJt9to/getUpdates "HTTP/1.1 200 OK"
2025-10-15 20:56:45,201 - httpx - INFO - HTTP Request: POST https://api.telegram.org/bot8242076298:AAGnHplpi7Ad4hOo9z4zTugjqcCEXLJt9to/getUpdates "HTTP/1.1 200 OK"
2025-10-15 20:56:55,267 - httpx - INFO - HTTP Request: POST https://api.telegram.org/bot8242076298:AAGnHplpi7Ad4hOo9z4zTugjqcCEXLJt9to/getUpdates "HTTP/1.1 200 OK"
2025-10-15 20:56:58,334 - httpx - INFO - HTTP Request: POST https://api.telegram.org/bot8242076298:AAGnHplpi7Ad4hOo9z4zTugjqcCEXLJt9to/getUpdates "HTTP/1.1 409 Conflict"
2025-10-15 20:56:58,335 - telegram.ext.Application - ERROR - No error handlers are registered, logging exception.
Traceback (most recent call last):
  File "/Library/Frameworks/Python.framework/Versions/3.13/lib/python3.13/site-packages/telegram/ext/_updater.py", line 743, in _network_loop_retry
    if not await do_action():
           ^^^^^^^^^^^^^^^^^
  File "/Library/Frameworks/Python.framework/Versions/3.13/lib/python3.13/site-packages/telegram/ext/_updater.py", line 737, in do_action
    return action_cb_task.result()
           ~~~~~~~~~~~~~~~~~~~~~^^
  File "/Library/Frameworks/Python.framework/Versions/3.13/lib/python3.13/site-packages/telegram/ext/_updater.py", line 367, in polling_action_cb
    updates = await self.bot.get_updates(
              ^^^^^^^^^^^^^^^^^^^^^^^^^^^
    ...<7 lines>...
    )
    ^
  File "/Library/Frameworks/Python.framework/Versions/3.13/lib/python3.13/site-packages/telegram/ext/_extbot.py", line 647, in get_updates
    updates = await super().get_updates(
              ^^^^^^^^^^^^^^^^^^^^^^^^^^
    ...<9 lines>...
    )
    ^
  File "/Library/Frameworks/Python.framework/Versions/3.13/lib/python3.13/site-packages/telegram/_bot.py", line 4421, in get_updates
    await self._post(
    ^^^^^^^^^^^^^^^^^
    ...<7 lines>...
    ),
    ^
  File "/Library/Frameworks/Python.framework/Versions/3.13/lib/python3.13/site-packages/telegram/_bot.py", line 617, in _post
    return await self._do_post(
           ^^^^^^^^^^^^^^^^^^^^
    ...<6 lines>...
    )
    ^
  File "/Library/Frameworks/Python.framework/Versions/3.13/lib/python3.13/site-packages/telegram/ext/_extbot.py", line 351, in _do_post
    return await super()._do_post(
           ^^^^^^^^^^^^^^^^^^^^^^^
    ...<6 lines>...
    )
    ^
  File "/Library/Frameworks/Python.framework/Versions/3.13/lib/python3.13/site-packages/telegram/_bot.py", line 646, in _do_post
    result = await request.post(
             ^^^^^^^^^^^^^^^^^^^
    ...<6 lines>...
    )
    ^
  File "/Library/Frameworks/Python.framework/Versions/3.13/lib/python3.13/site-packages/telegram/request/_baserequest.py", line 202, in post
    result = await self._request_wrapper(
             ^^^^^^^^^^^^^^^^^^^^^^^^^^^^
    ...<7 lines>...
    )
    ^
  File "/Library/Frameworks/Python.framework/Versions/3.13/lib/python3.13/site-packages/telegram/request/_baserequest.py", line 385, in _request_wrapper
    raise Conflict(message)
telegram.error.Conflict: Conflict: terminated by other getUpdates request; make sure that only one bot instance is running
2025-10-15 20:57:09,403 - httpx - INFO - HTTP Request: POST https://api.telegram.org/bot8242076298:AAGnHplpi7Ad4hOo9z4zTugjqcCEXLJt9to/getUpdates "HTTP/1.1 200 OK"
